*** Starting uWSGI 2.0.17 (64bit) on [Mon Apr 16 02:54:22 2018] ***
compiled with version: 5.4.0 20160609 on 16 March 2018 10:44:40
os: Linux-4.4.0-1054-aws #63-Ubuntu SMP Wed Mar 28 19:42:42 UTC 2018
nodename: ip-172-31-22-61
machine: x86_64
clock source: unix
detected number of CPU cores: 1
current working directory: /home/ubuntu/makeit
detected binary path: /usr/local/bin/uwsgi
!!! no internal routing support, rebuild with pcre support !!!
uWSGI running as root, you can use --uid/--gid/--chroot options
*** WARNING: you are running uWSGI as root !!! (use the --uid flag) *** 
your processes number limit is 3900
your memory page size is 4096 bytes
detected max file descriptor number: 1024
lock engine: pthread robust mutexes
thunder lock: disabled (you can enable it with --thunder-lock)
uwsgi socket 0 bound to TCP address 127.0.0.1:5000 fd 3
uWSGI running as root, you can use --uid/--gid/--chroot options
*** WARNING: you are running uWSGI as root !!! (use the --uid flag) *** 
Python version: 3.5.2 (default, Nov 23 2017, 16:37:01)  [GCC 5.4.0 20160609]
Python main interpreter initialized at 0x1ac4e40
uWSGI running as root, you can use --uid/--gid/--chroot options
*** WARNING: you are running uWSGI as root !!! (use the --uid flag) *** 
python threads support enabled
your server socket listen backlog is limited to 100 connections
your mercy for graceful operations on workers is 60 seconds
mapped 416720 bytes (406 KB) for 8 cores
*** Operational MODE: preforking+threaded ***
 * Running on http://0.0.0.0:2000/ (Press CTRL+C to quit)
127.0.0.1 - - [16/Apr/2018 02:54:40] "POST /login HTTP/1.0" 200 -
127.0.0.1 - - [16/Apr/2018 02:54:42] "GET /login HTTP/1.0" 200 -
127.0.0.1 - - [16/Apr/2018 02:54:47] "GET /be_a_seller HTTP/1.0" 200 -
127.0.0.1 - - [16/Apr/2018 02:56:10] "POST /be_a_seller HTTP/1.0" 302 -
127.0.0.1 - - [16/Apr/2018 02:56:10] "GET /login HTTP/1.0" 200 -
127.0.0.1 - - [16/Apr/2018 02:56:18] "POST /login HTTP/1.0" 302 -
127.0.0.1 - - [16/Apr/2018 02:56:18] "GET / HTTP/1.0" 200 -
127.0.0.1 - - [16/Apr/2018 02:56:22] "GET /shop HTTP/1.0" 200 -
127.0.0.1 - - [16/Apr/2018 02:56:24] "GET /shop/add HTTP/1.0" 200 -
127.0.0.1 - - [16/Apr/2018 02:58:26] "POST /shop/add HTTP/1.0" 302 -
127.0.0.1 - - [16/Apr/2018 02:58:27] "GET /shop HTTP/1.0" 200 -
127.0.0.1 - - [16/Apr/2018 02:58:27] "GET /static/img/photo_bucket/Smoothies_buah_naga__pisang_Beauty_Blush.jpg HTTP/1.0" 200 -
127.0.0.1 - - [16/Apr/2018 02:58:30] "GET /shop/add HTTP/1.0" 200 -
127.0.0.1 - - [16/Apr/2018 02:58:57] "POST /shop/add HTTP/1.0" 302 -
127.0.0.1 - - [16/Apr/2018 02:58:57] "GET /shop HTTP/1.0" 200 -
127.0.0.1 - - [16/Apr/2018 02:58:58] "GET /static/img/photo_bucket/Smoothies_Mangga_Glory_Glow.jpg HTTP/1.0" 200 -
127.0.0.1 - - [16/Apr/2018 02:59:02] "GET /shop/add HTTP/1.0" 200 -
127.0.0.1 - - [16/Apr/2018 02:59:31] "POST /shop/add HTTP/1.0" 302 -
127.0.0.1 - - [16/Apr/2018 02:59:31] "GET /shop HTTP/1.0" 200 -
127.0.0.1 - - [16/Apr/2018 02:59:31] "GET /static/img/photo_bucket/Smoothies_Melon__bayem_Fountain_of_Joy.jpg HTTP/1.0" 200 -
127.0.0.1 - - [16/Apr/2018 02:59:34] "GET /shop/add HTTP/1.0" 200 -
127.0.0.1 - - [16/Apr/2018 03:00:06] "POST /shop/add HTTP/1.0" 302 -
127.0.0.1 - - [16/Apr/2018 03:00:06] "GET /shop HTTP/1.0" 200 -
127.0.0.1 - - [16/Apr/2018 03:00:06] "GET /static/img/photo_bucket/1Smoothies_Mangga_Glory_Glow.jpg HTTP/1.0" 200 -
127.0.0.1 - - [16/Apr/2018 03:00:09] "GET /profile HTTP/1.0" 200 -
127.0.0.1 - - [16/Apr/2018 03:00:10] "GET /static/img/photo_bucket/18.jpg HTTP/1.0" 200 -
127.0.0.1 - - [16/Apr/2018 03:00:10] "GET /static/img/photo_bucket/Arga_-_16k.jpg HTTP/1.0" 200 -
127.0.0.1 - - [16/Apr/2018 03:00:10] "GET /static/img/photo_bucket/195078.jpg HTTP/1.0" 200 -
127.0.0.1 - - [16/Apr/2018 03:00:10] "GET /static/img/photo_bucket/1257967.jpg HTTP/1.0" 200 -
127.0.0.1 - - [16/Apr/2018 03:00:10] "GET /static/img/photo_bucket/378830.jpg HTTP/1.0" 200 -
127.0.0.1 - - [16/Apr/2018 03:00:10] "GET /static/img/photo_bucket/S__78905543.jpg HTTP/1.0" 200 -
127.0.0.1 - - [16/Apr/2018 03:00:11] "GET /static/img/photo_bucket/Rumbe_Classic_-_36k.jpg HTTP/1.0" 200 -
127.0.0.1 - - [16/Apr/2018 03:00:11] "GET /static/img/photo_bucket/120180316_1_180324_0021.jpg HTTP/1.0" 200 -
127.0.0.1 - - [16/Apr/2018 03:00:11] "GET /static/img/photo_bucket/Kire_Earring_-_30k.jpg HTTP/1.0" 200 -
127.0.0.1 - - [16/Apr/2018 03:00:12] "GET /static/img/photo_bucket/Freya_black.jpg HTTP/1.0" 200 -
127.0.0.1 - - [16/Apr/2018 03:00:12] "GET /static/img/photo_bucket/Ta_Ta_Ta_Grey_-_22k.jpg HTTP/1.0" 200 -
127.0.0.1 - - [16/Apr/2018 03:00:13] "GET /static/img/photo_bucket/195083.jpg HTTP/1.0" 200 -
127.0.0.1 - - [16/Apr/2018 03:00:14] "GET /static/img/photo_bucket/120180316_2_180324_0006.jpg HTTP/1.0" 200 -
127.0.0.1 - - [16/Apr/2018 03:00:14] "GET /static/img/photo_bucket/S__77979685.jpg HTTP/1.0" 200 -
127.0.0.1 - - [16/Apr/2018 03:00:14] "GET /static/img/photo_bucket/S__79028285.jpg HTTP/1.0" 200 -
127.0.0.1 - - [16/Apr/2018 03:00:16] "GET /static/img/photo_bucket/S__79020088.jpg HTTP/1.0" 200 -
127.0.0.1 - - [16/Apr/2018 03:00:16] "GET /static/img/photo_bucket/S__78905536.jpg HTTP/1.0" 200 -
127.0.0.1 - - [16/Apr/2018 03:00:16] "GET /static/img/photo_bucket/Midnight_-_28k.jpg HTTP/1.0" 200 -
127.0.0.1 - - [16/Apr/2018 03:00:18] "GET /static/img/photo_bucket/20180314_180319_0004.jpg HTTP/1.0" 304 -
127.0.0.1 - - [16/Apr/2018 03:00:18] "GET /static/img/photo_bucket/20180316_180324_0011.jpg HTTP/1.0" 200 -
127.0.0.1 - - [16/Apr/2018 03:00:18] "GET /static/img/photo_bucket/produk_180313_0004.jpg HTTP/1.0" 200 -
127.0.0.1 - - [16/Apr/2018 03:00:19] "GET /static/img/photo_bucket/products.jpg HTTP/1.0" 200 -
127.0.0.1 - - [16/Apr/2018 03:00:19] "GET /static/img/photo_bucket/Minimalist_-_35k.jpg HTTP/1.0" 200 -
127.0.0.1 - - [16/Apr/2018 03:00:19] "GET /static/img/photo_bucket/11519032320775.jpg HTTP/1.0" 200 -
127.0.0.1 - - [16/Apr/2018 03:00:21] "GET /static/img/photo_bucket/420392.jpg HTTP/1.0" 304 -
127.0.0.1 - - [16/Apr/2018 03:00:22] "GET /profile/stat HTTP/1.0" 404 -
(<database_setup.Shop object at 0x7f6532f71a58>, <database_setup.Article object at 0x7f6532f71198>)
(<database_setup.Shop object at 0x7f6532f71828>, <database_setup.Article object at 0x7f6532f71e10>)
(<database_setup.Shop object at 0x7f6532f71cc0>, <database_setup.Article object at 0x7f6532f71ac8>)
(<database_setup.Shop object at 0x7f6532f71c18>, <database_setup.Article object at 0x7f6532f715f8>)
(<database_setup.Shop object at 0x7f6532f719e8>, <database_setup.Article object at 0x7f6532f71390>)
(<database_setup.Shop object at 0x7f6532f71780>, <database_setup.Article object at 0x7f6532f71438>)
(<database_setup.Shop object at 0x7f6532f71748>, <database_setup.Article object at 0x7f6532f712e8>)
(<database_setup.Shop object at 0x7f6532f68cc0>, <database_setup.Article object at 0x7f6532f681d0>)
(<database_setup.Shop object at 0x7f6532f68da0>, <database_setup.Article object at 0x7f6532f68d68>)
(<database_setup.Shop object at 0x7f6532f68438>, <database_setup.Article object at 0x7f6532f68a20>)
(<database_setup.Shop object at 0x7f6532f68fd0>, <database_setup.Article object at 0x7f6532f68e48>)
(<database_setup.Shop object at 0x7f6532f68978>, <database_setup.Article object at 0x7f6532f687b8>)
(<database_setup.Shop object at 0x7f6532f68780>, <database_setup.Article object at 0x7f6532f68588>)
(<database_setup.Shop object at 0x7f6532f68160>, <database_setup.Article object at 0x7f6532f68240>)
(<database_setup.Shop object at 0x7f6532f68160>, <database_setup.Article object at 0x7f6532f687f0>)
(<database_setup.Shop object at 0x7f6532f68160>, <database_setup.Article object at 0x7f6533a7be48>)
(<database_setup.Shop object at 0x7f6532f68160>, <database_setup.Article object at 0x7f6533a7bb00>)
(<database_setup.Shop object at 0x7f6532f68160>, <database_setup.Article object at 0x7f653364a240>)
(<database_setup.Shop object at 0x7f653364aa20>, <database_setup.Article object at 0x7f653364a7f0>)
(<database_setup.Shop object at 0x7f653364a630>, <database_setup.Article object at 0x7f65335ed080>)
(<database_setup.Shop object at 0x7f653364a630>, <database_setup.Article object at 0x7f65335ed2e8>)
(<database_setup.Shop object at 0x7f65336122b0>, <database_setup.Article object at 0x7f65336127b8>)
(<database_setup.Shop object at 0x7f6533612400>, <database_setup.Article object at 0x7f6533612b70>)
(<database_setup.Shop object at 0x7f65336121d0>, <database_setup.Article object at 0x7f6533612828>)
(<database_setup.Shop object at 0x7f6533612978>, <database_setup.Article object at 0x7f65336125c0>)
(<database_setup.Shop object at 0x7f6533612080>, <database_setup.Article object at 0x7f6533adc908>)
(<database_setup.Shop object at 0x7f6533612080>, <database_setup.Article object at 0x7f6533622f60>)
(<database_setup.Shop object at 0x7f6533612080>, <database_setup.Article object at 0x7f65335fa128>)
(<database_setup.Shop object at 0x7f6533612080>, <database_setup.Article object at 0x7f65335fa080>)
127.0.0.1 - - [16/Apr/2018 03:00:27] "GET /stat HTTP/1.0" 200 -
127.0.0.1 - - [16/Apr/2018 03:00:47] "GET / HTTP/1.0" 200 -
127.0.0.1 - - [16/Apr/2018 03:00:50] "GET /logout HTTP/1.0" 302 -
127.0.0.1 - - [16/Apr/2018 03:00:50] "GET / HTTP/1.0" 200 -
127.0.0.1 - - [16/Apr/2018 03:13:50] "GET / HTTP/1.0" 200 -
127.0.0.1 - - [16/Apr/2018 03:13:52] "GET /static/css/custom.css HTTP/1.0" 304 -
127.0.0.1 - - [16/Apr/2018 03:13:52] "GET /static/js/bootstrap.min.js HTTP/1.0" 200 -
127.0.0.1 - - [16/Apr/2018 03:13:52] "GET /static/css/bootstrap.min.css HTTP/1.0" 200 -
127.0.0.1 - - [16/Apr/2018 03:13:52] "GET /static/js/custom.js HTTP/1.0" 304 -
127.0.0.1 - - [16/Apr/2018 03:14:02] "GET /static/js/jquery.js HTTP/1.0" 200 -
127.0.0.1 - - [16/Apr/2018 03:14:02] "GET /static/img/logo-trimmed.png HTTP/1.0" 304 -
127.0.0.1 - - [16/Apr/2018 03:14:05] "GET /static/img/city-sunrise.png HTTP/1.0" 304 -
127.0.0.1 - - [16/Apr/2018 03:14:05] "GET / HTTP/1.0" 200 -
127.0.0.1 - - [16/Apr/2018 03:14:05] "GET /static/img/background-white.jpg HTTP/1.0" 304 -
127.0.0.1 - - [16/Apr/2018 03:14:06] "GET /favicon.ico HTTP/1.0" 404 -
127.0.0.1 - - [16/Apr/2018 03:14:10] "GET /category HTTP/1.0" 200 -
127.0.0.1 - - [16/Apr/2018 03:14:10] "GET /static/js/bootstrap.min.js HTTP/1.0" 200 -
127.0.0.1 - - [16/Apr/2018 03:14:10] "GET /static/js/jquery.js HTTP/1.0" 200 -
127.0.0.1 - - [16/Apr/2018 03:14:10] "GET /static/img/logo-trimmed.png HTTP/1.0" 200 -
127.0.0.1 - - [16/Apr/2018 03:14:10] "GET /static/css/custom.css HTTP/1.0" 200 -
127.0.0.1 - - [16/Apr/2018 03:14:10] "GET /static/css/bootstrap.min.css HTTP/1.0" 200 -
127.0.0.1 - - [16/Apr/2018 03:14:10] "GET /static/js/custom.js HTTP/1.0" 200 -
127.0.0.1 - - [16/Apr/2018 03:14:12] "GET /category/Arts HTTP/1.0" 200 -
127.0.0.1 - - [16/Apr/2018 03:14:12] "GET /category/Technology HTTP/1.0" 200 -
127.0.0.1 - - [16/Apr/2018 03:14:12] "GET /static/img/photo_bucket/20180316_2_180324_0006.jpg HTTP/1.0" 200 -
127.0.0.1 - - [16/Apr/2018 03:14:12] "GET /static/img/photo_bucket/LOGO.jpg HTTP/1.0" 200 -
127.0.0.1 - - [16/Apr/2018 03:14:12] "GET /static/img/photo_bucket/linux.jpg HTTP/1.0" 200 -
127.0.0.1 - - [16/Apr/2018 03:14:12] "GET / HTTP/1.0" 200 -
127.0.0.1 - - [16/Apr/2018 03:14:12] "GET /static/img/photo_bucket/111LOGO.jpg HTTP/1.0" 200 -
127.0.0.1 - - [16/Apr/2018 03:14:12] "GET /static/img/background-white.jpg HTTP/1.0" 200 -
127.0.0.1 - - [16/Apr/2018 03:14:12] "GET /static/img/city-sunrise.png HTTP/1.0" 200 -
127.0.0.1 - - [16/Apr/2018 03:14:20] "HEAD /category HTTP/1.0" 200 -
127.0.0.1 - - [16/Apr/2018 03:14:20] "GET /category/Food HTTP/1.0" 200 -
127.0.0.1 - - [16/Apr/2018 03:14:20] "GET /category/Other HTTP/1.0" 200 -
127.0.0.1 - - [16/Apr/2018 03:14:20] "GET /static/img/photo_bucket/minang.jpg HTTP/1.0" 200 -
127.0.0.1 - - [16/Apr/2018 03:14:20] "GET /static/img/photo_bucket/257967.jpg HTTP/1.0" 200 -
127.0.0.1 - - [16/Apr/2018 03:14:20] "GET /static/img/photo_bucket/20180314_180319_0001.jpg HTTP/1.0" 200 -
127.0.0.1 - - [16/Apr/2018 03:14:20] "GET /static/img/photo_bucket/LOGO_180409_0117.jpg HTTP/1.0" 200 -
127.0.0.1 - - [16/Apr/2018 03:14:20] "GET /static/img/photo_bucket/LOGO_180412_0140.jpg HTTP/1.0" 200 -
127.0.0.1 - - [16/Apr/2018 03:14:20] "GET /category/Fashion HTTP/1.0" 200 -
127.0.0.1 - - [16/Apr/2018 03:14:20] "GET /static/img/photo_bucket/1B6D5EDF5-B640-41DE-9C3D-3BC9A937EE62.jpg HTTP/1.0" 200 -
127.0.0.1 - - [16/Apr/2018 03:14:21] "GET /static/img/photo_bucket/11LOGO.jpg HTTP/1.0" 200 -
127.0.0.1 - - [16/Apr/2018 03:14:21] "GET /static/img/photo_bucket/pecelkeun.jpg HTTP/1.0" 200 -
127.0.0.1 - - [16/Apr/2018 03:14:21] "GET /static/img/photo_bucket/LOGO_BOLD.jpg HTTP/1.0" 200 -
127.0.0.1 - - [16/Apr/2018 03:14:21] "GET /static/img/photo_bucket/1LOGO.jpg HTTP/1.0" 200 -
127.0.0.1 - - [16/Apr/2018 03:14:21] "GET /static/img/photo_bucket/Freya_180313_0002.jpg HTTP/1.0" 200 -
127.0.0.1 - - [16/Apr/2018 03:14:21] "GET /static/img/photo_bucket/S__78905539.jpg HTTP/1.0" 200 -
127.0.0.1 - - [16/Apr/2018 03:14:21] "GET /category?&r=1 HTTP/1.0" 200 -
127.0.0.1 - - [16/Apr/2018 03:14:21] "GET /category/Beverages HTTP/1.0" 200 -
127.0.0.1 - - [16/Apr/2018 03:14:21] "GET /static/img/photo_bucket/LOGO_BOLD.jpg HTTP/1.0" 200 -
127.0.0.1 - - [16/Apr/2018 03:14:22] "GET /static/img/photo_bucket/LOGO_180415_0121.jpg HTTP/1.0" 200 -
127.0.0.1 - - [16/Apr/2018 03:14:22] "GET /static/img/photo_bucket/kudhemen_logoblue-02.png HTTP/1.0" 200 -
127.0.0.1 - - [16/Apr/2018 03:14:22] "GET /category/Education HTTP/1.0" 200 -
127.0.0.1 - - [16/Apr/2018 03:14:22] "GET /category/Beauty HTTP/1.0" 200 -
127.0.0.1 - - [16/Apr/2018 03:14:22] "GET /static/img/photo_bucket/20180316_1_180324_0021.jpg HTTP/1.0" 200 -
127.0.0.1 - - [16/Apr/2018 03:14:22] "GET /static/img/photo_bucket/image.jpeg HTTP/1.0" 200 -
127.0.0.1 - - [16/Apr/2018 03:14:22] "GET /static/img/photo_bucket/20180316_180324_0016.jpg HTTP/1.0" 200 -
127.0.0.1 - - [16/Apr/2018 03:14:22] "GET /static/img/photo_bucket/logo.jpg HTTP/1.0" 200 -
127.0.0.1 - - [16/Apr/2018 03:14:22] "GET /static/img/photo_bucket/1519032320775.jpg HTTP/1.0" 200 -
127.0.0.1 - - [16/Apr/2018 03:14:25] "HEAD /category?&r=1 HTTP/1.0" 200 -
127.0.0.1 - - [16/Apr/2018 03:14:26] "GET /category? HTTP/1.0" 200 -
127.0.0.1 - - [16/Apr/2018 03:14:28] "GET /static/css/custom.css HTTP/1.0" 200 -
127.0.0.1 - - [16/Apr/2018 03:14:28] "GET /static/js/custom.js HTTP/1.0" 200 -
127.0.0.1 - - [16/Apr/2018 03:14:28] "GET /static/img/logo-trimmed.png HTTP/1.0" 200 -
127.0.0.1 - - [16/Apr/2018 03:14:36] "GET /category/Beverages HTTP/1.0" 200 -
127.0.0.1 - - [16/Apr/2018 03:14:37] "GET /static/img/photo_bucket/LOGO_180415_0121.jpg HTTP/1.0" 200 -
127.0.0.1 - - [16/Apr/2018 03:14:37] "GET /static/img/photo_bucket/kudhemen_logoblue-02.png HTTP/1.0" 200 -
127.0.0.1 - - [16/Apr/2018 03:14:46] "GET /category/Beverages/Stay%20Fruit HTTP/1.0" 200 -
127.0.0.1 - - [16/Apr/2018 03:14:47] "GET /static/img/photo_bucket/1Smoothies_Mangga_Glory_Glow.jpg HTTP/1.0" 200 -
127.0.0.1 - - [16/Apr/2018 03:14:47] "GET /static/img/photo_bucket/Smoothies_buah_naga__pisang_Beauty_Blush.jpg HTTP/1.0" 200 -
127.0.0.1 - - [16/Apr/2018 03:14:47] "GET /static/img/photo_bucket/Smoothies_Mangga_Glory_Glow.jpg HTTP/1.0" 200 -
127.0.0.1 - - [16/Apr/2018 03:14:47] "GET /static/img/photo_bucket/Smoothies_Melon__bayem_Fountain_of_Joy.jpg HTTP/1.0" 200 -
127.0.0.1 - - [16/Apr/2018 03:15:01] "GET / HTTP/1.0" 200 -
127.0.0.1 - - [16/Apr/2018 03:16:39] "GET /category/Food HTTP/1.0" 200 -
127.0.0.1 - - [16/Apr/2018 03:16:40] "GET /static/css/bootstrap.min.css HTTP/1.0" 200 -
127.0.0.1 - - [16/Apr/2018 03:16:40] "GET /static/css/custom.css HTTP/1.0" 200 -
127.0.0.1 - - [16/Apr/2018 03:16:40] "GET /static/img/photo_bucket/257967.jpg HTTP/1.0" 200 -
127.0.0.1 - - [16/Apr/2018 03:16:40] "GET /static/img/photo_bucket/11LOGO.jpg HTTP/1.0" 200 -
127.0.0.1 - - [16/Apr/2018 03:16:40] "GET /static/js/jquery.js HTTP/1.0" 200 -
127.0.0.1 - - [16/Apr/2018 03:16:40] "GET /static/js/custom.js HTTP/1.0" 200 -
127.0.0.1 - - [16/Apr/2018 03:16:41] "GET /static/img/photo_bucket/1B6D5EDF5-B640-41DE-9C3D-3BC9A937EE62.jpg HTTP/1.0" 200 -
127.0.0.1 - - [16/Apr/2018 03:16:41] "GET /static/img/photo_bucket/LOGO_180409_0117.jpg HTTP/1.0" 200 -
127.0.0.1 - - [16/Apr/2018 03:16:41] "GET /static/js/bootstrap.min.js HTTP/1.0" 200 -
127.0.0.1 - - [16/Apr/2018 03:16:41] "GET /static/img/logo-trimmed.png HTTP/1.0" 200 -
127.0.0.1 - - [16/Apr/2018 03:16:42] "GET /static/img/photo_bucket/pecelkeun.jpg HTTP/1.0" 200 -
127.0.0.1 - - [16/Apr/2018 03:16:42] "GET /static/img/photo_bucket/minang.jpg HTTP/1.0" 200 -
127.0.0.1 - - [16/Apr/2018 03:16:42] "GET /static/img/photo_bucket/20180314_180319_0001.jpg HTTP/1.0" 200 -
127.0.0.1 - - [16/Apr/2018 03:16:44] "GET /static/img/photo_bucket/LOGO_180412_0140.jpg HTTP/1.0" 200 -
127.0.0.1 - - [16/Apr/2018 03:18:31] "GET /profile HTTP/1.0" 200 -
127.0.0.1 - - [16/Apr/2018 03:18:32] "GET /static/img/photo_bucket/18.jpg HTTP/1.0" 200 -
127.0.0.1 - - [16/Apr/2018 03:18:33] "GET /static/img/photo_bucket/products.jpg HTTP/1.0" 200 -
127.0.0.1 - - [16/Apr/2018 03:18:33] "GET /static/img/photo_bucket/11519032320775.jpg HTTP/1.0" 200 -
127.0.0.1 - - [16/Apr/2018 03:18:33] "GET /static/img/photo_bucket/420392.jpg HTTP/1.0" 200 -
127.0.0.1 - - [16/Apr/2018 03:18:33] "GET /static/img/photo_bucket/produk_180313_0004.jpg HTTP/1.0" 200 -
127.0.0.1 - - [16/Apr/2018 03:18:33] "GET /static/img/photo_bucket/Minimalist_-_35k.jpg HTTP/1.0" 200 -
127.0.0.1 - - [16/Apr/2018 03:18:41] "GET /static/img/photo_bucket/120180316_1_180324_0021.jpg HTTP/1.0" 200 -
127.0.0.1 - - [16/Apr/2018 03:18:42] "GET /category/Arts/a.el.project/project%20one HTTP/1.0" 200 -
127.0.0.1 - - [16/Apr/2018 03:18:42] "GET /static/js/fadeslideshow.js HTTP/1.0" 200 -
127.0.0.1 - - [16/Apr/2018 03:18:43] "GET /static/js/jquery.touchSwipe.min.js HTTP/1.0" 200 -
127.0.0.1 - - [16/Apr/2018 03:18:44] "GET /static/img/photo_bucket/18.jpg HTTP/1.0" 200 -
127.0.0.1 - - [16/Apr/2018 03:18:44] "GET /static/img/photo_bucket/15.jpg HTTP/1.0" 200 -
127.0.0.1 - - [16/Apr/2018 03:18:44] "GET /static/img/photo_bucket/9.jpg HTTP/1.0" 200 -
127.0.0.1 - - [16/Apr/2018 03:18:44] "GET /static/img/photo_bucket/16.jpg HTTP/1.0" 200 -
127.0.0.1 - - [16/Apr/2018 03:18:44] "GET /static/img/photo_bucket/6.jpg HTTP/1.0" 200 -
127.0.0.1 - - [16/Apr/2018 03:18:44] "GET /static/img/photo_bucket/7.jpg HTTP/1.0" 200 -
[2018-04-16 03:19:30,620] ERROR in app: Exception on /category/Arts/a.el.project/loading.gif [GET]
Traceback (most recent call last):
  File "/usr/local/lib/python3.5/dist-packages/flask/app.py", line 1982, in wsgi_app
    response = self.full_dispatch_request()
  File "/usr/local/lib/python3.5/dist-packages/flask/app.py", line 1614, in full_dispatch_request
    rv = self.handle_user_exception(e)
  File "/usr/local/lib/python3.5/dist-packages/flask/app.py", line 1517, in handle_user_exception
    reraise(exc_type, exc_value, tb)
  File "/usr/local/lib/python3.5/dist-packages/flask/_compat.py", line 33, in reraise
    raise value
  File "/usr/local/lib/python3.5/dist-packages/flask/app.py", line 1612, in full_dispatch_request
    rv = self.dispatch_request()
  File "/usr/local/lib/python3.5/dist-packages/flask/app.py", line 1598, in dispatch_request
    return self.view_functions[rule.endpoint](**req.view_args)
  File "./trial.py", line 523, in showitem
    return render_template('item.html',item=items,photos=photos,content=item[0][0].content,title=item[0][0].title,nav=nav.format('','','',''),logged_in=log_in,not_logged_in=not_log_in)
IndexError: list index out of range
127.0.0.1 - - [16/Apr/2018 03:19:30] "GET /category/Arts/a.el.project/loading.gif HTTP/1.0" 500 -
127.0.0.1 - - [16/Apr/2018 03:23:22] "GET / HTTP/1.0" 200 -
127.0.0.1 - - [16/Apr/2018 03:23:27] "HEAD /category HTTP/1.0" 200 -
127.0.0.1 - - [16/Apr/2018 03:23:29] "GET /category HTTP/1.0" 200 -
127.0.0.1 - - [16/Apr/2018 03:23:43] "GET /category/Fashion HTTP/1.0" 200 -
127.0.0.1 - - [16/Apr/2018 03:23:43] "GET /static/img/photo_bucket/LOGO_BOLD.jpg HTTP/1.0" 200 -
127.0.0.1 - - [16/Apr/2018 03:23:43] "GET /static/img/photo_bucket/S__78905539.jpg HTTP/1.0" 200 -
127.0.0.1 - - [16/Apr/2018 03:23:43] "GET /static/img/photo_bucket/1LOGO.jpg HTTP/1.0" 200 -
127.0.0.1 - - [16/Apr/2018 03:23:43] "GET /static/img/photo_bucket/Freya_180313_0002.jpg HTTP/1.0" 200 -
127.0.0.1 - - [16/Apr/2018 03:23:47] "GET /category/Beauty HTTP/1.0" 200 -
127.0.0.1 - - [16/Apr/2018 03:23:48] "GET /static/img/photo_bucket/image.jpeg HTTP/1.0" 200 -
127.0.0.1 - - [16/Apr/2018 03:23:48] "GET /static/img/photo_bucket/20180316_180324_0016.jpg HTTP/1.0" 200 -
127.0.0.1 - - [16/Apr/2018 03:23:48] "GET /static/img/photo_bucket/logo.jpg HTTP/1.0" 200 -
127.0.0.1 - - [16/Apr/2018 03:23:48] "GET /static/img/photo_bucket/20180316_1_180324_0021.jpg HTTP/1.0" 200 -
127.0.0.1 - - [16/Apr/2018 03:23:48] "GET /static/img/photo_bucket/1519032320775.jpg HTTP/1.0" 200 -
127.0.0.1 - - [16/Apr/2018 03:24:22] "GET /category/Beverages HTTP/1.0" 200 -
127.0.0.1 - - [16/Apr/2018 03:24:30] "GET /category/Beverages/Stay%20Fruit HTTP/1.0" 200 -
127.0.0.1 - - [16/Apr/2018 03:25:01] "GET /category/Beverages/Kudhemen%20Creamery HTTP/1.0" 200 -
127.0.0.1 - - [16/Apr/2018 03:25:01] "GET /static/img/photo_bucket/195078.jpg HTTP/1.0" 304 -
127.0.0.1 - - [16/Apr/2018 03:25:01] "GET /static/img/photo_bucket/195083.jpg HTTP/1.0" 304 -
127.0.0.1 - - [16/Apr/2018 03:25:17] "GET /category/Beverages/Kudhemen%20Creamery HTTP/1.0" 200 -
127.0.0.1 - - [16/Apr/2018 03:25:56] "GET /category/Beauty HTTP/1.0" 200 -
127.0.0.1 - - [16/Apr/2018 03:26:18] "GET /category/Beauty/not%20a%20sunflower HTTP/1.0" 200 -
127.0.0.1 - - [16/Apr/2018 03:26:19] "GET /static/img/photo_bucket/products.jpg HTTP/1.0" 304 -
127.0.0.1 - - [16/Apr/2018 03:26:34] "GET /category/Arts HTTP/1.0" 200 -
127.0.0.1 - - [16/Apr/2018 03:26:35] "GET /static/img/photo_bucket/LOGO.jpg HTTP/1.0" 200 -
127.0.0.1 - - [16/Apr/2018 03:26:35] "GET /static/img/photo_bucket/20180316_2_180324_0006.jpg HTTP/1.0" 200 -
127.0.0.1 - - [16/Apr/2018 03:26:35] "GET /static/img/photo_bucket/111LOGO.jpg HTTP/1.0" 200 -
127.0.0.1 - - [16/Apr/2018 03:26:42] "GET /category/Arts/Popon%20Tanaman%20Hidroponik HTTP/1.0" 200 -
127.0.0.1 - - [16/Apr/2018 03:26:42] "GET /static/img/photo_bucket/Minimalist_-_35k.jpg HTTP/1.0" 304 -
127.0.0.1 - - [16/Apr/2018 03:26:47] "GET /category/Arts/The%20Vividiary%20Florist HTTP/1.0" 200 -
127.0.0.1 - - [16/Apr/2018 03:26:47] "GET /static/img/photo_bucket/120180316_2_180324_0006.jpg HTTP/1.0" 200 -
127.0.0.1 - - [16/Apr/2018 03:27:01] "GET /category/Fashion HTTP/1.0" 200 -
127.0.0.1 - - [16/Apr/2018 03:27:01] "GET /static/img/photo_bucket/LOGO_BOLD.jpg HTTP/1.0" 200 -
127.0.0.1 - - [16/Apr/2018 03:27:11] "GET /category/Fashion/Rante%20Rumbe HTTP/1.0" 200 -
127.0.0.1 - - [16/Apr/2018 03:27:11] "GET /static/img/photo_bucket/Ta_Ta_Ta_Grey_-_22k.jpg HTTP/1.0" 304 -
127.0.0.1 - - [16/Apr/2018 03:27:11] "GET /static/img/photo_bucket/Arga_-_16k.jpg HTTP/1.0" 200 -
127.0.0.1 - - [16/Apr/2018 03:27:11] "GET /static/img/photo_bucket/Midnight_-_28k.jpg HTTP/1.0" 200 -
127.0.0.1 - - [16/Apr/2018 03:27:11] "GET /static/img/photo_bucket/Rumbe_Classic_-_36k.jpg HTTP/1.0" 200 -
127.0.0.1 - - [16/Apr/2018 03:27:11] "GET /static/img/photo_bucket/Kire_Earring_-_30k.jpg HTTP/1.0" 200 -
127.0.0.1 - - [16/Apr/2018 03:27:31] "GET /category/Fashion/Bright%20&%20Wild HTTP/1.0" 200 -
127.0.0.1 - - [16/Apr/2018 03:27:32] "GET /static/img/photo_bucket/S__78905536.jpg HTTP/1.0" 304 -
127.0.0.1 - - [16/Apr/2018 03:27:34] "GET /category/Fashion/Bright%20&%20Wild/Sandal%20Cibaduyut HTTP/1.0" 200 -
127.0.0.1 - - [16/Apr/2018 03:27:35] "GET /static/js/jquery.touchSwipe.min.js HTTP/1.0" 200 -
127.0.0.1 - - [16/Apr/2018 03:27:35] "GET /static/js/fadeslideshow.js HTTP/1.0" 200 -
127.0.0.1 - - [16/Apr/2018 03:27:35] "GET /static/img/photo_bucket/S__78905537.jpg HTTP/1.0" 200 -
127.0.0.1 - - [16/Apr/2018 03:27:35] "GET /static/img/photo_bucket/S__78905538.jpg HTTP/1.0" 200 -
[2018-04-16 03:27:36,103] ERROR in app: Exception on /category/Fashion/Bright & Wild/loading.gif [GET]
Traceback (most recent call last):
  File "/usr/local/lib/python3.5/dist-packages/flask/app.py", line 1982, in wsgi_app
    response = self.full_dispatch_request()
  File "/usr/local/lib/python3.5/dist-packages/flask/app.py", line 1614, in full_dispatch_request
    rv = self.handle_user_exception(e)
  File "/usr/local/lib/python3.5/dist-packages/flask/app.py", line 1517, in handle_user_exception
    reraise(exc_type, exc_value, tb)
  File "/usr/local/lib/python3.5/dist-packages/flask/_compat.py", line 33, in reraise
    raise value
  File "/usr/local/lib/python3.5/dist-packages/flask/app.py", line 1612, in full_dispatch_request
    rv = self.dispatch_request()
  File "/usr/local/lib/python3.5/dist-packages/flask/app.py", line 1598, in dispatch_request
    return self.view_functions[rule.endpoint](**req.view_args)
  File "./trial.py", line 523, in showitem
    return render_template('item.html',item=items,photos=photos,content=item[0][0].content,title=item[0][0].title,nav=nav.format('','','',''),logged_in=log_in,not_logged_in=not_log_in)
IndexError: list index out of range
127.0.0.1 - - [16/Apr/2018 03:27:36] "GET /category/Fashion/Bright%20&%20Wild/loading.gif HTTP/1.0" 500 -
[2018-04-16 03:27:36,906] ERROR in app: Exception on /category/Fashion/Bright & Wild/loading.gif [GET]
Traceback (most recent call last):
  File "/usr/local/lib/python3.5/dist-packages/flask/app.py", line 1982, in wsgi_app
    response = self.full_dispatch_request()
  File "/usr/local/lib/python3.5/dist-packages/flask/app.py", line 1614, in full_dispatch_request
    rv = self.handle_user_exception(e)
  File "/usr/local/lib/python3.5/dist-packages/flask/app.py", line 1517, in handle_user_exception
    reraise(exc_type, exc_value, tb)
  File "/usr/local/lib/python3.5/dist-packages/flask/_compat.py", line 33, in reraise
    raise value
  File "/usr/local/lib/python3.5/dist-packages/flask/app.py", line 1612, in full_dispatch_request
    rv = self.dispatch_request()
  File "/usr/local/lib/python3.5/dist-packages/flask/app.py", line 1598, in dispatch_request
    return self.view_functions[rule.endpoint](**req.view_args)
  File "./trial.py", line 523, in showitem
    return render_template('item.html',item=items,photos=photos,content=item[0][0].content,title=item[0][0].title,nav=nav.format('','','',''),logged_in=log_in,not_logged_in=not_log_in)
IndexError: list index out of range
127.0.0.1 - - [16/Apr/2018 03:27:36] "GET /category/Fashion/Bright%20&%20Wild/loading.gif HTTP/1.0" 500 -
127.0.0.1 - - [16/Apr/2018 03:27:42] "GET /category/Fashion/Bright%20&%20Wild/Sandal%20Cibaduyut HTTP/1.0" 200 -
[2018-04-16 03:27:43,538] ERROR in app: Exception on /category/Fashion/Bright & Wild/loading.gif [GET]
Traceback (most recent call last):
  File "/usr/local/lib/python3.5/dist-packages/flask/app.py", line 1982, in wsgi_app
    response = self.full_dispatch_request()
  File "/usr/local/lib/python3.5/dist-packages/flask/app.py", line 1614, in full_dispatch_request
    rv = self.handle_user_exception(e)
  File "/usr/local/lib/python3.5/dist-packages/flask/app.py", line 1517, in handle_user_exception
    reraise(exc_type, exc_value, tb)
  File "/usr/local/lib/python3.5/dist-packages/flask/_compat.py", line 33, in reraise
    raise value
  File "/usr/local/lib/python3.5/dist-packages/flask/app.py", line 1612, in full_dispatch_request
    rv = self.dispatch_request()
  File "/usr/local/lib/python3.5/dist-packages/flask/app.py", line 1598, in dispatch_request
    return self.view_functions[rule.endpoint](**req.view_args)
  File "./trial.py", line 523, in showitem
    return render_template('item.html',item=items,photos=photos,content=item[0][0].content,title=item[0][0].title,nav=nav.format('','','',''),logged_in=log_in,not_logged_in=not_log_in)
IndexError: list index out of range
127.0.0.1 - - [16/Apr/2018 03:27:43] "GET /category/Fashion/Bright%20&%20Wild/loading.gif HTTP/1.0" 500 -
[2018-04-16 03:27:43,857] ERROR in app: Exception on /category/Fashion/Bright & Wild/loading.gif [GET]
Traceback (most recent call last):
  File "/usr/local/lib/python3.5/dist-packages/flask/app.py", line 1982, in wsgi_app
    response = self.full_dispatch_request()
  File "/usr/local/lib/python3.5/dist-packages/flask/app.py", line 1614, in full_dispatch_request
    rv = self.handle_user_exception(e)
  File "/usr/local/lib/python3.5/dist-packages/flask/app.py", line 1517, in handle_user_exception
    reraise(exc_type, exc_value, tb)
  File "/usr/local/lib/python3.5/dist-packages/flask/_compat.py", line 33, in reraise
    raise value
  File "/usr/local/lib/python3.5/dist-packages/flask/app.py", line 1612, in full_dispatch_request
    rv = self.dispatch_request()
  File "/usr/local/lib/python3.5/dist-packages/flask/app.py", line 1598, in dispatch_request
    return self.view_functions[rule.endpoint](**req.view_args)
  File "./trial.py", line 523, in showitem
    return render_template('item.html',item=items,photos=photos,content=item[0][0].content,title=item[0][0].title,nav=nav.format('','','',''),logged_in=log_in,not_logged_in=not_log_in)
IndexError: list index out of range
127.0.0.1 - - [16/Apr/2018 03:27:43] "GET /category/Fashion/Bright%20&%20Wild/loading.gif HTTP/1.0" 500 -
127.0.0.1 - - [16/Apr/2018 03:27:47] "GET /category/Fashion/Bright%20&%20Wild/Sandal%20Cibaduyut/buy HTTP/1.0" 200 -
127.0.0.1 - - [16/Apr/2018 03:28:17] "GET /category/Fashion/Rante%20Rumbe HTTP/1.0" 200 -
127.0.0.1 - - [16/Apr/2018 03:28:24] "GET /category/Food HTTP/1.0" 200 -
127.0.0.1 - - [16/Apr/2018 03:28:25] "GET /static/img/photo_bucket/minang.jpg HTTP/1.0" 200 -
127.0.0.1 - - [16/Apr/2018 03:28:25] "GET /static/img/photo_bucket/257967.jpg HTTP/1.0" 200 -
127.0.0.1 - - [16/Apr/2018 03:28:25] "GET /static/img/photo_bucket/1B6D5EDF5-B640-41DE-9C3D-3BC9A937EE62.jpg HTTP/1.0" 200 -
127.0.0.1 - - [16/Apr/2018 03:28:25] "GET /static/img/photo_bucket/LOGO_180412_0140.jpg HTTP/1.0" 200 -
127.0.0.1 - - [16/Apr/2018 03:28:25] "GET /static/img/photo_bucket/LOGO_180409_0117.jpg HTTP/1.0" 200 -
127.0.0.1 - - [16/Apr/2018 03:28:25] "GET /static/img/photo_bucket/pecelkeun.jpg HTTP/1.0" 200 -
127.0.0.1 - - [16/Apr/2018 03:28:25] "GET /static/img/photo_bucket/20180314_180319_0001.jpg HTTP/1.0" 200 -
127.0.0.1 - - [16/Apr/2018 03:28:25] "GET /static/img/photo_bucket/11LOGO.jpg HTTP/1.0" 200 -
127.0.0.1 - - [16/Apr/2018 03:28:40] "GET /category/Beverages HTTP/1.0" 200 -
(<database_setup.Shop object at 0x7f6532f2e0b8>, <database_setup.Article object at 0x7f6532f2ebe0>)
(<database_setup.Shop object at 0x7f6532f2ef98>, <database_setup.Article object at 0x7f6532f2e9b0>)
(<database_setup.Shop object at 0x7f6532f2e978>, <database_setup.Article object at 0x7f6532f2e8d0>)
(<database_setup.Shop object at 0x7f6532f2ec88>, <database_setup.Article object at 0x7f6532f2e390>)
(<database_setup.Shop object at 0x7f6532f2eb00>, <database_setup.Article object at 0x7f6532f2e780>)
(<database_setup.Shop object at 0x7f6532f2e6d8>, <database_setup.Article object at 0x7f6532f2e710>)
(<database_setup.Shop object at 0x7f6532f2e898>, <database_setup.Article object at 0x7f6532f2e4a8>)
(<database_setup.Shop object at 0x7f6533a7bb00>, <database_setup.Article object at 0x7f6533a7be48>)
(<database_setup.Shop object at 0x7f6533adc908>, <database_setup.Article object at 0x7f6532f89898>)
(<database_setup.Shop object at 0x7f6532f0ef28>, <database_setup.Article object at 0x7f6532f0ee10>)
(<database_setup.Shop object at 0x7f6532f0ea90>, <database_setup.Article object at 0x7f6532f0ec50>)
(<database_setup.Shop object at 0x7f6532f0ecf8>, <database_setup.Article object at 0x7f65346680f0>)
(<database_setup.Shop object at 0x7f6532f7d390>, <database_setup.Article object at 0x7f6532f7d780>)
(<database_setup.Shop object at 0x7f6532f7d278>, <database_setup.Article object at 0x7f6532f7dfd0>)
(<database_setup.Shop object at 0x7f6532f7d278>, <database_setup.Article object at 0x7f6532f7d438>)
(<database_setup.Shop object at 0x7f6532f7d278>, <database_setup.Article object at 0x7f6532f7d240>)
(<database_setup.Shop object at 0x7f6532f7d278>, <database_setup.Article object at 0x7f6532f7db38>)
(<database_setup.Shop object at 0x7f6532f7d278>, <database_setup.Article object at 0x7f6532f7d4e0>)
(<database_setup.Shop object at 0x7f6532f7dbe0>, <database_setup.Article object at 0x7f6532f7d630>)
(<database_setup.Shop object at 0x7f6532f7df60>, <database_setup.Article object at 0x7f6532f7d748>)
(<database_setup.Shop object at 0x7f6532f7df60>, <database_setup.Article object at 0x7f6532f7d400>)
(<database_setup.Shop object at 0x7f6532f7db00>, <database_setup.Article object at 0x7f6532f7d080>)
(<database_setup.Shop object at 0x7f6532f7d6a0>, <database_setup.Article object at 0x7f6532f7d860>)
(<database_setup.Shop object at 0x7f6532f7de48>, <database_setup.Article object at 0x7f653364a5c0>)
(<database_setup.Shop object at 0x7f653364a3c8>, <database_setup.Article object at 0x7f653364a630>)
(<database_setup.Shop object at 0x7f65376d8d30>, <database_setup.Article object at 0x7f65335fac50>)
(<database_setup.Shop object at 0x7f65376d8d30>, <database_setup.Article object at 0x7f65335fa400>)
(<database_setup.Shop object at 0x7f65376d8d30>, <database_setup.Article object at 0x7f65335fa208>)
(<database_setup.Shop object at 0x7f65376d8d30>, <database_setup.Article object at 0x7f6532f4f908>)
127.0.0.1 - - [16/Apr/2018 03:29:18] "GET /stat HTTP/1.0" 200 -
127.0.0.1 - - [16/Apr/2018 03:30:24] "GET /category/Education HTTP/1.0" 200 -
127.0.0.1 - - [16/Apr/2018 03:30:27] "GET /category/Beauty HTTP/1.0" 200 -
127.0.0.1 - - [16/Apr/2018 03:30:31] "GET /category/Beverages HTTP/1.0" 200 -
127.0.0.1 - - [16/Apr/2018 03:30:40] "GET /category/Food HTTP/1.0" 200 -
127.0.0.1 - - [16/Apr/2018 03:30:51] "GET /category/Arts HTTP/1.0" 200 -
127.0.0.1 - - [16/Apr/2018 03:31:10] "GET /category/Technology HTTP/1.0" 200 -
127.0.0.1 - - [16/Apr/2018 03:31:10] "GET /static/img/photo_bucket/linux.jpg HTTP/1.0" 200 -
127.0.0.1 - - [16/Apr/2018 03:33:10] "GET /category HTTP/1.0" 200 -
127.0.0.1 - - [16/Apr/2018 03:33:21] "GET /category/Arts HTTP/1.0" 200 -
127.0.0.1 - - [16/Apr/2018 03:33:36] "GET /sign_up HTTP/1.0" 200 -
127.0.0.1 - - [16/Apr/2018 03:33:55] "GET /sign_up HTTP/1.0" 200 -
127.0.0.1 - - [16/Apr/2018 03:35:56] "GET / HTTP/1.0" 200 -
127.0.0.1 - - [16/Apr/2018 03:36:04] "GET /profile HTTP/1.0" 200 -
127.0.0.1 - - [16/Apr/2018 03:36:04] "GET /static/img/photo_bucket/378830.jpg HTTP/1.0" 200 -
127.0.0.1 - - [16/Apr/2018 03:36:04] "GET /static/img/photo_bucket/S__77979685.jpg HTTP/1.0" 200 -
127.0.0.1 - - [16/Apr/2018 03:36:04] "GET /static/img/photo_bucket/18.jpg HTTP/1.0" 304 -
127.0.0.1 - - [16/Apr/2018 03:36:04] "GET /static/img/photo_bucket/S__79028285.jpg HTTP/1.0" 200 -
127.0.0.1 - - [16/Apr/2018 03:36:04] "GET /static/img/photo_bucket/S__79020088.jpg HTTP/1.0" 200 -
127.0.0.1 - - [16/Apr/2018 03:36:04] "GET /static/img/photo_bucket/S__78905543.jpg HTTP/1.0" 200 -
127.0.0.1 - - [16/Apr/2018 03:36:04] "GET /static/img/photo_bucket/11519032320775.jpg HTTP/1.0" 200 -
127.0.0.1 - - [16/Apr/2018 03:36:04] "GET /static/img/photo_bucket/Freya_black.jpg HTTP/1.0" 304 -
127.0.0.1 - - [16/Apr/2018 03:36:04] "GET /static/img/photo_bucket/produk_180313_0004.jpg HTTP/1.0" 304 -
127.0.0.1 - - [16/Apr/2018 03:36:04] "GET /static/img/photo_bucket/120180316_1_180324_0021.jpg HTTP/1.0" 304 -
127.0.0.1 - - [16/Apr/2018 03:36:04] "GET /static/img/photo_bucket/20180314_180319_0004.jpg HTTP/1.0" 304 -
127.0.0.1 - - [16/Apr/2018 03:36:04] "GET /static/img/photo_bucket/420392.jpg HTTP/1.0" 304 -
127.0.0.1 - - [16/Apr/2018 03:36:04] "GET /static/img/photo_bucket/20180316_180324_0011.jpg HTTP/1.0" 304 -
127.0.0.1 - - [16/Apr/2018 03:36:04] "GET /static/img/photo_bucket/1257967.jpg HTTP/1.0" 304 -
(<database_setup.Shop object at 0x7f653364a860>, <database_setup.Article object at 0x7f6532f68278>)
(<database_setup.Shop object at 0x7f6532f68160>, <database_setup.Article object at 0x7f6532f68748>)
(<database_setup.Shop object at 0x7f6532f68588>, <database_setup.Article object at 0x7f6533a8e0f0>)
(<database_setup.Shop object at 0x7f6533a8eda0>, <database_setup.Article object at 0x7f6533a8ed68>)
(<database_setup.Shop object at 0x7f6533a8e1d0>, <database_setup.Article object at 0x7f6533a8eeb8>)
(<database_setup.Shop object at 0x7f6533641278>, <database_setup.Article object at 0x7f6533612e10>)
(<database_setup.Shop object at 0x7f6533612c18>, <database_setup.Article object at 0x7f65336121d0>)
(<database_setup.Shop object at 0x7f65336126a0>, <database_setup.Article object at 0x7f6533612d68>)
(<database_setup.Shop object at 0x7f6533612198>, <database_setup.Article object at 0x7f65336127f0>)
(<database_setup.Shop object at 0x7f6533612550>, <database_setup.Article object at 0x7f6532ef4b00>)
(<database_setup.Shop object at 0x7f6532ef42b0>, <database_setup.Article object at 0x7f6532ef4160>)
(<database_setup.Shop object at 0x7f6532ef4eb8>, <database_setup.Article object at 0x7f6532ef4198>)
(<database_setup.Shop object at 0x7f6532ef4438>, <database_setup.Article object at 0x7f6532ef4c50>)
(<database_setup.Shop object at 0x7f6532ef4f98>, <database_setup.Article object at 0x7f6532ef4a58>)
(<database_setup.Shop object at 0x7f6532ef4f98>, <database_setup.Article object at 0x7f6532ef4278>)
(<database_setup.Shop object at 0x7f6532ef4f98>, <database_setup.Article object at 0x7f6532ef4f60>)
(<database_setup.Shop object at 0x7f6532ef4f98>, <database_setup.Article object at 0x7f6532ef4518>)
(<database_setup.Shop object at 0x7f6532ef4f98>, <database_setup.Article object at 0x7f6532ef4fd0>)
(<database_setup.Shop object at 0x7f6532ef4b38>, <database_setup.Article object at 0x7f6532ef4390>)
(<database_setup.Shop object at 0x7f6532ef4080>, <database_setup.Article object at 0x7f6532e93710>)
(<database_setup.Shop object at 0x7f6532ef4080>, <database_setup.Article object at 0x7f6532e935f8>)
(<database_setup.Shop object at 0x7f6532e93c50>, <database_setup.Article object at 0x7f6532e93128>)
(<database_setup.Shop object at 0x7f6532e93cf8>, <database_setup.Article object at 0x7f6532e93400>)
(<database_setup.Shop object at 0x7f6532e930f0>, <database_setup.Article object at 0x7f6532e93f28>)
(<database_setup.Shop object at 0x7f6532e93978>, <database_setup.Article object at 0x7f6532e93ef0>)
(<database_setup.Shop object at 0x7f6532e936d8>, <database_setup.Article object at 0x7f6532e93a20>)
(<database_setup.Shop object at 0x7f6532e936d8>, <database_setup.Article object at 0x7f6532e93ac8>)
(<database_setup.Shop object at 0x7f6532e936d8>, <database_setup.Article object at 0x7f6532e93b70>)
(<database_setup.Shop object at 0x7f6532e936d8>, <database_setup.Article object at 0x7f6532e93dd8>)
127.0.0.1 - - [16/Apr/2018 03:37:21] "GET /stat HTTP/1.0" 200 -
127.0.0.1 - - [16/Apr/2018 03:41:59] "GET / HTTP/1.0" 200 -
127.0.0.1 - - [16/Apr/2018 03:42:00] "GET /static/css/bootstrap.min.css HTTP/1.0" 200 -
127.0.0.1 - - [16/Apr/2018 03:42:00] "GET /static/js/bootstrap.min.js HTTP/1.0" 200 -
127.0.0.1 - - [16/Apr/2018 03:42:00] "GET /static/css/custom.css HTTP/1.0" 200 -
127.0.0.1 - - [16/Apr/2018 03:42:01] "GET /static/js/jquery.js HTTP/1.0" 200 -
127.0.0.1 - - [16/Apr/2018 03:42:10] "GET /static/js/custom.js HTTP/1.0" 200 -
127.0.0.1 - - [16/Apr/2018 03:42:11] "GET /static/img/logo-trimmed.png HTTP/1.0" 200 -
127.0.0.1 - - [16/Apr/2018 03:42:16] "GET / HTTP/1.0" 200 -
127.0.0.1 - - [16/Apr/2018 03:42:24] "GET /sign_up HTTP/1.0" 200 -
127.0.0.1 - - [16/Apr/2018 03:42:41] "GET /static/img/background-white.jpg HTTP/1.0" 200 -
127.0.0.1 - - [16/Apr/2018 03:48:41] "GET / HTTP/1.0" 200 -
127.0.0.1 - - [16/Apr/2018 03:50:27] "GET /category HTTP/1.0" 200 -
127.0.0.1 - - [16/Apr/2018 03:50:32] "GET /profile HTTP/1.0" 200 -
127.0.0.1 - - [16/Apr/2018 03:50:44] "GET /login HTTP/1.0" 200 -
127.0.0.1 - - [16/Apr/2018 03:55:14] "GET / HTTP/1.0" 200 -
127.0.0.1 - - [16/Apr/2018 03:55:23] "GET /profile HTTP/1.0" 200 -
127.0.0.1 - - [16/Apr/2018 03:55:25] "GET /category/Arts/a.el.project/project%20one HTTP/1.0" 200 -
127.0.0.1 - - [16/Apr/2018 03:55:25] "GET /static/img/photo_bucket/15.jpg HTTP/1.0" 304 -
127.0.0.1 - - [16/Apr/2018 03:55:25] "GET /static/img/photo_bucket/16.jpg HTTP/1.0" 304 -
127.0.0.1 - - [16/Apr/2018 03:55:25] "GET /static/img/photo_bucket/6.jpg HTTP/1.0" 304 -
127.0.0.1 - - [16/Apr/2018 03:55:25] "GET /static/img/photo_bucket/7.jpg HTTP/1.0" 304 -
127.0.0.1 - - [16/Apr/2018 03:55:25] "GET /static/img/photo_bucket/9.jpg HTTP/1.0" 304 -
[2018-04-16 03:55:26,096] ERROR in app: Exception on /category/Arts/a.el.project/loading.gif [GET]
Traceback (most recent call last):
  File "/usr/local/lib/python3.5/dist-packages/flask/app.py", line 1982, in wsgi_app
    response = self.full_dispatch_request()
  File "/usr/local/lib/python3.5/dist-packages/flask/app.py", line 1614, in full_dispatch_request
    rv = self.handle_user_exception(e)
  File "/usr/local/lib/python3.5/dist-packages/flask/app.py", line 1517, in handle_user_exception
    reraise(exc_type, exc_value, tb)
  File "/usr/local/lib/python3.5/dist-packages/flask/_compat.py", line 33, in reraise
    raise value
  File "/usr/local/lib/python3.5/dist-packages/flask/app.py", line 1612, in full_dispatch_request
    rv = self.dispatch_request()
  File "/usr/local/lib/python3.5/dist-packages/flask/app.py", line 1598, in dispatch_request
    return self.view_functions[rule.endpoint](**req.view_args)
  File "./trial.py", line 523, in showitem
    return render_template('item.html',item=items,photos=photos,content=item[0][0].content,title=item[0][0].title,nav=nav.format('','','',''),logged_in=log_in,not_logged_in=not_log_in)
IndexError: list index out of range
127.0.0.1 - - [16/Apr/2018 03:55:26] "GET /category/Arts/a.el.project/loading.gif HTTP/1.0" 500 -
[2018-04-16 03:55:26,887] ERROR in app: Exception on /category/Arts/a.el.project/loading.gif [GET]
Traceback (most recent call last):
  File "/usr/local/lib/python3.5/dist-packages/flask/app.py", line 1982, in wsgi_app
    response = self.full_dispatch_request()
  File "/usr/local/lib/python3.5/dist-packages/flask/app.py", line 1614, in full_dispatch_request
    rv = self.handle_user_exception(e)
  File "/usr/local/lib/python3.5/dist-packages/flask/app.py", line 1517, in handle_user_exception
    reraise(exc_type, exc_value, tb)
  File "/usr/local/lib/python3.5/dist-packages/flask/_compat.py", line 33, in reraise
    raise value
  File "/usr/local/lib/python3.5/dist-packages/flask/app.py", line 1612, in full_dispatch_request
    rv = self.dispatch_request()
  File "/usr/local/lib/python3.5/dist-packages/flask/app.py", line 1598, in dispatch_request
    return self.view_functions[rule.endpoint](**req.view_args)
  File "./trial.py", line 523, in showitem
    return render_template('item.html',item=items,photos=photos,content=item[0][0].content,title=item[0][0].title,nav=nav.format('','','',''),logged_in=log_in,not_logged_in=not_log_in)
IndexError: list index out of range
127.0.0.1 - - [16/Apr/2018 03:55:26] "GET /category/Arts/a.el.project/loading.gif HTTP/1.0" 500 -
127.0.0.1 - - [16/Apr/2018 03:55:27] "GET /category/Arts/a.el.project/project%20one/buy HTTP/1.0" 200 -
127.0.0.1 - - [16/Apr/2018 03:59:27] "GET /category/Arts/a.el.project/project%20one/buy HTTP/1.0" 200 -
127.0.0.1 - - [16/Apr/2018 04:01:31] "GET /login HTTP/1.0" 200 -
127.0.0.1 - - [16/Apr/2018 04:01:53] "POST /login HTTP/1.0" 302 -
127.0.0.1 - - [16/Apr/2018 04:01:54] "GET / HTTP/1.0" 200 -
127.0.0.1 - - [16/Apr/2018 04:02:02] "GET /prof HTTP/1.0" 200 -
127.0.0.1 - - [16/Apr/2018 04:02:07] "GET /prof/edit HTTP/1.0" 200 -
127.0.0.1 - - [16/Apr/2018 04:02:34] "GET /be_a_seller HTTP/1.0" 200 -
127.0.0.1 - - [16/Apr/2018 04:03:31] "GET /logout HTTP/1.0" 302 -
127.0.0.1 - - [16/Apr/2018 04:03:32] "GET / HTTP/1.0" 200 -
127.0.0.1 - - [16/Apr/2018 04:03:35] "GET /sign_up HTTP/1.0" 200 -
127.0.0.1 - - [16/Apr/2018 04:03:52] "GET /be_a_seller HTTP/1.0" 200 -
127.0.0.1 - - [16/Apr/2018 04:04:02] "GET /sign_up HTTP/1.0" 200 -
(<database_setup.Shop object at 0x7f6532f81c88>, <database_setup.Article object at 0x7f6532f81f98>)
(<database_setup.Shop object at 0x7f6532f812b0>, <database_setup.Article object at 0x7f6532f810f0>)
(<database_setup.Shop object at 0x7f6532f81f60>, <database_setup.Article object at 0x7f6532f81240>)
(<database_setup.Shop object at 0x7f6532f81be0>, <database_setup.Article object at 0x7f6532f81860>)
(<database_setup.Shop object at 0x7f6532f81e80>, <database_setup.Article object at 0x7f6533641eb8>)
(<database_setup.Shop object at 0x7f6533641400>, <database_setup.Article object at 0x7f6533a8e0b8>)
(<database_setup.Shop object at 0x7f6533a8ed68>, <database_setup.Article object at 0x7f6533a8e4e0>)
(<database_setup.Shop object at 0x7f6533a8e128>, <database_setup.Article object at 0x7f6533a8eda0>)
(<database_setup.Shop object at 0x7f6533a8efd0>, <database_setup.Article object at 0x7f6533ab14a8>)
(<database_setup.Shop object at 0x7f6533ab12b0>, <database_setup.Article object at 0x7f6533ab1390>)
(<database_setup.Shop object at 0x7f6533ab1588>, <database_setup.Article object at 0x7f6532e976a0>)
(<database_setup.Shop object at 0x7f6532e97da0>, <database_setup.Article object at 0x7f6532e979b0>)
(<database_setup.Shop object at 0x7f6532e97c50>, <database_setup.Article object at 0x7f6532e97be0>)
(<database_setup.Shop object at 0x7f6532e974e0>, <database_setup.Article object at 0x7f6532e979e8>)
(<database_setup.Shop object at 0x7f6532e974e0>, <database_setup.Article object at 0x7f6532e975c0>)
(<database_setup.Shop object at 0x7f6532e974e0>, <database_setup.Article object at 0x7f6532e97b70>)
(<database_setup.Shop object at 0x7f6532e974e0>, <database_setup.Article object at 0x7f6532e97940>)
(<database_setup.Shop object at 0x7f6532e974e0>, <database_setup.Article object at 0x7f6532e97518>)
(<database_setup.Shop object at 0x7f6532e97fd0>, <database_setup.Article object at 0x7f6532e97ac8>)
(<database_setup.Shop object at 0x7f6532e976d8>, <database_setup.Article object at 0x7f6532e97ba8>)
(<database_setup.Shop object at 0x7f6532e976d8>, <database_setup.Article object at 0x7f6532e975f8>)
(<database_setup.Shop object at 0x7f6532e97cc0>, <database_setup.Article object at 0x7f6532e97e48>)
(<database_setup.Shop object at 0x7f6532e97b38>, <database_setup.Article object at 0x7f6532e97f60>)
(<database_setup.Shop object at 0x7f6532e97f28>, <database_setup.Article object at 0x7f6532e97b00>)
(<database_setup.Shop object at 0x7f6532f7dfd0>, <database_setup.Article object at 0x7f6532f7d9e8>)
(<database_setup.Shop object at 0x7f6532f7df60>, <database_setup.Article object at 0x7f6532f7d860>)
(<database_setup.Shop object at 0x7f6532f7df60>, <database_setup.Article object at 0x7f6532f7dcf8>)
(<database_setup.Shop object at 0x7f6532f7df60>, <database_setup.Article object at 0x7f6532f7d898>)
(<database_setup.Shop object at 0x7f6532f7df60>, <database_setup.Article object at 0x7f6532f7d550>)
127.0.0.1 - - [16/Apr/2018 04:06:56] "GET /stat HTTP/1.0" 200 -
127.0.0.1 - - [16/Apr/2018 04:12:17] "GET / HTTP/1.0" 200 -
127.0.0.1 - - [16/Apr/2018 04:12:37] "GET /about HTTP/1.0" 200 -
127.0.0.1 - - [16/Apr/2018 04:14:04] "GET /profile HTTP/1.0" 200 -
127.0.0.1 - - [16/Apr/2018 04:14:16] "GET / HTTP/1.0" 200 -
127.0.0.1 - - [16/Apr/2018 04:16:33] "GET /category HTTP/1.0" 200 -
127.0.0.1 - - [16/Apr/2018 04:18:58] "GET /category HTTP/1.0" 200 -
127.0.0.1 - - [16/Apr/2018 04:19:23] "GET /category/Technology HTTP/1.0" 200 -
127.0.0.1 - - [16/Apr/2018 04:29:43] "GET /category/Arts HTTP/1.0" 200 -
127.0.0.1 - - [16/Apr/2018 04:29:52] "GET /login HTTP/1.0" 200 -
127.0.0.1 - - [16/Apr/2018 04:29:56] "GET /about HTTP/1.0" 200 -
127.0.0.1 - - [16/Apr/2018 04:29:59] "GET / HTTP/1.0" 200 -
127.0.0.1 - - [16/Apr/2018 04:30:26] "GET /category HTTP/1.0" 200 -
127.0.0.1 - - [16/Apr/2018 04:30:31] "GET /category/Beverages HTTP/1.0" 200 -
127.0.0.1 - - [16/Apr/2018 04:56:51] "GET / HTTP/1.0" 200 -
127.0.0.1 - - [16/Apr/2018 04:56:51] "GET /category HTTP/1.0" 200 -
127.0.0.1 - - [16/Apr/2018 04:56:52] "GET /static/img/background-white.jpg HTTP/1.0" 200 -
127.0.0.1 - - [16/Apr/2018 04:56:53] "GET /static/img/city-sunrise.png HTTP/1.0" 200 -
127.0.0.1 - - [16/Apr/2018 04:56:53] "GET /apple-touch-icon-120x120-precomposed.png HTTP/1.0" 404 -
127.0.0.1 - - [16/Apr/2018 04:56:54] "GET /apple-touch-icon-120x120.png HTTP/1.0" 404 -
127.0.0.1 - - [16/Apr/2018 04:56:54] "GET /apple-touch-icon.png HTTP/1.0" 404 -
127.0.0.1 - - [16/Apr/2018 04:56:55] "GET /apple-touch-icon.png HTTP/1.0" 404 -
127.0.0.1 - - [16/Apr/2018 04:56:58] "GET /profile HTTP/1.0" 200 -
127.0.0.1 - - [16/Apr/2018 04:57:00] "GET /apple-touch-icon-precomposed.png HTTP/1.0" 404 -
127.0.0.1 - - [16/Apr/2018 04:57:01] "GET /favicon.ico HTTP/1.0" 404 -
127.0.0.1 - - [16/Apr/2018 04:57:02] "GET /category/Arts/a.el.project/project%20one HTTP/1.0" 200 -
[2018-04-16 04:57:02,872] ERROR in app: Exception on /category/Arts/a.el.project/loading.gif [GET]
Traceback (most recent call last):
  File "/usr/local/lib/python3.5/dist-packages/flask/app.py", line 1982, in wsgi_app
    response = self.full_dispatch_request()
  File "/usr/local/lib/python3.5/dist-packages/flask/app.py", line 1614, in full_dispatch_request
    rv = self.handle_user_exception(e)
  File "/usr/local/lib/python3.5/dist-packages/flask/app.py", line 1517, in handle_user_exception
    reraise(exc_type, exc_value, tb)
  File "/usr/local/lib/python3.5/dist-packages/flask/_compat.py", line 33, in reraise
    raise value
  File "/usr/local/lib/python3.5/dist-packages/flask/app.py", line 1612, in full_dispatch_request
    rv = self.dispatch_request()
  File "/usr/local/lib/python3.5/dist-packages/flask/app.py", line 1598, in dispatch_request
    return self.view_functions[rule.endpoint](**req.view_args)
  File "./trial.py", line 523, in showitem
    return render_template('item.html',item=items,photos=photos,content=item[0][0].content,title=item[0][0].title,nav=nav.format('','','',''),logged_in=log_in,not_logged_in=not_log_in)
IndexError: list index out of range
127.0.0.1 - - [16/Apr/2018 04:57:02] "GET /category/Arts/a.el.project/loading.gif HTTP/1.0" 500 -
127.0.0.1 - - [16/Apr/2018 06:08:16] "GET / HTTP/1.0" 200 -
127.0.0.1 - - [16/Apr/2018 06:08:20] "GET /static/css/bootstrap.min.css HTTP/1.0" 304 -
127.0.0.1 - - [16/Apr/2018 06:08:20] "GET /static/css/custom.css HTTP/1.0" 304 -
127.0.0.1 - - [16/Apr/2018 06:08:20] "GET /static/js/jquery.js HTTP/1.0" 304 -
127.0.0.1 - - [16/Apr/2018 06:08:21] "GET /static/js/bootstrap.min.js HTTP/1.0" 304 -
127.0.0.1 - - [16/Apr/2018 06:08:21] "GET /static/js/custom.js HTTP/1.0" 304 -
127.0.0.1 - - [16/Apr/2018 06:08:22] "GET /static/img/logo-trimmed.png HTTP/1.0" 304 -
127.0.0.1 - - [16/Apr/2018 06:08:22] "GET /static/img/city-sunrise.png HTTP/1.0" 304 -
127.0.0.1 - - [16/Apr/2018 06:08:22] "GET /static/img/background-white.jpg HTTP/1.0" 304 -
127.0.0.1 - - [16/Apr/2018 06:08:23] "GET /favicon.ico HTTP/1.0" 404 -
127.0.0.1 - - [16/Apr/2018 06:09:00] "GET /about HTTP/1.0" 200 -
127.0.0.1 - - [16/Apr/2018 06:10:16] "GET /profile HTTP/1.0" 200 -
127.0.0.1 - - [16/Apr/2018 06:10:16] "GET /static/img/photo_bucket/18.jpg HTTP/1.0" 304 -
127.0.0.1 - - [16/Apr/2018 06:10:16] "GET /static/img/photo_bucket/products.jpg HTTP/1.0" 304 -
127.0.0.1 - - [16/Apr/2018 06:10:17] "GET /static/img/photo_bucket/120180316_2_180324_0006.jpg HTTP/1.0" 304 -
127.0.0.1 - - [16/Apr/2018 06:10:17] "GET /static/img/photo_bucket/Midnight_-_28k.jpg HTTP/1.0" 304 -
127.0.0.1 - - [16/Apr/2018 06:10:17] "GET /static/img/photo_bucket/20180314_180319_0004.jpg HTTP/1.0" 304 -
127.0.0.1 - - [16/Apr/2018 06:10:17] "GET /static/img/photo_bucket/378830.jpg HTTP/1.0" 304 -
127.0.0.1 - - [16/Apr/2018 06:10:17] "GET /static/img/photo_bucket/195078.jpg HTTP/1.0" 304 -
127.0.0.1 - - [16/Apr/2018 06:10:17] "GET /static/img/photo_bucket/Rumbe_Classic_-_36k.jpg HTTP/1.0" 304 -
127.0.0.1 - - [16/Apr/2018 06:10:17] "GET /static/img/photo_bucket/120180316_1_180324_0021.jpg HTTP/1.0" 304 -
127.0.0.1 - - [16/Apr/2018 06:10:17] "GET /static/img/photo_bucket/Kire_Earring_-_30k.jpg HTTP/1.0" 304 -
127.0.0.1 - - [16/Apr/2018 06:10:17] "GET /static/img/photo_bucket/Freya_black.jpg HTTP/1.0" 304 -
127.0.0.1 - - [16/Apr/2018 06:10:17] "GET /static/img/photo_bucket/S__78905543.jpg HTTP/1.0" 304 -
127.0.0.1 - - [16/Apr/2018 06:10:17] "GET /static/img/photo_bucket/Ta_Ta_Ta_Grey_-_22k.jpg HTTP/1.0" 304 -
127.0.0.1 - - [16/Apr/2018 06:10:17] "GET /static/img/photo_bucket/S__77979685.jpg HTTP/1.0" 304 -
127.0.0.1 - - [16/Apr/2018 06:10:17] "GET /static/img/photo_bucket/S__78905536.jpg HTTP/1.0" 304 -
127.0.0.1 - - [16/Apr/2018 06:10:17] "GET /static/img/photo_bucket/Arga_-_16k.jpg HTTP/1.0" 304 -
127.0.0.1 - - [16/Apr/2018 06:10:17] "GET /static/img/photo_bucket/420392.jpg HTTP/1.0" 304 -
127.0.0.1 - - [16/Apr/2018 06:10:17] "GET /static/img/photo_bucket/Minimalist_-_35k.jpg HTTP/1.0" 304 -
127.0.0.1 - - [16/Apr/2018 06:10:17] "GET /static/img/photo_bucket/11519032320775.jpg HTTP/1.0" 304 -
127.0.0.1 - - [16/Apr/2018 06:10:18] "GET /static/img/photo_bucket/produk_180313_0004.jpg HTTP/1.0" 200 -
127.0.0.1 - - [16/Apr/2018 06:10:18] "GET /static/img/photo_bucket/195083.jpg HTTP/1.0" 304 -
127.0.0.1 - - [16/Apr/2018 06:10:18] "GET /static/img/photo_bucket/S__79020088.jpg HTTP/1.0" 304 -
127.0.0.1 - - [16/Apr/2018 06:10:18] "GET /static/img/photo_bucket/S__79028285.jpg HTTP/1.0" 304 -
127.0.0.1 - - [16/Apr/2018 06:10:18] "GET /static/img/photo_bucket/1257967.jpg HTTP/1.0" 304 -
127.0.0.1 - - [16/Apr/2018 06:10:18] "GET /static/img/photo_bucket/20180316_180324_0011.jpg HTTP/1.0" 304 -
127.0.0.1 - - [16/Apr/2018 06:10:18] "GET /static/img/photo_bucket/Smoothies_buah_naga__pisang_Beauty_Blush.jpg HTTP/1.0" 200 -
127.0.0.1 - - [16/Apr/2018 06:10:19] "GET /static/img/photo_bucket/Smoothies_Mangga_Glory_Glow.jpg HTTP/1.0" 200 -
127.0.0.1 - - [16/Apr/2018 06:10:19] "GET /static/img/photo_bucket/Smoothies_Melon__bayem_Fountain_of_Joy.jpg HTTP/1.0" 200 -
127.0.0.1 - - [16/Apr/2018 06:10:20] "GET /static/img/photo_bucket/1Smoothies_Mangga_Glory_Glow.jpg HTTP/1.0" 200 -
127.0.0.1 - - [16/Apr/2018 06:10:40] "GET /category/Fashion/Kayamata/Kayamata HTTP/1.0" 200 -
127.0.0.1 - - [16/Apr/2018 06:10:40] "GET /static/js/fadeslideshow.js HTTP/1.0" 304 -
127.0.0.1 - - [16/Apr/2018 06:10:40] "GET /static/js/jquery.touchSwipe.min.js HTTP/1.0" 304 -
127.0.0.1 - - [16/Apr/2018 06:10:41] "GET /static/img/photo_bucket/Kayabandung_-_IDR_899.jpg HTTP/1.0" 200 -
127.0.0.1 - - [16/Apr/2018 06:10:41] "GET /static/img/photo_bucket/produk_180313_0010.jpg HTTP/1.0" 200 -
127.0.0.1 - - [16/Apr/2018 06:10:41] "GET /static/img/photo_bucket/produk_180313_0011.jpg HTTP/1.0" 200 -
127.0.0.1 - - [16/Apr/2018 06:10:41] "GET /static/img/photo_bucket/produk_180313_0005.jpg HTTP/1.0" 200 -
[2018-04-16 06:10:41,850] ERROR in app: Exception on /category/Fashion/Kayamata/loading.gif [GET]
Traceback (most recent call last):
  File "/usr/local/lib/python3.5/dist-packages/flask/app.py", line 1982, in wsgi_app
    response = self.full_dispatch_request()
  File "/usr/local/lib/python3.5/dist-packages/flask/app.py", line 1614, in full_dispatch_request
    rv = self.handle_user_exception(e)
  File "/usr/local/lib/python3.5/dist-packages/flask/app.py", line 1517, in handle_user_exception
    reraise(exc_type, exc_value, tb)
  File "/usr/local/lib/python3.5/dist-packages/flask/_compat.py", line 33, in reraise
    raise value
  File "/usr/local/lib/python3.5/dist-packages/flask/app.py", line 1612, in full_dispatch_request
    rv = self.dispatch_request()
  File "/usr/local/lib/python3.5/dist-packages/flask/app.py", line 1598, in dispatch_request
    return self.view_functions[rule.endpoint](**req.view_args)
  File "./trial.py", line 523, in showitem
    return render_template('item.html',item=items,photos=photos,content=item[0][0].content,title=item[0][0].title,nav=nav.format('','','',''),logged_in=log_in,not_logged_in=not_log_in)
IndexError: list index out of range
127.0.0.1 - - [16/Apr/2018 06:10:41] "GET /category/Fashion/Kayamata/loading.gif HTTP/1.0" 500 -
127.0.0.1 - - [16/Apr/2018 06:11:29] "GET /about HTTP/1.0" 200 -
127.0.0.1 - - [16/Apr/2018 06:11:30] "GET /about HTTP/1.0" 200 -
127.0.0.1 - - [16/Apr/2018 06:11:34] "GET / HTTP/1.0" 200 -
127.0.0.1 - - [16/Apr/2018 06:28:11] "GET / HTTP/1.0" 200 -
127.0.0.1 - - [16/Apr/2018 06:28:12] "GET /static/css/custom.css HTTP/1.0" 304 -
127.0.0.1 - - [16/Apr/2018 06:28:12] "GET /static/js/custom.js HTTP/1.0" 304 -
127.0.0.1 - - [16/Apr/2018 06:28:12] "GET /static/js/bootstrap.min.js HTTP/1.0" 304 -
127.0.0.1 - - [16/Apr/2018 06:28:12] "GET /static/css/bootstrap.min.css HTTP/1.0" 304 -
127.0.0.1 - - [16/Apr/2018 06:28:12] "GET /static/js/jquery.js HTTP/1.0" 304 -
127.0.0.1 - - [16/Apr/2018 06:28:13] "GET /static/img/logo-trimmed.png HTTP/1.0" 304 -
127.0.0.1 - - [16/Apr/2018 06:28:13] "GET /static/img/city-sunrise.png HTTP/1.0" 304 -
127.0.0.1 - - [16/Apr/2018 06:28:13] "GET /favicon.ico HTTP/1.0" 404 -
127.0.0.1 - - [16/Apr/2018 06:29:58] "GET /about HTTP/1.0" 200 -
127.0.0.1 - - [16/Apr/2018 06:36:03] "GET /category/Food/nagilagi/Nagilagi HTTP/1.0" 200 -
127.0.0.1 - - [16/Apr/2018 06:36:03] "GET /category/Food/nagilagi/Nagilagi HTTP/1.0" 200 -
127.0.0.1 - - [16/Apr/2018 06:36:04] "GET /static/img/logo-trimmed.png HTTP/1.0" 200 -
127.0.0.1 - - [16/Apr/2018 06:36:06] "GET /category/Food/nagilagi HTTP/1.0" 200 -
127.0.0.1 - - [16/Apr/2018 06:36:06] "GET /category/Food/nagilagi HTTP/1.0" 200 -
127.0.0.1 - - [16/Apr/2018 06:36:06] "GET /static/img/photo_bucket/1257967.jpg HTTP/1.0" 200 -
127.0.0.1 - - [16/Apr/2018 06:36:06] "GET /static/img/logo-trimmed.png HTTP/1.0" 200 -
127.0.0.1 - - [16/Apr/2018 06:36:08] "GET /static/img/photo_bucket/1257967.jpg HTTP/1.0" 200 -
(<database_setup.Shop object at 0x7f6532f2ee10>, <database_setup.Article object at 0x7f6532f2e4a8>)
(<database_setup.Shop object at 0x7f6532f2e1d0>, <database_setup.Article object at 0x7f6532f2e320>)
(<database_setup.Shop object at 0x7f6532f2e550>, <database_setup.Article object at 0x7f6532f2e400>)
(<database_setup.Shop object at 0x7f6532f41ef0>, <database_setup.Article object at 0x7f6532f412b0>)
(<database_setup.Shop object at 0x7f6532f41d68>, <database_setup.Article object at 0x7f6532f41c88>)
(<database_setup.Shop object at 0x7f6532f41d30>, <database_setup.Article object at 0x7f6532f416d8>)
(<database_setup.Shop object at 0x7f6532f414a8>, <database_setup.Article object at 0x7f6532f415f8>)
(<database_setup.Shop object at 0x7f6532f41588>, <database_setup.Article object at 0x7f6532f41be0>)
(<database_setup.Shop object at 0x7f6532f41080>, <database_setup.Article object at 0x7f6532f41208>)
(<database_setup.Shop object at 0x7f6532f41198>, <database_setup.Article object at 0x7f6532f41ba8>)
(<database_setup.Shop object at 0x7f6532f411d0>, <database_setup.Article object at 0x7f6532f410f0>)
(<database_setup.Shop object at 0x7f6532f41c50>, <database_setup.Article object at 0x7f6532f41da0>)
(<database_setup.Shop object at 0x7f6532f41eb8>, <database_setup.Article object at 0x7f6532f41048>)
(<database_setup.Shop object at 0x7f6532f41550>, <database_setup.Article object at 0x7f6532f41278>)
(<database_setup.Shop object at 0x7f6532f41550>, <database_setup.Article object at 0x7f6532f417b8>)
(<database_setup.Shop object at 0x7f6532f41550>, <database_setup.Article object at 0x7f6532f412e8>)
(<database_setup.Shop object at 0x7f6532f41550>, <database_setup.Article object at 0x7f6532f41518>)
(<database_setup.Shop object at 0x7f6532f41550>, <database_setup.Article object at 0x7f6532f41b00>)
(<database_setup.Shop object at 0x7f6532f419b0>, <database_setup.Article object at 0x7f6532f415c0>)
(<database_setup.Shop object at 0x7f6532f41e80>, <database_setup.Article object at 0x7f65335fa400>)
(<database_setup.Shop object at 0x7f6532f41e80>, <database_setup.Article object at 0x7f65335fa128>)
(<database_setup.Shop object at 0x7f65335fa208>, <database_setup.Article object at 0x7f6533ab14a8>)
(<database_setup.Shop object at 0x7f6533ab1550>, <database_setup.Article object at 0x7f6533ab12b0>)
(<database_setup.Shop object at 0x7f6533ab14e0>, <database_setup.Article object at 0x7f6532e936d8>)
(<database_setup.Shop object at 0x7f6532e93630>, <database_setup.Article object at 0x7f6532e93d30>)
(<database_setup.Shop object at 0x7f6532e93b38>, <database_setup.Article object at 0x7f6532e93978>)
(<database_setup.Shop object at 0x7f6532e93b38>, <database_setup.Article object at 0x7f6532e93b70>)
(<database_setup.Shop object at 0x7f6532e93b38>, <database_setup.Article object at 0x7f6532e93390>)
(<database_setup.Shop object at 0x7f6532e93b38>, <database_setup.Article object at 0x7f6532e93160>)
127.0.0.1 - - [16/Apr/2018 06:36:09] "GET /stat HTTP/1.0" 200 -
(<database_setup.Shop object at 0x7f6532f2e358>, <database_setup.Article object at 0x7f6532f2e128>)
(<database_setup.Shop object at 0x7f6532f2e0b8>, <database_setup.Article object at 0x7f6532e93b38>)
(<database_setup.Shop object at 0x7f6532e93160>, <database_setup.Article object at 0x7f6532e939e8>)
(<database_setup.Shop object at 0x7f6532e938d0>, <database_setup.Article object at 0x7f6532e93e80>)
(<database_setup.Shop object at 0x7f6532e93a90>, <database_setup.Article object at 0x7f6532e93198>)
(<database_setup.Shop object at 0x7f6532e93898>, <database_setup.Article object at 0x7f6532e93860>)
(<database_setup.Shop object at 0x7f6532e93048>, <database_setup.Article object at 0x7f6532e93fd0>)
(<database_setup.Shop object at 0x7f6532e93400>, <database_setup.Article object at 0x7f6532e933c8>)
(<database_setup.Shop object at 0x7f6532e93710>, <database_setup.Article object at 0x7f6532e93550>)
(<database_setup.Shop object at 0x7f6532e93dd8>, <database_setup.Article object at 0x7f6532e93470>)
(<database_setup.Shop object at 0x7f6532e93940>, <database_setup.Article object at 0x7f6532e93c50>)
(<database_setup.Shop object at 0x7f6532e93828>, <database_setup.Article object at 0x7f6532e93c18>)
(<database_setup.Shop object at 0x7f6532e93a20>, <database_setup.Article object at 0x7f6532e97b38>)
(<database_setup.Shop object at 0x7f6532e97ef0>, <database_setup.Article object at 0x7f6532e97da0>)
(<database_setup.Shop object at 0x7f6532e97ef0>, <database_setup.Article object at 0x7f6532e97550>)
(<database_setup.Shop object at 0x7f6532e97ef0>, <database_setup.Article object at 0x7f6532e97d68>)
(<database_setup.Shop object at 0x7f6532e97ef0>, <database_setup.Article object at 0x7f6532e97278>)
(<database_setup.Shop object at 0x7f6532e97ef0>, <database_setup.Article object at 0x7f6532e976d8>)
(<database_setup.Shop object at 0x7f6532e97668>, <database_setup.Article object at 0x7f6532e97e48>)
(<database_setup.Shop object at 0x7f6532e97860>, <database_setup.Article object at 0x7f6532e97438>)
(<database_setup.Shop object at 0x7f6532e97860>, <database_setup.Article object at 0x7f6532f411d0>)
(<database_setup.Shop object at 0x7f6532f414a8>, <database_setup.Article object at 0x7f6532f415f8>)
(<database_setup.Shop object at 0x7f6532f7db38>, <database_setup.Article object at 0x7f6532f7d438>)
(<database_setup.Shop object at 0x7f6532e97940>, <database_setup.Article object at 0x7f6532e97f28>)
(<database_setup.Shop object at 0x7f6532e97240>, <database_setup.Article object at 0x7f6532e97978>)
(<database_setup.Shop object at 0x7f6532e97f60>, <database_setup.Article object at 0x7f6532e97c88>)
(<database_setup.Shop object at 0x7f6532e97f60>, <database_setup.Article object at 0x7f6532e97588>)
(<database_setup.Shop object at 0x7f6532e97f60>, <database_setup.Article object at 0x7f6532e97dd8>)
(<database_setup.Shop object at 0x7f6532e97f60>, <database_setup.Article object at 0x7f6532e975f8>)
127.0.0.1 - - [16/Apr/2018 06:36:09] "GET /stat HTTP/1.0" 200 -
127.0.0.1 - - [16/Apr/2018 06:46:06] "GET /be_a_seller HTTP/1.0" 200 -
[2018-04-16 06:48:40,514] ERROR in app: Exception on /be_a_seller [POST]
Traceback (most recent call last):
  File "/usr/local/lib/python3.5/dist-packages/sqlalchemy/engine/base.py", line 1182, in _execute_context
    context)
  File "/usr/local/lib/python3.5/dist-packages/sqlalchemy/engine/default.py", line 470, in do_execute
    cursor.execute(statement, parameters)
sqlite3.IntegrityError: UNIQUE constraint failed: user.username

The above exception was the direct cause of the following exception:

Traceback (most recent call last):
  File "/usr/local/lib/python3.5/dist-packages/flask/app.py", line 1982, in wsgi_app
    response = self.full_dispatch_request()
  File "/usr/local/lib/python3.5/dist-packages/flask/app.py", line 1614, in full_dispatch_request
    rv = self.handle_user_exception(e)
  File "/usr/local/lib/python3.5/dist-packages/flask/app.py", line 1517, in handle_user_exception
    reraise(exc_type, exc_value, tb)
  File "/usr/local/lib/python3.5/dist-packages/flask/_compat.py", line 33, in reraise
    raise value
  File "/usr/local/lib/python3.5/dist-packages/flask/app.py", line 1612, in full_dispatch_request
    rv = self.dispatch_request()
  File "/usr/local/lib/python3.5/dist-packages/flask/app.py", line 1598, in dispatch_request
    return self.view_functions[rule.endpoint](**req.view_args)
  File "./trial.py", line 416, in daftar_seller
    session.commit()
  File "/usr/local/lib/python3.5/dist-packages/sqlalchemy/orm/session.py", line 921, in commit
    self.transaction.commit()
  File "/usr/local/lib/python3.5/dist-packages/sqlalchemy/orm/session.py", line 461, in commit
    self._prepare_impl()
  File "/usr/local/lib/python3.5/dist-packages/sqlalchemy/orm/session.py", line 441, in _prepare_impl
    self.session.flush()
  File "/usr/local/lib/python3.5/dist-packages/sqlalchemy/orm/session.py", line 2192, in flush
    self._flush(objects)
  File "/usr/local/lib/python3.5/dist-packages/sqlalchemy/orm/session.py", line 2312, in _flush
    transaction.rollback(_capture_exception=True)
  File "/usr/local/lib/python3.5/dist-packages/sqlalchemy/util/langhelpers.py", line 66, in __exit__
    compat.reraise(exc_type, exc_value, exc_tb)
  File "/usr/local/lib/python3.5/dist-packages/sqlalchemy/util/compat.py", line 187, in reraise
    raise value
  File "/usr/local/lib/python3.5/dist-packages/sqlalchemy/orm/session.py", line 2276, in _flush
    flush_context.execute()
  File "/usr/local/lib/python3.5/dist-packages/sqlalchemy/orm/unitofwork.py", line 389, in execute
    rec.execute(self)
  File "/usr/local/lib/python3.5/dist-packages/sqlalchemy/orm/unitofwork.py", line 548, in execute
    uow
  File "/usr/local/lib/python3.5/dist-packages/sqlalchemy/orm/persistence.py", line 181, in save_obj
    mapper, table, insert)
  File "/usr/local/lib/python3.5/dist-packages/sqlalchemy/orm/persistence.py", line 799, in _emit_insert_statements
    execute(statement, multiparams)
  File "/usr/local/lib/python3.5/dist-packages/sqlalchemy/engine/base.py", line 945, in execute
    return meth(self, multiparams, params)
  File "/usr/local/lib/python3.5/dist-packages/sqlalchemy/sql/elements.py", line 263, in _execute_on_connection
    return connection._execute_clauseelement(self, multiparams, params)
  File "/usr/local/lib/python3.5/dist-packages/sqlalchemy/engine/base.py", line 1053, in _execute_clauseelement
    compiled_sql, distilled_params
  File "/usr/local/lib/python3.5/dist-packages/sqlalchemy/engine/base.py", line 1189, in _execute_context
    context)
  File "/usr/local/lib/python3.5/dist-packages/sqlalchemy/engine/base.py", line 1402, in _handle_dbapi_exception
    exc_info
  File "/usr/local/lib/python3.5/dist-packages/sqlalchemy/util/compat.py", line 203, in raise_from_cause
    reraise(type(exception), exception, tb=exc_tb, cause=cause)
  File "/usr/local/lib/python3.5/dist-packages/sqlalchemy/util/compat.py", line 186, in reraise
    raise value.with_traceback(tb)
  File "/usr/local/lib/python3.5/dist-packages/sqlalchemy/engine/base.py", line 1182, in _execute_context
    context)
  File "/usr/local/lib/python3.5/dist-packages/sqlalchemy/engine/default.py", line 470, in do_execute
    cursor.execute(statement, parameters)
sqlalchemy.exc.IntegrityError: (sqlite3.IntegrityError) UNIQUE constraint failed: user.username [SQL: 'INSERT INTO user (username, password, name, email, gender, birth_date, phone_number, address, photodir, verified) VALUES (?, ?, ?, ?, ?, ?, ?, ?, ?, ?)'] [parameters: ('cethik', '$2b$12$60UQCzVKjIi5vsiYQvQ.AOq0itYi.lnRuvNFOPtKbsoM1uPnWRt/u', 'Erwan', 'cethik7@gmail.com', 'Male', '2018-01-01', '081224035608', 'Bandung', './static/img/photo_bucket/1logo.jpg', 0)]
127.0.0.1 - - [16/Apr/2018 06:48:40] "POST /be_a_seller HTTP/1.0" 500 -
[2018-04-16 06:49:27,244] ERROR in app: Exception on /be_a_seller [POST]
Traceback (most recent call last):
  File "/usr/local/lib/python3.5/dist-packages/flask/app.py", line 1982, in wsgi_app
    response = self.full_dispatch_request()
  File "/usr/local/lib/python3.5/dist-packages/flask/app.py", line 1614, in full_dispatch_request
    rv = self.handle_user_exception(e)
  File "/usr/local/lib/python3.5/dist-packages/flask/app.py", line 1517, in handle_user_exception
    reraise(exc_type, exc_value, tb)
  File "/usr/local/lib/python3.5/dist-packages/flask/_compat.py", line 33, in reraise
    raise value
  File "/usr/local/lib/python3.5/dist-packages/flask/app.py", line 1612, in full_dispatch_request
    rv = self.dispatch_request()
  File "/usr/local/lib/python3.5/dist-packages/flask/app.py", line 1598, in dispatch_request
    return self.view_functions[rule.endpoint](**req.view_args)
  File "./trial.py", line 405, in daftar_seller
    while(session.query(ArticlePhoto).filter_by(dir=photodir).first() or session.query(ShopPhoto).filter_by(dir=photodir).first() or session.query(User).filter_by(photodir=photodir).first()):
  File "/usr/local/lib/python3.5/dist-packages/sqlalchemy/orm/query.py", line 2755, in first
    ret = list(self[0:1])
  File "/usr/local/lib/python3.5/dist-packages/sqlalchemy/orm/query.py", line 2547, in __getitem__
    return list(res)
  File "/usr/local/lib/python3.5/dist-packages/sqlalchemy/orm/query.py", line 2855, in __iter__
    return self._execute_and_instances(context)
  File "/usr/local/lib/python3.5/dist-packages/sqlalchemy/orm/query.py", line 2876, in _execute_and_instances
    close_with_result=True)
  File "/usr/local/lib/python3.5/dist-packages/sqlalchemy/orm/query.py", line 2885, in _get_bind_args
    **kw
  File "/usr/local/lib/python3.5/dist-packages/sqlalchemy/orm/query.py", line 2867, in _connection_from_session
    conn = self.session.connection(**kw)
  File "/usr/local/lib/python3.5/dist-packages/sqlalchemy/orm/session.py", line 1013, in connection
    execution_options=execution_options)
  File "/usr/local/lib/python3.5/dist-packages/sqlalchemy/orm/session.py", line 1018, in _connection_for_bind
    engine, execution_options)
  File "/usr/local/lib/python3.5/dist-packages/sqlalchemy/orm/session.py", line 382, in _connection_for_bind
    self._assert_active()
  File "/usr/local/lib/python3.5/dist-packages/sqlalchemy/orm/session.py", line 276, in _assert_active
    % self._rollback_exception
sqlalchemy.exc.InvalidRequestError: This Session's transaction has been rolled back due to a previous exception during flush. To begin a new transaction with this Session, first issue Session.rollback(). Original exception was: (sqlite3.IntegrityError) UNIQUE constraint failed: user.username [SQL: 'INSERT INTO user (username, password, name, email, gender, birth_date, phone_number, address, photodir, verified) VALUES (?, ?, ?, ?, ?, ?, ?, ?, ?, ?)'] [parameters: ('cethik', '$2b$12$60UQCzVKjIi5vsiYQvQ.AOq0itYi.lnRuvNFOPtKbsoM1uPnWRt/u', 'Erwan', 'cethik7@gmail.com', 'Male', '2018-01-01', '081224035608', 'Bandung', './static/img/photo_bucket/1logo.jpg', 0)]
127.0.0.1 - - [16/Apr/2018 06:49:27] "POST /be_a_seller HTTP/1.0" 500 -
[2018-04-16 06:49:48,423] ERROR in app: Exception on /be_a_seller [POST]
Traceback (most recent call last):
  File "/usr/local/lib/python3.5/dist-packages/flask/app.py", line 1982, in wsgi_app
    response = self.full_dispatch_request()
  File "/usr/local/lib/python3.5/dist-packages/flask/app.py", line 1614, in full_dispatch_request
    rv = self.handle_user_exception(e)
  File "/usr/local/lib/python3.5/dist-packages/flask/app.py", line 1517, in handle_user_exception
    reraise(exc_type, exc_value, tb)
  File "/usr/local/lib/python3.5/dist-packages/flask/_compat.py", line 33, in reraise
    raise value
  File "/usr/local/lib/python3.5/dist-packages/flask/app.py", line 1612, in full_dispatch_request
    rv = self.dispatch_request()
  File "/usr/local/lib/python3.5/dist-packages/flask/app.py", line 1598, in dispatch_request
    return self.view_functions[rule.endpoint](**req.view_args)
  File "./trial.py", line 405, in daftar_seller
    while(session.query(ArticlePhoto).filter_by(dir=photodir).first() or session.query(ShopPhoto).filter_by(dir=photodir).first() or session.query(User).filter_by(photodir=photodir).first()):
  File "/usr/local/lib/python3.5/dist-packages/sqlalchemy/orm/query.py", line 2755, in first
    ret = list(self[0:1])
  File "/usr/local/lib/python3.5/dist-packages/sqlalchemy/orm/query.py", line 2547, in __getitem__
    return list(res)
  File "/usr/local/lib/python3.5/dist-packages/sqlalchemy/orm/query.py", line 2855, in __iter__
    return self._execute_and_instances(context)
  File "/usr/local/lib/python3.5/dist-packages/sqlalchemy/orm/query.py", line 2876, in _execute_and_instances
    close_with_result=True)
  File "/usr/local/lib/python3.5/dist-packages/sqlalchemy/orm/query.py", line 2885, in _get_bind_args
    **kw
  File "/usr/local/lib/python3.5/dist-packages/sqlalchemy/orm/query.py", line 2867, in _connection_from_session
    conn = self.session.connection(**kw)
  File "/usr/local/lib/python3.5/dist-packages/sqlalchemy/orm/session.py", line 1013, in connection
    execution_options=execution_options)
  File "/usr/local/lib/python3.5/dist-packages/sqlalchemy/orm/session.py", line 1018, in _connection_for_bind
    engine, execution_options)
  File "/usr/local/lib/python3.5/dist-packages/sqlalchemy/orm/session.py", line 382, in _connection_for_bind
    self._assert_active()
  File "/usr/local/lib/python3.5/dist-packages/sqlalchemy/orm/session.py", line 276, in _assert_active
    % self._rollback_exception
sqlalchemy.exc.InvalidRequestError: This Session's transaction has been rolled back due to a previous exception during flush. To begin a new transaction with this Session, first issue Session.rollback(). Original exception was: (sqlite3.IntegrityError) UNIQUE constraint failed: user.username [SQL: 'INSERT INTO user (username, password, name, email, gender, birth_date, phone_number, address, photodir, verified) VALUES (?, ?, ?, ?, ?, ?, ?, ?, ?, ?)'] [parameters: ('cethik', '$2b$12$60UQCzVKjIi5vsiYQvQ.AOq0itYi.lnRuvNFOPtKbsoM1uPnWRt/u', 'Erwan', 'cethik7@gmail.com', 'Male', '2018-01-01', '081224035608', 'Bandung', './static/img/photo_bucket/1logo.jpg', 0)]
127.0.0.1 - - [16/Apr/2018 06:49:48] "POST /be_a_seller HTTP/1.0" 500 -
[2018-04-16 06:51:37,259] ERROR in app: Exception on /be_a_seller [POST]
Traceback (most recent call last):
  File "/usr/local/lib/python3.5/dist-packages/flask/app.py", line 1982, in wsgi_app
    response = self.full_dispatch_request()
  File "/usr/local/lib/python3.5/dist-packages/flask/app.py", line 1614, in full_dispatch_request
    rv = self.handle_user_exception(e)
  File "/usr/local/lib/python3.5/dist-packages/flask/app.py", line 1517, in handle_user_exception
    reraise(exc_type, exc_value, tb)
  File "/usr/local/lib/python3.5/dist-packages/flask/_compat.py", line 33, in reraise
    raise value
  File "/usr/local/lib/python3.5/dist-packages/flask/app.py", line 1612, in full_dispatch_request
    rv = self.dispatch_request()
  File "/usr/local/lib/python3.5/dist-packages/flask/app.py", line 1598, in dispatch_request
    return self.view_functions[rule.endpoint](**req.view_args)
  File "./trial.py", line 405, in daftar_seller
    while(session.query(ArticlePhoto).filter_by(dir=photodir).first() or session.query(ShopPhoto).filter_by(dir=photodir).first() or session.query(User).filter_by(photodir=photodir).first()):
  File "/usr/local/lib/python3.5/dist-packages/sqlalchemy/orm/query.py", line 2755, in first
    ret = list(self[0:1])
  File "/usr/local/lib/python3.5/dist-packages/sqlalchemy/orm/query.py", line 2547, in __getitem__
    return list(res)
  File "/usr/local/lib/python3.5/dist-packages/sqlalchemy/orm/query.py", line 2855, in __iter__
    return self._execute_and_instances(context)
  File "/usr/local/lib/python3.5/dist-packages/sqlalchemy/orm/query.py", line 2876, in _execute_and_instances
    close_with_result=True)
  File "/usr/local/lib/python3.5/dist-packages/sqlalchemy/orm/query.py", line 2885, in _get_bind_args
    **kw
  File "/usr/local/lib/python3.5/dist-packages/sqlalchemy/orm/query.py", line 2867, in _connection_from_session
    conn = self.session.connection(**kw)
  File "/usr/local/lib/python3.5/dist-packages/sqlalchemy/orm/session.py", line 1013, in connection
    execution_options=execution_options)
  File "/usr/local/lib/python3.5/dist-packages/sqlalchemy/orm/session.py", line 1018, in _connection_for_bind
    engine, execution_options)
  File "/usr/local/lib/python3.5/dist-packages/sqlalchemy/orm/session.py", line 382, in _connection_for_bind
    self._assert_active()
  File "/usr/local/lib/python3.5/dist-packages/sqlalchemy/orm/session.py", line 276, in _assert_active
    % self._rollback_exception
sqlalchemy.exc.InvalidRequestError: This Session's transaction has been rolled back due to a previous exception during flush. To begin a new transaction with this Session, first issue Session.rollback(). Original exception was: (sqlite3.IntegrityError) UNIQUE constraint failed: user.username [SQL: 'INSERT INTO user (username, password, name, email, gender, birth_date, phone_number, address, photodir, verified) VALUES (?, ?, ?, ?, ?, ?, ?, ?, ?, ?)'] [parameters: ('cethik', '$2b$12$60UQCzVKjIi5vsiYQvQ.AOq0itYi.lnRuvNFOPtKbsoM1uPnWRt/u', 'Erwan', 'cethik7@gmail.com', 'Male', '2018-01-01', '081224035608', 'Bandung', './static/img/photo_bucket/1logo.jpg', 0)]
127.0.0.1 - - [16/Apr/2018 06:51:37] "POST /be_a_seller HTTP/1.0" 500 -
[2018-04-16 06:52:32,823] ERROR in app: Exception on /be_a_seller [POST]
Traceback (most recent call last):
  File "/usr/local/lib/python3.5/dist-packages/flask/app.py", line 1982, in wsgi_app
    response = self.full_dispatch_request()
  File "/usr/local/lib/python3.5/dist-packages/flask/app.py", line 1614, in full_dispatch_request
    rv = self.handle_user_exception(e)
  File "/usr/local/lib/python3.5/dist-packages/flask/app.py", line 1517, in handle_user_exception
    reraise(exc_type, exc_value, tb)
  File "/usr/local/lib/python3.5/dist-packages/flask/_compat.py", line 33, in reraise
    raise value
  File "/usr/local/lib/python3.5/dist-packages/flask/app.py", line 1612, in full_dispatch_request
    rv = self.dispatch_request()
  File "/usr/local/lib/python3.5/dist-packages/flask/app.py", line 1598, in dispatch_request
    return self.view_functions[rule.endpoint](**req.view_args)
  File "./trial.py", line 405, in daftar_seller
    while(session.query(ArticlePhoto).filter_by(dir=photodir).first() or session.query(ShopPhoto).filter_by(dir=photodir).first() or session.query(User).filter_by(photodir=photodir).first()):
  File "/usr/local/lib/python3.5/dist-packages/sqlalchemy/orm/query.py", line 2755, in first
    ret = list(self[0:1])
  File "/usr/local/lib/python3.5/dist-packages/sqlalchemy/orm/query.py", line 2547, in __getitem__
    return list(res)
  File "/usr/local/lib/python3.5/dist-packages/sqlalchemy/orm/query.py", line 2855, in __iter__
    return self._execute_and_instances(context)
  File "/usr/local/lib/python3.5/dist-packages/sqlalchemy/orm/query.py", line 2876, in _execute_and_instances
    close_with_result=True)
  File "/usr/local/lib/python3.5/dist-packages/sqlalchemy/orm/query.py", line 2885, in _get_bind_args
    **kw
  File "/usr/local/lib/python3.5/dist-packages/sqlalchemy/orm/query.py", line 2867, in _connection_from_session
    conn = self.session.connection(**kw)
  File "/usr/local/lib/python3.5/dist-packages/sqlalchemy/orm/session.py", line 1013, in connection
    execution_options=execution_options)
  File "/usr/local/lib/python3.5/dist-packages/sqlalchemy/orm/session.py", line 1018, in _connection_for_bind
    engine, execution_options)
  File "/usr/local/lib/python3.5/dist-packages/sqlalchemy/orm/session.py", line 382, in _connection_for_bind
    self._assert_active()
  File "/usr/local/lib/python3.5/dist-packages/sqlalchemy/orm/session.py", line 276, in _assert_active
    % self._rollback_exception
sqlalchemy.exc.InvalidRequestError: This Session's transaction has been rolled back due to a previous exception during flush. To begin a new transaction with this Session, first issue Session.rollback(). Original exception was: (sqlite3.IntegrityError) UNIQUE constraint failed: user.username [SQL: 'INSERT INTO user (username, password, name, email, gender, birth_date, phone_number, address, photodir, verified) VALUES (?, ?, ?, ?, ?, ?, ?, ?, ?, ?)'] [parameters: ('cethik', '$2b$12$60UQCzVKjIi5vsiYQvQ.AOq0itYi.lnRuvNFOPtKbsoM1uPnWRt/u', 'Erwan', 'cethik7@gmail.com', 'Male', '2018-01-01', '081224035608', 'Bandung', './static/img/photo_bucket/1logo.jpg', 0)]
127.0.0.1 - - [16/Apr/2018 06:52:32] "POST /be_a_seller HTTP/1.0" 500 -
127.0.0.1 - - [16/Apr/2018 06:52:35] "GET / HTTP/1.0" 200 -
[2018-04-16 06:52:40,112] ERROR in app: Exception on /profile [GET]
Traceback (most recent call last):
  File "/usr/local/lib/python3.5/dist-packages/flask/app.py", line 1982, in wsgi_app
    response = self.full_dispatch_request()
  File "/usr/local/lib/python3.5/dist-packages/flask/app.py", line 1614, in full_dispatch_request
    rv = self.handle_user_exception(e)
  File "/usr/local/lib/python3.5/dist-packages/flask/app.py", line 1517, in handle_user_exception
    reraise(exc_type, exc_value, tb)
  File "/usr/local/lib/python3.5/dist-packages/flask/_compat.py", line 33, in reraise
    raise value
  File "/usr/local/lib/python3.5/dist-packages/flask/app.py", line 1612, in full_dispatch_request
    rv = self.dispatch_request()
  File "/usr/local/lib/python3.5/dist-packages/flask/app.py", line 1598, in dispatch_request
    return self.view_functions[rule.endpoint](**req.view_args)
  File "./trial.py", line 435, in profile
    shops = session.query(Shop,Article,ArticlePhoto,ShopTag).join(Article).join(ArticlePhoto).join(ShopTag).all()
  File "/usr/local/lib/python3.5/dist-packages/sqlalchemy/orm/query.py", line 2703, in all
    return list(self)
  File "/usr/local/lib/python3.5/dist-packages/sqlalchemy/orm/query.py", line 2855, in __iter__
    return self._execute_and_instances(context)
  File "/usr/local/lib/python3.5/dist-packages/sqlalchemy/orm/query.py", line 2876, in _execute_and_instances
    close_with_result=True)
  File "/usr/local/lib/python3.5/dist-packages/sqlalchemy/orm/query.py", line 2885, in _get_bind_args
    **kw
  File "/usr/local/lib/python3.5/dist-packages/sqlalchemy/orm/query.py", line 2867, in _connection_from_session
    conn = self.session.connection(**kw)
  File "/usr/local/lib/python3.5/dist-packages/sqlalchemy/orm/session.py", line 1013, in connection
    execution_options=execution_options)
  File "/usr/local/lib/python3.5/dist-packages/sqlalchemy/orm/session.py", line 1018, in _connection_for_bind
    engine, execution_options)
  File "/usr/local/lib/python3.5/dist-packages/sqlalchemy/orm/session.py", line 382, in _connection_for_bind
    self._assert_active()
  File "/usr/local/lib/python3.5/dist-packages/sqlalchemy/orm/session.py", line 276, in _assert_active
    % self._rollback_exception
sqlalchemy.exc.InvalidRequestError: This Session's transaction has been rolled back due to a previous exception during flush. To begin a new transaction with this Session, first issue Session.rollback(). Original exception was: (sqlite3.IntegrityError) UNIQUE constraint failed: user.username [SQL: 'INSERT INTO user (username, password, name, email, gender, birth_date, phone_number, address, photodir, verified) VALUES (?, ?, ?, ?, ?, ?, ?, ?, ?, ?)'] [parameters: ('cethik', '$2b$12$60UQCzVKjIi5vsiYQvQ.AOq0itYi.lnRuvNFOPtKbsoM1uPnWRt/u', 'Erwan', 'cethik7@gmail.com', 'Male', '2018-01-01', '081224035608', 'Bandung', './static/img/photo_bucket/1logo.jpg', 0)]
127.0.0.1 - - [16/Apr/2018 06:52:40] "GET /profile HTTP/1.0" 500 -
127.0.0.1 - - [16/Apr/2018 06:52:40] "GET /static/img/photo_bucket/18.jpg HTTP/1.0" 304 -
127.0.0.1 - - [16/Apr/2018 06:52:40] "GET /static/img/photo_bucket/produk_180313_0004.jpg HTTP/1.0" 304 -
127.0.0.1 - - [16/Apr/2018 06:52:40] "GET /static/img/photo_bucket/products.jpg HTTP/1.0" 304 -
127.0.0.1 - - [16/Apr/2018 06:52:40] "GET /static/img/photo_bucket/420392.jpg HTTP/1.0" 304 -
127.0.0.1 - - [16/Apr/2018 06:52:40] "GET /static/img/photo_bucket/11519032320775.jpg HTTP/1.0" 304 -
127.0.0.1 - - [16/Apr/2018 06:52:40] "GET /static/img/photo_bucket/Minimalist_-_35k.jpg HTTP/1.0" 304 -
127.0.0.1 - - [16/Apr/2018 06:52:40] "GET /static/img/photo_bucket/Smoothies_Mangga_Glory_Glow.jpg HTTP/1.0" 200 -
127.0.0.1 - - [16/Apr/2018 06:52:40] "GET /static/img/photo_bucket/S__79028285.jpg HTTP/1.0" 304 -
127.0.0.1 - - [16/Apr/2018 06:52:40] "GET /static/img/photo_bucket/120180316_1_180324_0021.jpg HTTP/1.0" 304 -
127.0.0.1 - - [16/Apr/2018 06:52:40] "GET /static/img/photo_bucket/195078.jpg HTTP/1.0" 304 -
127.0.0.1 - - [16/Apr/2018 06:52:40] "GET /static/img/photo_bucket/S__77979685.jpg HTTP/1.0" 304 -
127.0.0.1 - - [16/Apr/2018 06:52:40] "GET /static/img/photo_bucket/Arga_-_16k.jpg HTTP/1.0" 304 -
127.0.0.1 - - [16/Apr/2018 06:52:41] "GET /static/img/photo_bucket/S__78905536.jpg HTTP/1.0" 304 -
127.0.0.1 - - [16/Apr/2018 06:52:41] "GET /static/img/photo_bucket/Rumbe_Classic_-_36k.jpg HTTP/1.0" 304 -
127.0.0.1 - - [16/Apr/2018 06:52:41] "GET /static/img/photo_bucket/Smoothies_buah_naga__pisang_Beauty_Blush.jpg HTTP/1.0" 200 -
127.0.0.1 - - [16/Apr/2018 06:52:41] "GET /static/img/photo_bucket/20180316_180324_0011.jpg HTTP/1.0" 304 -
127.0.0.1 - - [16/Apr/2018 06:52:41] "GET /static/img/photo_bucket/Smoothies_Melon__bayem_Fountain_of_Joy.jpg HTTP/1.0" 200 -
127.0.0.1 - - [16/Apr/2018 06:52:41] "GET /static/img/photo_bucket/1257967.jpg HTTP/1.0" 304 -
127.0.0.1 - - [16/Apr/2018 06:52:41] "GET /static/img/photo_bucket/120180316_2_180324_0006.jpg HTTP/1.0" 304 -
127.0.0.1 - - [16/Apr/2018 06:52:41] "GET /static/img/photo_bucket/378830.jpg HTTP/1.0" 304 -
127.0.0.1 - - [16/Apr/2018 06:52:41] "GET /static/img/photo_bucket/Ta_Ta_Ta_Grey_-_22k.jpg HTTP/1.0" 304 -
127.0.0.1 - - [16/Apr/2018 06:52:41] "GET /static/img/photo_bucket/195083.jpg HTTP/1.0" 304 -
127.0.0.1 - - [16/Apr/2018 06:52:41] "GET /static/img/photo_bucket/S__78905543.jpg HTTP/1.0" 304 -
127.0.0.1 - - [16/Apr/2018 06:52:41] "GET /static/img/photo_bucket/Midnight_-_28k.jpg HTTP/1.0" 304 -
127.0.0.1 - - [16/Apr/2018 06:52:41] "GET /static/img/photo_bucket/Kire_Earring_-_30k.jpg HTTP/1.0" 304 -
127.0.0.1 - - [16/Apr/2018 06:52:41] "GET /static/img/photo_bucket/S__79020088.jpg HTTP/1.0" 304 -
127.0.0.1 - - [16/Apr/2018 06:52:41] "GET /static/img/photo_bucket/20180314_180319_0004.jpg HTTP/1.0" 304 -
127.0.0.1 - - [16/Apr/2018 06:52:41] "GET /static/img/photo_bucket/Freya_black.jpg HTTP/1.0" 304 -
127.0.0.1 - - [16/Apr/2018 06:52:42] "GET /static/img/photo_bucket/1Smoothies_Mangga_Glory_Glow.jpg HTTP/1.0" 200 -
127.0.0.1 - - [16/Apr/2018 06:53:26] "GET /category HTTP/1.0" 200 -
[2018-04-16 06:53:34,478] ERROR in app: Exception on /category/Fashion [GET]
Traceback (most recent call last):
  File "/usr/local/lib/python3.5/dist-packages/flask/app.py", line 1982, in wsgi_app
    response = self.full_dispatch_request()
  File "/usr/local/lib/python3.5/dist-packages/flask/app.py", line 1614, in full_dispatch_request
    rv = self.handle_user_exception(e)
  File "/usr/local/lib/python3.5/dist-packages/flask/app.py", line 1517, in handle_user_exception
    reraise(exc_type, exc_value, tb)
  File "/usr/local/lib/python3.5/dist-packages/flask/_compat.py", line 33, in reraise
    raise value
  File "/usr/local/lib/python3.5/dist-packages/flask/app.py", line 1612, in full_dispatch_request
    rv = self.dispatch_request()
  File "/usr/local/lib/python3.5/dist-packages/flask/app.py", line 1598, in dispatch_request
    return self.view_functions[rule.endpoint](**req.view_args)
  File "./trial.py", line 467, in shoplist
    shopname = session.query(Shop,ShopTag,ShopPhoto).join(ShopTag).filter_by(tag=category).join(ShopPhoto).all()
  File "/usr/local/lib/python3.5/dist-packages/sqlalchemy/orm/query.py", line 2703, in all
    return list(self)
  File "/usr/local/lib/python3.5/dist-packages/sqlalchemy/orm/query.py", line 2855, in __iter__
    return self._execute_and_instances(context)
  File "/usr/local/lib/python3.5/dist-packages/sqlalchemy/orm/query.py", line 2876, in _execute_and_instances
    close_with_result=True)
  File "/usr/local/lib/python3.5/dist-packages/sqlalchemy/orm/query.py", line 2885, in _get_bind_args
    **kw
  File "/usr/local/lib/python3.5/dist-packages/sqlalchemy/orm/query.py", line 2867, in _connection_from_session
    conn = self.session.connection(**kw)
  File "/usr/local/lib/python3.5/dist-packages/sqlalchemy/orm/session.py", line 1013, in connection
    execution_options=execution_options)
  File "/usr/local/lib/python3.5/dist-packages/sqlalchemy/orm/session.py", line 1018, in _connection_for_bind
    engine, execution_options)
  File "/usr/local/lib/python3.5/dist-packages/sqlalchemy/orm/session.py", line 382, in _connection_for_bind
    self._assert_active()
  File "/usr/local/lib/python3.5/dist-packages/sqlalchemy/orm/session.py", line 276, in _assert_active
    % self._rollback_exception
sqlalchemy.exc.InvalidRequestError: This Session's transaction has been rolled back due to a previous exception during flush. To begin a new transaction with this Session, first issue Session.rollback(). Original exception was: (sqlite3.IntegrityError) UNIQUE constraint failed: user.username [SQL: 'INSERT INTO user (username, password, name, email, gender, birth_date, phone_number, address, photodir, verified) VALUES (?, ?, ?, ?, ?, ?, ?, ?, ?, ?)'] [parameters: ('cethik', '$2b$12$60UQCzVKjIi5vsiYQvQ.AOq0itYi.lnRuvNFOPtKbsoM1uPnWRt/u', 'Erwan', 'cethik7@gmail.com', 'Male', '2018-01-01', '081224035608', 'Bandung', './static/img/photo_bucket/1logo.jpg', 0)]
127.0.0.1 - - [16/Apr/2018 06:53:34] "GET /category/Fashion HTTP/1.0" 500 -
[2018-04-16 06:53:38,351] ERROR in app: Exception on /category/Fashion [GET]
Traceback (most recent call last):
  File "/usr/local/lib/python3.5/dist-packages/flask/app.py", line 1982, in wsgi_app
    response = self.full_dispatch_request()
  File "/usr/local/lib/python3.5/dist-packages/flask/app.py", line 1614, in full_dispatch_request
    rv = self.handle_user_exception(e)
  File "/usr/local/lib/python3.5/dist-packages/flask/app.py", line 1517, in handle_user_exception
    reraise(exc_type, exc_value, tb)
  File "/usr/local/lib/python3.5/dist-packages/flask/_compat.py", line 33, in reraise
    raise value
  File "/usr/local/lib/python3.5/dist-packages/flask/app.py", line 1612, in full_dispatch_request
    rv = self.dispatch_request()
  File "/usr/local/lib/python3.5/dist-packages/flask/app.py", line 1598, in dispatch_request
    return self.view_functions[rule.endpoint](**req.view_args)
  File "./trial.py", line 467, in shoplist
    shopname = session.query(Shop,ShopTag,ShopPhoto).join(ShopTag).filter_by(tag=category).join(ShopPhoto).all()
  File "/usr/local/lib/python3.5/dist-packages/sqlalchemy/orm/query.py", line 2703, in all
    return list(self)
  File "/usr/local/lib/python3.5/dist-packages/sqlalchemy/orm/query.py", line 2855, in __iter__
    return self._execute_and_instances(context)
  File "/usr/local/lib/python3.5/dist-packages/sqlalchemy/orm/query.py", line 2876, in _execute_and_instances
    close_with_result=True)
  File "/usr/local/lib/python3.5/dist-packages/sqlalchemy/orm/query.py", line 2885, in _get_bind_args
    **kw
  File "/usr/local/lib/python3.5/dist-packages/sqlalchemy/orm/query.py", line 2867, in _connection_from_session
    conn = self.session.connection(**kw)
  File "/usr/local/lib/python3.5/dist-packages/sqlalchemy/orm/session.py", line 1013, in connection
    execution_options=execution_options)
  File "/usr/local/lib/python3.5/dist-packages/sqlalchemy/orm/session.py", line 1018, in _connection_for_bind
    engine, execution_options)
  File "/usr/local/lib/python3.5/dist-packages/sqlalchemy/orm/session.py", line 382, in _connection_for_bind
    self._assert_active()
  File "/usr/local/lib/python3.5/dist-packages/sqlalchemy/orm/session.py", line 276, in _assert_active
    % self._rollback_exception
sqlalchemy.exc.InvalidRequestError: This Session's transaction has been rolled back due to a previous exception during flush. To begin a new transaction with this Session, first issue Session.rollback(). Original exception was: (sqlite3.IntegrityError) UNIQUE constraint failed: user.username [SQL: 'INSERT INTO user (username, password, name, email, gender, birth_date, phone_number, address, photodir, verified) VALUES (?, ?, ?, ?, ?, ?, ?, ?, ?, ?)'] [parameters: ('cethik', '$2b$12$60UQCzVKjIi5vsiYQvQ.AOq0itYi.lnRuvNFOPtKbsoM1uPnWRt/u', 'Erwan', 'cethik7@gmail.com', 'Male', '2018-01-01', '081224035608', 'Bandung', './static/img/photo_bucket/1logo.jpg', 0)]
127.0.0.1 - - [16/Apr/2018 06:53:38] "GET /category/Fashion HTTP/1.0" 500 -
[2018-04-16 06:53:56,628] ERROR in app: Exception on /category/Arts/a.el.project/loading.gif [GET]
Traceback (most recent call last):
  File "/usr/local/lib/python3.5/dist-packages/flask/app.py", line 1982, in wsgi_app
    response = self.full_dispatch_request()
  File "/usr/local/lib/python3.5/dist-packages/flask/app.py", line 1614, in full_dispatch_request
    rv = self.handle_user_exception(e)
  File "/usr/local/lib/python3.5/dist-packages/flask/app.py", line 1517, in handle_user_exception
    reraise(exc_type, exc_value, tb)
  File "/usr/local/lib/python3.5/dist-packages/flask/_compat.py", line 33, in reraise
    raise value
  File "/usr/local/lib/python3.5/dist-packages/flask/app.py", line 1612, in full_dispatch_request
    rv = self.dispatch_request()
  File "/usr/local/lib/python3.5/dist-packages/flask/app.py", line 1598, in dispatch_request
    return self.view_functions[rule.endpoint](**req.view_args)
  File "./trial.py", line 514, in showitem
    item = session.query(Article,ArticlePhoto).filter_by(title=item).join(ArticlePhoto).all()
  File "/usr/local/lib/python3.5/dist-packages/sqlalchemy/orm/query.py", line 2703, in all
    return list(self)
  File "/usr/local/lib/python3.5/dist-packages/sqlalchemy/orm/query.py", line 2855, in __iter__
    return self._execute_and_instances(context)
  File "/usr/local/lib/python3.5/dist-packages/sqlalchemy/orm/query.py", line 2876, in _execute_and_instances
    close_with_result=True)
  File "/usr/local/lib/python3.5/dist-packages/sqlalchemy/orm/query.py", line 2885, in _get_bind_args
    **kw
  File "/usr/local/lib/python3.5/dist-packages/sqlalchemy/orm/query.py", line 2867, in _connection_from_session
    conn = self.session.connection(**kw)
  File "/usr/local/lib/python3.5/dist-packages/sqlalchemy/orm/session.py", line 1013, in connection
    execution_options=execution_options)
  File "/usr/local/lib/python3.5/dist-packages/sqlalchemy/orm/session.py", line 1018, in _connection_for_bind
    engine, execution_options)
  File "/usr/local/lib/python3.5/dist-packages/sqlalchemy/orm/session.py", line 382, in _connection_for_bind
    self._assert_active()
  File "/usr/local/lib/python3.5/dist-packages/sqlalchemy/orm/session.py", line 276, in _assert_active
    % self._rollback_exception
sqlalchemy.exc.InvalidRequestError: This Session's transaction has been rolled back due to a previous exception during flush. To begin a new transaction with this Session, first issue Session.rollback(). Original exception was: (sqlite3.IntegrityError) UNIQUE constraint failed: user.username [SQL: 'INSERT INTO user (username, password, name, email, gender, birth_date, phone_number, address, photodir, verified) VALUES (?, ?, ?, ?, ?, ?, ?, ?, ?, ?)'] [parameters: ('cethik', '$2b$12$60UQCzVKjIi5vsiYQvQ.AOq0itYi.lnRuvNFOPtKbsoM1uPnWRt/u', 'Erwan', 'cethik7@gmail.com', 'Male', '2018-01-01', '081224035608', 'Bandung', './static/img/photo_bucket/1logo.jpg', 0)]
127.0.0.1 - - [16/Apr/2018 06:53:56] "GET /category/Arts/a.el.project/loading.gif HTTP/1.0" 500 -
127.0.0.1 - - [16/Apr/2018 06:53:57] "GET / HTTP/1.0" 200 -
127.0.0.1 - - [16/Apr/2018 06:53:57] "GET /static/img/city-sunrise.png HTTP/1.0" 200 -
127.0.0.1 - - [16/Apr/2018 06:54:01] "GET /category HTTP/1.0" 200 -
[2018-04-16 06:54:17,884] ERROR in app: Exception on /category/Fashion [GET]
Traceback (most recent call last):
  File "/usr/local/lib/python3.5/dist-packages/flask/app.py", line 1982, in wsgi_app
    response = self.full_dispatch_request()
  File "/usr/local/lib/python3.5/dist-packages/flask/app.py", line 1614, in full_dispatch_request
    rv = self.handle_user_exception(e)
  File "/usr/local/lib/python3.5/dist-packages/flask/app.py", line 1517, in handle_user_exception
    reraise(exc_type, exc_value, tb)
  File "/usr/local/lib/python3.5/dist-packages/flask/_compat.py", line 33, in reraise
    raise value
  File "/usr/local/lib/python3.5/dist-packages/flask/app.py", line 1612, in full_dispatch_request
    rv = self.dispatch_request()
  File "/usr/local/lib/python3.5/dist-packages/flask/app.py", line 1598, in dispatch_request
    return self.view_functions[rule.endpoint](**req.view_args)
  File "./trial.py", line 467, in shoplist
    shopname = session.query(Shop,ShopTag,ShopPhoto).join(ShopTag).filter_by(tag=category).join(ShopPhoto).all()
  File "/usr/local/lib/python3.5/dist-packages/sqlalchemy/orm/query.py", line 2703, in all
    return list(self)
  File "/usr/local/lib/python3.5/dist-packages/sqlalchemy/orm/query.py", line 2855, in __iter__
    return self._execute_and_instances(context)
  File "/usr/local/lib/python3.5/dist-packages/sqlalchemy/orm/query.py", line 2876, in _execute_and_instances
    close_with_result=True)
  File "/usr/local/lib/python3.5/dist-packages/sqlalchemy/orm/query.py", line 2885, in _get_bind_args
    **kw
  File "/usr/local/lib/python3.5/dist-packages/sqlalchemy/orm/query.py", line 2867, in _connection_from_session
    conn = self.session.connection(**kw)
  File "/usr/local/lib/python3.5/dist-packages/sqlalchemy/orm/session.py", line 1013, in connection
    execution_options=execution_options)
  File "/usr/local/lib/python3.5/dist-packages/sqlalchemy/orm/session.py", line 1018, in _connection_for_bind
    engine, execution_options)
  File "/usr/local/lib/python3.5/dist-packages/sqlalchemy/orm/session.py", line 382, in _connection_for_bind
    self._assert_active()
  File "/usr/local/lib/python3.5/dist-packages/sqlalchemy/orm/session.py", line 276, in _assert_active
    % self._rollback_exception
sqlalchemy.exc.InvalidRequestError: This Session's transaction has been rolled back due to a previous exception during flush. To begin a new transaction with this Session, first issue Session.rollback(). Original exception was: (sqlite3.IntegrityError) UNIQUE constraint failed: user.username [SQL: 'INSERT INTO user (username, password, name, email, gender, birth_date, phone_number, address, photodir, verified) VALUES (?, ?, ?, ?, ?, ?, ?, ?, ?, ?)'] [parameters: ('cethik', '$2b$12$60UQCzVKjIi5vsiYQvQ.AOq0itYi.lnRuvNFOPtKbsoM1uPnWRt/u', 'Erwan', 'cethik7@gmail.com', 'Male', '2018-01-01', '081224035608', 'Bandung', './static/img/photo_bucket/1logo.jpg', 0)]
127.0.0.1 - - [16/Apr/2018 06:54:17] "GET /category/Fashion HTTP/1.0" 500 -
127.0.0.1 - - [16/Apr/2018 06:55:03] "GET / HTTP/1.0" 200 -
127.0.0.1 - - [16/Apr/2018 06:55:06] "GET /category HTTP/1.0" 200 -
[2018-04-16 06:55:08,380] ERROR in app: Exception on /category/Food [GET]
Traceback (most recent call last):
  File "/usr/local/lib/python3.5/dist-packages/flask/app.py", line 1982, in wsgi_app
    response = self.full_dispatch_request()
  File "/usr/local/lib/python3.5/dist-packages/flask/app.py", line 1614, in full_dispatch_request
    rv = self.handle_user_exception(e)
  File "/usr/local/lib/python3.5/dist-packages/flask/app.py", line 1517, in handle_user_exception
    reraise(exc_type, exc_value, tb)
  File "/usr/local/lib/python3.5/dist-packages/flask/_compat.py", line 33, in reraise
    raise value
  File "/usr/local/lib/python3.5/dist-packages/flask/app.py", line 1612, in full_dispatch_request
    rv = self.dispatch_request()
  File "/usr/local/lib/python3.5/dist-packages/flask/app.py", line 1598, in dispatch_request
    return self.view_functions[rule.endpoint](**req.view_args)
  File "./trial.py", line 467, in shoplist
    shopname = session.query(Shop,ShopTag,ShopPhoto).join(ShopTag).filter_by(tag=category).join(ShopPhoto).all()
  File "/usr/local/lib/python3.5/dist-packages/sqlalchemy/orm/query.py", line 2703, in all
    return list(self)
  File "/usr/local/lib/python3.5/dist-packages/sqlalchemy/orm/query.py", line 2855, in __iter__
    return self._execute_and_instances(context)
  File "/usr/local/lib/python3.5/dist-packages/sqlalchemy/orm/query.py", line 2876, in _execute_and_instances
    close_with_result=True)
  File "/usr/local/lib/python3.5/dist-packages/sqlalchemy/orm/query.py", line 2885, in _get_bind_args
    **kw
  File "/usr/local/lib/python3.5/dist-packages/sqlalchemy/orm/query.py", line 2867, in _connection_from_session
    conn = self.session.connection(**kw)
  File "/usr/local/lib/python3.5/dist-packages/sqlalchemy/orm/session.py", line 1013, in connection
    execution_options=execution_options)
  File "/usr/local/lib/python3.5/dist-packages/sqlalchemy/orm/session.py", line 1018, in _connection_for_bind
    engine, execution_options)
  File "/usr/local/lib/python3.5/dist-packages/sqlalchemy/orm/session.py", line 382, in _connection_for_bind
    self._assert_active()
  File "/usr/local/lib/python3.5/dist-packages/sqlalchemy/orm/session.py", line 276, in _assert_active
    % self._rollback_exception
sqlalchemy.exc.InvalidRequestError: This Session's transaction has been rolled back due to a previous exception during flush. To begin a new transaction with this Session, first issue Session.rollback(). Original exception was: (sqlite3.IntegrityError) UNIQUE constraint failed: user.username [SQL: 'INSERT INTO user (username, password, name, email, gender, birth_date, phone_number, address, photodir, verified) VALUES (?, ?, ?, ?, ?, ?, ?, ?, ?, ?)'] [parameters: ('cethik', '$2b$12$60UQCzVKjIi5vsiYQvQ.AOq0itYi.lnRuvNFOPtKbsoM1uPnWRt/u', 'Erwan', 'cethik7@gmail.com', 'Male', '2018-01-01', '081224035608', 'Bandung', './static/img/photo_bucket/1logo.jpg', 0)]
127.0.0.1 - - [16/Apr/2018 06:55:08] "GET /category/Food HTTP/1.0" 500 -
[2018-04-16 06:55:12,911] ERROR in app: Exception on /profile [GET]
Traceback (most recent call last):
  File "/usr/local/lib/python3.5/dist-packages/flask/app.py", line 1982, in wsgi_app
    response = self.full_dispatch_request()
  File "/usr/local/lib/python3.5/dist-packages/flask/app.py", line 1614, in full_dispatch_request
    rv = self.handle_user_exception(e)
  File "/usr/local/lib/python3.5/dist-packages/flask/app.py", line 1517, in handle_user_exception
    reraise(exc_type, exc_value, tb)
  File "/usr/local/lib/python3.5/dist-packages/flask/_compat.py", line 33, in reraise
    raise value
  File "/usr/local/lib/python3.5/dist-packages/flask/app.py", line 1612, in full_dispatch_request
    rv = self.dispatch_request()
  File "/usr/local/lib/python3.5/dist-packages/flask/app.py", line 1598, in dispatch_request
    return self.view_functions[rule.endpoint](**req.view_args)
  File "./trial.py", line 435, in profile
    shops = session.query(Shop,Article,ArticlePhoto,ShopTag).join(Article).join(ArticlePhoto).join(ShopTag).all()
  File "/usr/local/lib/python3.5/dist-packages/sqlalchemy/orm/query.py", line 2703, in all
    return list(self)
  File "/usr/local/lib/python3.5/dist-packages/sqlalchemy/orm/query.py", line 2855, in __iter__
    return self._execute_and_instances(context)
  File "/usr/local/lib/python3.5/dist-packages/sqlalchemy/orm/query.py", line 2876, in _execute_and_instances
    close_with_result=True)
  File "/usr/local/lib/python3.5/dist-packages/sqlalchemy/orm/query.py", line 2885, in _get_bind_args
    **kw
  File "/usr/local/lib/python3.5/dist-packages/sqlalchemy/orm/query.py", line 2867, in _connection_from_session
    conn = self.session.connection(**kw)
  File "/usr/local/lib/python3.5/dist-packages/sqlalchemy/orm/session.py", line 1013, in connection
    execution_options=execution_options)
  File "/usr/local/lib/python3.5/dist-packages/sqlalchemy/orm/session.py", line 1018, in _connection_for_bind
    engine, execution_options)
  File "/usr/local/lib/python3.5/dist-packages/sqlalchemy/orm/session.py", line 382, in _connection_for_bind
    self._assert_active()
  File "/usr/local/lib/python3.5/dist-packages/sqlalchemy/orm/session.py", line 276, in _assert_active
    % self._rollback_exception
sqlalchemy.exc.InvalidRequestError: This Session's transaction has been rolled back due to a previous exception during flush. To begin a new transaction with this Session, first issue Session.rollback(). Original exception was: (sqlite3.IntegrityError) UNIQUE constraint failed: user.username [SQL: 'INSERT INTO user (username, password, name, email, gender, birth_date, phone_number, address, photodir, verified) VALUES (?, ?, ?, ?, ?, ?, ?, ?, ?, ?)'] [parameters: ('cethik', '$2b$12$60UQCzVKjIi5vsiYQvQ.AOq0itYi.lnRuvNFOPtKbsoM1uPnWRt/u', 'Erwan', 'cethik7@gmail.com', 'Male', '2018-01-01', '081224035608', 'Bandung', './static/img/photo_bucket/1logo.jpg', 0)]
127.0.0.1 - - [16/Apr/2018 06:55:12] "GET /profile HTTP/1.0" 500 -
[2018-04-16 06:55:14,854] ERROR in app: Exception on /category/Fashion/Kayamata/Kayamata [GET]
Traceback (most recent call last):
  File "/usr/local/lib/python3.5/dist-packages/flask/app.py", line 1982, in wsgi_app
    response = self.full_dispatch_request()
  File "/usr/local/lib/python3.5/dist-packages/flask/app.py", line 1614, in full_dispatch_request
    rv = self.handle_user_exception(e)
  File "/usr/local/lib/python3.5/dist-packages/flask/app.py", line 1517, in handle_user_exception
    reraise(exc_type, exc_value, tb)
  File "/usr/local/lib/python3.5/dist-packages/flask/_compat.py", line 33, in reraise
    raise value
  File "/usr/local/lib/python3.5/dist-packages/flask/app.py", line 1612, in full_dispatch_request
    rv = self.dispatch_request()
  File "/usr/local/lib/python3.5/dist-packages/flask/app.py", line 1598, in dispatch_request
    return self.view_functions[rule.endpoint](**req.view_args)
  File "./trial.py", line 514, in showitem
    item = session.query(Article,ArticlePhoto).filter_by(title=item).join(ArticlePhoto).all()
  File "/usr/local/lib/python3.5/dist-packages/sqlalchemy/orm/query.py", line 2703, in all
    return list(self)
  File "/usr/local/lib/python3.5/dist-packages/sqlalchemy/orm/query.py", line 2855, in __iter__
    return self._execute_and_instances(context)
  File "/usr/local/lib/python3.5/dist-packages/sqlalchemy/orm/query.py", line 2876, in _execute_and_instances
    close_with_result=True)
  File "/usr/local/lib/python3.5/dist-packages/sqlalchemy/orm/query.py", line 2885, in _get_bind_args
    **kw
  File "/usr/local/lib/python3.5/dist-packages/sqlalchemy/orm/query.py", line 2867, in _connection_from_session
    conn = self.session.connection(**kw)
  File "/usr/local/lib/python3.5/dist-packages/sqlalchemy/orm/session.py", line 1013, in connection
    execution_options=execution_options)
  File "/usr/local/lib/python3.5/dist-packages/sqlalchemy/orm/session.py", line 1018, in _connection_for_bind
    engine, execution_options)
  File "/usr/local/lib/python3.5/dist-packages/sqlalchemy/orm/session.py", line 382, in _connection_for_bind
    self._assert_active()
  File "/usr/local/lib/python3.5/dist-packages/sqlalchemy/orm/session.py", line 276, in _assert_active
    % self._rollback_exception
sqlalchemy.exc.InvalidRequestError: This Session's transaction has been rolled back due to a previous exception during flush. To begin a new transaction with this Session, first issue Session.rollback(). Original exception was: (sqlite3.IntegrityError) UNIQUE constraint failed: user.username [SQL: 'INSERT INTO user (username, password, name, email, gender, birth_date, phone_number, address, photodir, verified) VALUES (?, ?, ?, ?, ?, ?, ?, ?, ?, ?)'] [parameters: ('cethik', '$2b$12$60UQCzVKjIi5vsiYQvQ.AOq0itYi.lnRuvNFOPtKbsoM1uPnWRt/u', 'Erwan', 'cethik7@gmail.com', 'Male', '2018-01-01', '081224035608', 'Bandung', './static/img/photo_bucket/1logo.jpg', 0)]
127.0.0.1 - - [16/Apr/2018 06:55:14] "GET /category/Fashion/Kayamata/Kayamata HTTP/1.0" 500 -
127.0.0.1 - - [16/Apr/2018 06:55:24] "GET / HTTP/1.0" 200 -
[2018-04-16 06:55:29,844] ERROR in app: Exception on /stat [GET]
Traceback (most recent call last):
  File "/usr/local/lib/python3.5/dist-packages/flask/app.py", line 1982, in wsgi_app
    response = self.full_dispatch_request()
  File "/usr/local/lib/python3.5/dist-packages/flask/app.py", line 1614, in full_dispatch_request
    rv = self.handle_user_exception(e)
  File "/usr/local/lib/python3.5/dist-packages/flask/app.py", line 1517, in handle_user_exception
    reraise(exc_type, exc_value, tb)
  File "/usr/local/lib/python3.5/dist-packages/flask/_compat.py", line 33, in reraise
    raise value
  File "/usr/local/lib/python3.5/dist-packages/flask/app.py", line 1612, in full_dispatch_request
    rv = self.dispatch_request()
  File "/usr/local/lib/python3.5/dist-packages/flask/app.py", line 1598, in dispatch_request
    return self.view_functions[rule.endpoint](**req.view_args)
  File "./trial.py", line 643, in statistic
    user = session.query(User).all()
  File "/usr/local/lib/python3.5/dist-packages/sqlalchemy/orm/query.py", line 2703, in all
    return list(self)
  File "/usr/local/lib/python3.5/dist-packages/sqlalchemy/orm/query.py", line 2855, in __iter__
    return self._execute_and_instances(context)
  File "/usr/local/lib/python3.5/dist-packages/sqlalchemy/orm/query.py", line 2876, in _execute_and_instances
    close_with_result=True)
  File "/usr/local/lib/python3.5/dist-packages/sqlalchemy/orm/query.py", line 2885, in _get_bind_args
    **kw
  File "/usr/local/lib/python3.5/dist-packages/sqlalchemy/orm/query.py", line 2867, in _connection_from_session
    conn = self.session.connection(**kw)
  File "/usr/local/lib/python3.5/dist-packages/sqlalchemy/orm/session.py", line 1013, in connection
    execution_options=execution_options)
  File "/usr/local/lib/python3.5/dist-packages/sqlalchemy/orm/session.py", line 1018, in _connection_for_bind
    engine, execution_options)
  File "/usr/local/lib/python3.5/dist-packages/sqlalchemy/orm/session.py", line 382, in _connection_for_bind
    self._assert_active()
  File "/usr/local/lib/python3.5/dist-packages/sqlalchemy/orm/session.py", line 276, in _assert_active
    % self._rollback_exception
sqlalchemy.exc.InvalidRequestError: This Session's transaction has been rolled back due to a previous exception during flush. To begin a new transaction with this Session, first issue Session.rollback(). Original exception was: (sqlite3.IntegrityError) UNIQUE constraint failed: user.username [SQL: 'INSERT INTO user (username, password, name, email, gender, birth_date, phone_number, address, photodir, verified) VALUES (?, ?, ?, ?, ?, ?, ?, ?, ?, ?)'] [parameters: ('cethik', '$2b$12$60UQCzVKjIi5vsiYQvQ.AOq0itYi.lnRuvNFOPtKbsoM1uPnWRt/u', 'Erwan', 'cethik7@gmail.com', 'Male', '2018-01-01', '081224035608', 'Bandung', './static/img/photo_bucket/1logo.jpg', 0)]
127.0.0.1 - - [16/Apr/2018 06:55:29] "GET /stat HTTP/1.0" 500 -
[2018-04-16 06:56:12,311] ERROR in app: Exception on /category/Fashion [GET]
Traceback (most recent call last):
  File "/usr/local/lib/python3.5/dist-packages/flask/app.py", line 1982, in wsgi_app
    response = self.full_dispatch_request()
  File "/usr/local/lib/python3.5/dist-packages/flask/app.py", line 1614, in full_dispatch_request
    rv = self.handle_user_exception(e)
  File "/usr/local/lib/python3.5/dist-packages/flask/app.py", line 1517, in handle_user_exception
    reraise(exc_type, exc_value, tb)
  File "/usr/local/lib/python3.5/dist-packages/flask/_compat.py", line 33, in reraise
    raise value
  File "/usr/local/lib/python3.5/dist-packages/flask/app.py", line 1612, in full_dispatch_request
    rv = self.dispatch_request()
  File "/usr/local/lib/python3.5/dist-packages/flask/app.py", line 1598, in dispatch_request
    return self.view_functions[rule.endpoint](**req.view_args)
  File "./trial.py", line 467, in shoplist
    shopname = session.query(Shop,ShopTag,ShopPhoto).join(ShopTag).filter_by(tag=category).join(ShopPhoto).all()
  File "/usr/local/lib/python3.5/dist-packages/sqlalchemy/orm/query.py", line 2703, in all
    return list(self)
  File "/usr/local/lib/python3.5/dist-packages/sqlalchemy/orm/query.py", line 2855, in __iter__
    return self._execute_and_instances(context)
  File "/usr/local/lib/python3.5/dist-packages/sqlalchemy/orm/query.py", line 2876, in _execute_and_instances
    close_with_result=True)
  File "/usr/local/lib/python3.5/dist-packages/sqlalchemy/orm/query.py", line 2885, in _get_bind_args
    **kw
  File "/usr/local/lib/python3.5/dist-packages/sqlalchemy/orm/query.py", line 2867, in _connection_from_session
    conn = self.session.connection(**kw)
  File "/usr/local/lib/python3.5/dist-packages/sqlalchemy/orm/session.py", line 1013, in connection
    execution_options=execution_options)
  File "/usr/local/lib/python3.5/dist-packages/sqlalchemy/orm/session.py", line 1018, in _connection_for_bind
    engine, execution_options)
  File "/usr/local/lib/python3.5/dist-packages/sqlalchemy/orm/session.py", line 382, in _connection_for_bind
    self._assert_active()
  File "/usr/local/lib/python3.5/dist-packages/sqlalchemy/orm/session.py", line 276, in _assert_active
    % self._rollback_exception
sqlalchemy.exc.InvalidRequestError: This Session's transaction has been rolled back due to a previous exception during flush. To begin a new transaction with this Session, first issue Session.rollback(). Original exception was: (sqlite3.IntegrityError) UNIQUE constraint failed: user.username [SQL: 'INSERT INTO user (username, password, name, email, gender, birth_date, phone_number, address, photodir, verified) VALUES (?, ?, ?, ?, ?, ?, ?, ?, ?, ?)'] [parameters: ('cethik', '$2b$12$60UQCzVKjIi5vsiYQvQ.AOq0itYi.lnRuvNFOPtKbsoM1uPnWRt/u', 'Erwan', 'cethik7@gmail.com', 'Male', '2018-01-01', '081224035608', 'Bandung', './static/img/photo_bucket/1logo.jpg', 0)]
127.0.0.1 - - [16/Apr/2018 06:56:12] "GET /category/Fashion HTTP/1.0" 500 -
[2018-04-16 06:56:14,834] ERROR in app: Exception on /stat [GET]
Traceback (most recent call last):
  File "/usr/local/lib/python3.5/dist-packages/flask/app.py", line 1982, in wsgi_app
    response = self.full_dispatch_request()
  File "/usr/local/lib/python3.5/dist-packages/flask/app.py", line 1614, in full_dispatch_request
    rv = self.handle_user_exception(e)
  File "/usr/local/lib/python3.5/dist-packages/flask/app.py", line 1517, in handle_user_exception
    reraise(exc_type, exc_value, tb)
  File "/usr/local/lib/python3.5/dist-packages/flask/_compat.py", line 33, in reraise
    raise value
  File "/usr/local/lib/python3.5/dist-packages/flask/app.py", line 1612, in full_dispatch_request
    rv = self.dispatch_request()
  File "/usr/local/lib/python3.5/dist-packages/flask/app.py", line 1598, in dispatch_request
    return self.view_functions[rule.endpoint](**req.view_args)
  File "./trial.py", line 643, in statistic
    user = session.query(User).all()
  File "/usr/local/lib/python3.5/dist-packages/sqlalchemy/orm/query.py", line 2703, in all
    return list(self)
  File "/usr/local/lib/python3.5/dist-packages/sqlalchemy/orm/query.py", line 2855, in __iter__
    return self._execute_and_instances(context)
  File "/usr/local/lib/python3.5/dist-packages/sqlalchemy/orm/query.py", line 2876, in _execute_and_instances
    close_with_result=True)
  File "/usr/local/lib/python3.5/dist-packages/sqlalchemy/orm/query.py", line 2885, in _get_bind_args
    **kw
  File "/usr/local/lib/python3.5/dist-packages/sqlalchemy/orm/query.py", line 2867, in _connection_from_session
    conn = self.session.connection(**kw)
  File "/usr/local/lib/python3.5/dist-packages/sqlalchemy/orm/session.py", line 1013, in connection
    execution_options=execution_options)
  File "/usr/local/lib/python3.5/dist-packages/sqlalchemy/orm/session.py", line 1018, in _connection_for_bind
    engine, execution_options)
  File "/usr/local/lib/python3.5/dist-packages/sqlalchemy/orm/session.py", line 382, in _connection_for_bind
    self._assert_active()
  File "/usr/local/lib/python3.5/dist-packages/sqlalchemy/orm/session.py", line 276, in _assert_active
    % self._rollback_exception
sqlalchemy.exc.InvalidRequestError: This Session's transaction has been rolled back due to a previous exception during flush. To begin a new transaction with this Session, first issue Session.rollback(). Original exception was: (sqlite3.IntegrityError) UNIQUE constraint failed: user.username [SQL: 'INSERT INTO user (username, password, name, email, gender, birth_date, phone_number, address, photodir, verified) VALUES (?, ?, ?, ?, ?, ?, ?, ?, ?, ?)'] [parameters: ('cethik', '$2b$12$60UQCzVKjIi5vsiYQvQ.AOq0itYi.lnRuvNFOPtKbsoM1uPnWRt/u', 'Erwan', 'cethik7@gmail.com', 'Male', '2018-01-01', '081224035608', 'Bandung', './static/img/photo_bucket/1logo.jpg', 0)]
127.0.0.1 - - [16/Apr/2018 06:56:14] "GET /stat HTTP/1.0" 500 -
127.0.0.1 - - [16/Apr/2018 06:56:27] "GET /static/img/city-sunrise.png HTTP/1.0" 200 -
127.0.0.1 - - [16/Apr/2018 06:56:45] "GET / HTTP/1.0" 200 -
127.0.0.1 - - [16/Apr/2018 06:56:47] "GET /apple-touch-icon-120x120-precomposed.png HTTP/1.0" 404 -
127.0.0.1 - - [16/Apr/2018 06:56:47] "GET /apple-touch-icon-120x120.png HTTP/1.0" 404 -
127.0.0.1 - - [16/Apr/2018 06:56:47] "GET / HTTP/1.0" 200 -
127.0.0.1 - - [16/Apr/2018 06:56:47] "GET /apple-touch-icon.png HTTP/1.0" 404 -
127.0.0.1 - - [16/Apr/2018 06:56:47] "GET /apple-touch-icon.png HTTP/1.0" 404 -
127.0.0.1 - - [16/Apr/2018 06:56:48] "GET /static/img/city-sunrise.png HTTP/1.0" 200 -
127.0.0.1 - - [16/Apr/2018 06:56:48] "GET /apple-touch-icon-precomposed.png HTTP/1.0" 404 -
127.0.0.1 - - [16/Apr/2018 06:56:48] "GET /favicon.ico HTTP/1.0" 404 -
127.0.0.1 - - [16/Apr/2018 06:56:52] "GET /category HTTP/1.0" 200 -
[2018-04-16 06:56:57,482] ERROR in app: Exception on /category/Fashion [GET]
Traceback (most recent call last):
  File "/usr/local/lib/python3.5/dist-packages/flask/app.py", line 1982, in wsgi_app
    response = self.full_dispatch_request()
  File "/usr/local/lib/python3.5/dist-packages/flask/app.py", line 1614, in full_dispatch_request
    rv = self.handle_user_exception(e)
  File "/usr/local/lib/python3.5/dist-packages/flask/app.py", line 1517, in handle_user_exception
    reraise(exc_type, exc_value, tb)
  File "/usr/local/lib/python3.5/dist-packages/flask/_compat.py", line 33, in reraise
    raise value
  File "/usr/local/lib/python3.5/dist-packages/flask/app.py", line 1612, in full_dispatch_request
    rv = self.dispatch_request()
  File "/usr/local/lib/python3.5/dist-packages/flask/app.py", line 1598, in dispatch_request
    return self.view_functions[rule.endpoint](**req.view_args)
  File "./trial.py", line 467, in shoplist
    shopname = session.query(Shop,ShopTag,ShopPhoto).join(ShopTag).filter_by(tag=category).join(ShopPhoto).all()
  File "/usr/local/lib/python3.5/dist-packages/sqlalchemy/orm/query.py", line 2703, in all
    return list(self)
  File "/usr/local/lib/python3.5/dist-packages/sqlalchemy/orm/query.py", line 2855, in __iter__
    return self._execute_and_instances(context)
  File "/usr/local/lib/python3.5/dist-packages/sqlalchemy/orm/query.py", line 2876, in _execute_and_instances
    close_with_result=True)
  File "/usr/local/lib/python3.5/dist-packages/sqlalchemy/orm/query.py", line 2885, in _get_bind_args
    **kw
  File "/usr/local/lib/python3.5/dist-packages/sqlalchemy/orm/query.py", line 2867, in _connection_from_session
    conn = self.session.connection(**kw)
  File "/usr/local/lib/python3.5/dist-packages/sqlalchemy/orm/session.py", line 1013, in connection
    execution_options=execution_options)
  File "/usr/local/lib/python3.5/dist-packages/sqlalchemy/orm/session.py", line 1018, in _connection_for_bind
    engine, execution_options)
  File "/usr/local/lib/python3.5/dist-packages/sqlalchemy/orm/session.py", line 382, in _connection_for_bind
    self._assert_active()
  File "/usr/local/lib/python3.5/dist-packages/sqlalchemy/orm/session.py", line 276, in _assert_active
    % self._rollback_exception
sqlalchemy.exc.InvalidRequestError: This Session's transaction has been rolled back due to a previous exception during flush. To begin a new transaction with this Session, first issue Session.rollback(). Original exception was: (sqlite3.IntegrityError) UNIQUE constraint failed: user.username [SQL: 'INSERT INTO user (username, password, name, email, gender, birth_date, phone_number, address, photodir, verified) VALUES (?, ?, ?, ?, ?, ?, ?, ?, ?, ?)'] [parameters: ('cethik', '$2b$12$60UQCzVKjIi5vsiYQvQ.AOq0itYi.lnRuvNFOPtKbsoM1uPnWRt/u', 'Erwan', 'cethik7@gmail.com', 'Male', '2018-01-01', '081224035608', 'Bandung', './static/img/photo_bucket/1logo.jpg', 0)]
127.0.0.1 - - [16/Apr/2018 06:56:57] "GET /category/Fashion HTTP/1.0" 500 -
[2018-04-16 06:59:14,370] ERROR in app: Exception on /profile [GET]
Traceback (most recent call last):
  File "/usr/local/lib/python3.5/dist-packages/flask/app.py", line 1982, in wsgi_app
    response = self.full_dispatch_request()
  File "/usr/local/lib/python3.5/dist-packages/flask/app.py", line 1614, in full_dispatch_request
    rv = self.handle_user_exception(e)
  File "/usr/local/lib/python3.5/dist-packages/flask/app.py", line 1517, in handle_user_exception
    reraise(exc_type, exc_value, tb)
  File "/usr/local/lib/python3.5/dist-packages/flask/_compat.py", line 33, in reraise
    raise value
  File "/usr/local/lib/python3.5/dist-packages/flask/app.py", line 1612, in full_dispatch_request
    rv = self.dispatch_request()
  File "/usr/local/lib/python3.5/dist-packages/flask/app.py", line 1598, in dispatch_request
    return self.view_functions[rule.endpoint](**req.view_args)
  File "./trial.py", line 435, in profile
    shops = session.query(Shop,Article,ArticlePhoto,ShopTag).join(Article).join(ArticlePhoto).join(ShopTag).all()
  File "/usr/local/lib/python3.5/dist-packages/sqlalchemy/orm/query.py", line 2703, in all
    return list(self)
  File "/usr/local/lib/python3.5/dist-packages/sqlalchemy/orm/query.py", line 2855, in __iter__
    return self._execute_and_instances(context)
  File "/usr/local/lib/python3.5/dist-packages/sqlalchemy/orm/query.py", line 2876, in _execute_and_instances
    close_with_result=True)
  File "/usr/local/lib/python3.5/dist-packages/sqlalchemy/orm/query.py", line 2885, in _get_bind_args
    **kw
  File "/usr/local/lib/python3.5/dist-packages/sqlalchemy/orm/query.py", line 2867, in _connection_from_session
    conn = self.session.connection(**kw)
  File "/usr/local/lib/python3.5/dist-packages/sqlalchemy/orm/session.py", line 1013, in connection
    execution_options=execution_options)
  File "/usr/local/lib/python3.5/dist-packages/sqlalchemy/orm/session.py", line 1018, in _connection_for_bind
    engine, execution_options)
  File "/usr/local/lib/python3.5/dist-packages/sqlalchemy/orm/session.py", line 382, in _connection_for_bind
    self._assert_active()
  File "/usr/local/lib/python3.5/dist-packages/sqlalchemy/orm/session.py", line 276, in _assert_active
    % self._rollback_exception
sqlalchemy.exc.InvalidRequestError: This Session's transaction has been rolled back due to a previous exception during flush. To begin a new transaction with this Session, first issue Session.rollback(). Original exception was: (sqlite3.IntegrityError) UNIQUE constraint failed: user.username [SQL: 'INSERT INTO user (username, password, name, email, gender, birth_date, phone_number, address, photodir, verified) VALUES (?, ?, ?, ?, ?, ?, ?, ?, ?, ?)'] [parameters: ('cethik', '$2b$12$60UQCzVKjIi5vsiYQvQ.AOq0itYi.lnRuvNFOPtKbsoM1uPnWRt/u', 'Erwan', 'cethik7@gmail.com', 'Male', '2018-01-01', '081224035608', 'Bandung', './static/img/photo_bucket/1logo.jpg', 0)]
127.0.0.1 - - [16/Apr/2018 06:59:14] "GET /profile HTTP/1.0" 500 -
127.0.0.1 - - [16/Apr/2018 07:12:40] "GET / HTTP/1.0" 200 -
127.0.0.1 - - [16/Apr/2018 07:12:40] "GET /favicon.ico HTTP/1.0" 404 -
[2018-04-16 07:12:42,579] ERROR in app: Exception on /profile [GET]
Traceback (most recent call last):
  File "/usr/local/lib/python3.5/dist-packages/flask/app.py", line 1982, in wsgi_app
    response = self.full_dispatch_request()
  File "/usr/local/lib/python3.5/dist-packages/flask/app.py", line 1614, in full_dispatch_request
    rv = self.handle_user_exception(e)
  File "/usr/local/lib/python3.5/dist-packages/flask/app.py", line 1517, in handle_user_exception
    reraise(exc_type, exc_value, tb)
  File "/usr/local/lib/python3.5/dist-packages/flask/_compat.py", line 33, in reraise
    raise value
  File "/usr/local/lib/python3.5/dist-packages/flask/app.py", line 1612, in full_dispatch_request
    rv = self.dispatch_request()
  File "/usr/local/lib/python3.5/dist-packages/flask/app.py", line 1598, in dispatch_request
    return self.view_functions[rule.endpoint](**req.view_args)
  File "./trial.py", line 435, in profile
    shops = session.query(Shop,Article,ArticlePhoto,ShopTag).join(Article).join(ArticlePhoto).join(ShopTag).all()
  File "/usr/local/lib/python3.5/dist-packages/sqlalchemy/orm/query.py", line 2703, in all
    return list(self)
  File "/usr/local/lib/python3.5/dist-packages/sqlalchemy/orm/query.py", line 2855, in __iter__
    return self._execute_and_instances(context)
  File "/usr/local/lib/python3.5/dist-packages/sqlalchemy/orm/query.py", line 2876, in _execute_and_instances
    close_with_result=True)
  File "/usr/local/lib/python3.5/dist-packages/sqlalchemy/orm/query.py", line 2885, in _get_bind_args
    **kw
  File "/usr/local/lib/python3.5/dist-packages/sqlalchemy/orm/query.py", line 2867, in _connection_from_session
    conn = self.session.connection(**kw)
  File "/usr/local/lib/python3.5/dist-packages/sqlalchemy/orm/session.py", line 1013, in connection
    execution_options=execution_options)
  File "/usr/local/lib/python3.5/dist-packages/sqlalchemy/orm/session.py", line 1018, in _connection_for_bind
    engine, execution_options)
  File "/usr/local/lib/python3.5/dist-packages/sqlalchemy/orm/session.py", line 382, in _connection_for_bind
    self._assert_active()
  File "/usr/local/lib/python3.5/dist-packages/sqlalchemy/orm/session.py", line 276, in _assert_active
    % self._rollback_exception
sqlalchemy.exc.InvalidRequestError: This Session's transaction has been rolled back due to a previous exception during flush. To begin a new transaction with this Session, first issue Session.rollback(). Original exception was: (sqlite3.IntegrityError) UNIQUE constraint failed: user.username [SQL: 'INSERT INTO user (username, password, name, email, gender, birth_date, phone_number, address, photodir, verified) VALUES (?, ?, ?, ?, ?, ?, ?, ?, ?, ?)'] [parameters: ('cethik', '$2b$12$60UQCzVKjIi5vsiYQvQ.AOq0itYi.lnRuvNFOPtKbsoM1uPnWRt/u', 'Erwan', 'cethik7@gmail.com', 'Male', '2018-01-01', '081224035608', 'Bandung', './static/img/photo_bucket/1logo.jpg', 0)]
127.0.0.1 - - [16/Apr/2018 07:12:42] "GET /profile HTTP/1.0" 500 -
[2018-04-16 07:12:44,337] ERROR in app: Exception on /category/Fashion/Kayamata/Kayamata [GET]
Traceback (most recent call last):
  File "/usr/local/lib/python3.5/dist-packages/flask/app.py", line 1982, in wsgi_app
    response = self.full_dispatch_request()
  File "/usr/local/lib/python3.5/dist-packages/flask/app.py", line 1614, in full_dispatch_request
    rv = self.handle_user_exception(e)
  File "/usr/local/lib/python3.5/dist-packages/flask/app.py", line 1517, in handle_user_exception
    reraise(exc_type, exc_value, tb)
  File "/usr/local/lib/python3.5/dist-packages/flask/_compat.py", line 33, in reraise
    raise value
  File "/usr/local/lib/python3.5/dist-packages/flask/app.py", line 1612, in full_dispatch_request
    rv = self.dispatch_request()
  File "/usr/local/lib/python3.5/dist-packages/flask/app.py", line 1598, in dispatch_request
    return self.view_functions[rule.endpoint](**req.view_args)
  File "./trial.py", line 514, in showitem
    item = session.query(Article,ArticlePhoto).filter_by(title=item).join(ArticlePhoto).all()
  File "/usr/local/lib/python3.5/dist-packages/sqlalchemy/orm/query.py", line 2703, in all
    return list(self)
  File "/usr/local/lib/python3.5/dist-packages/sqlalchemy/orm/query.py", line 2855, in __iter__
    return self._execute_and_instances(context)
  File "/usr/local/lib/python3.5/dist-packages/sqlalchemy/orm/query.py", line 2876, in _execute_and_instances
    close_with_result=True)
  File "/usr/local/lib/python3.5/dist-packages/sqlalchemy/orm/query.py", line 2885, in _get_bind_args
    **kw
  File "/usr/local/lib/python3.5/dist-packages/sqlalchemy/orm/query.py", line 2867, in _connection_from_session
    conn = self.session.connection(**kw)
  File "/usr/local/lib/python3.5/dist-packages/sqlalchemy/orm/session.py", line 1013, in connection
    execution_options=execution_options)
  File "/usr/local/lib/python3.5/dist-packages/sqlalchemy/orm/session.py", line 1018, in _connection_for_bind
    engine, execution_options)
  File "/usr/local/lib/python3.5/dist-packages/sqlalchemy/orm/session.py", line 382, in _connection_for_bind
    self._assert_active()
  File "/usr/local/lib/python3.5/dist-packages/sqlalchemy/orm/session.py", line 276, in _assert_active
    % self._rollback_exception
sqlalchemy.exc.InvalidRequestError: This Session's transaction has been rolled back due to a previous exception during flush. To begin a new transaction with this Session, first issue Session.rollback(). Original exception was: (sqlite3.IntegrityError) UNIQUE constraint failed: user.username [SQL: 'INSERT INTO user (username, password, name, email, gender, birth_date, phone_number, address, photodir, verified) VALUES (?, ?, ?, ?, ?, ?, ?, ?, ?, ?)'] [parameters: ('cethik', '$2b$12$60UQCzVKjIi5vsiYQvQ.AOq0itYi.lnRuvNFOPtKbsoM1uPnWRt/u', 'Erwan', 'cethik7@gmail.com', 'Male', '2018-01-01', '081224035608', 'Bandung', './static/img/photo_bucket/1logo.jpg', 0)]
127.0.0.1 - - [16/Apr/2018 07:12:44] "GET /category/Fashion/Kayamata/Kayamata HTTP/1.0" 500 -
[2018-04-16 07:13:48,827] ERROR in app: Exception on /category/Beverages/Stay Fruit/Smoothies buah naga & pisang (Beauty Blush) [GET]
Traceback (most recent call last):
  File "/usr/local/lib/python3.5/dist-packages/flask/app.py", line 1982, in wsgi_app
    response = self.full_dispatch_request()
  File "/usr/local/lib/python3.5/dist-packages/flask/app.py", line 1614, in full_dispatch_request
    rv = self.handle_user_exception(e)
  File "/usr/local/lib/python3.5/dist-packages/flask/app.py", line 1517, in handle_user_exception
    reraise(exc_type, exc_value, tb)
  File "/usr/local/lib/python3.5/dist-packages/flask/_compat.py", line 33, in reraise
    raise value
  File "/usr/local/lib/python3.5/dist-packages/flask/app.py", line 1612, in full_dispatch_request
    rv = self.dispatch_request()
  File "/usr/local/lib/python3.5/dist-packages/flask/app.py", line 1598, in dispatch_request
    return self.view_functions[rule.endpoint](**req.view_args)
  File "./trial.py", line 514, in showitem
    item = session.query(Article,ArticlePhoto).filter_by(title=item).join(ArticlePhoto).all()
  File "/usr/local/lib/python3.5/dist-packages/sqlalchemy/orm/query.py", line 2703, in all
    return list(self)
  File "/usr/local/lib/python3.5/dist-packages/sqlalchemy/orm/query.py", line 2855, in __iter__
    return self._execute_and_instances(context)
  File "/usr/local/lib/python3.5/dist-packages/sqlalchemy/orm/query.py", line 2876, in _execute_and_instances
    close_with_result=True)
  File "/usr/local/lib/python3.5/dist-packages/sqlalchemy/orm/query.py", line 2885, in _get_bind_args
    **kw
  File "/usr/local/lib/python3.5/dist-packages/sqlalchemy/orm/query.py", line 2867, in _connection_from_session
    conn = self.session.connection(**kw)
  File "/usr/local/lib/python3.5/dist-packages/sqlalchemy/orm/session.py", line 1013, in connection
    execution_options=execution_options)
  File "/usr/local/lib/python3.5/dist-packages/sqlalchemy/orm/session.py", line 1018, in _connection_for_bind
    engine, execution_options)
  File "/usr/local/lib/python3.5/dist-packages/sqlalchemy/orm/session.py", line 382, in _connection_for_bind
    self._assert_active()
  File "/usr/local/lib/python3.5/dist-packages/sqlalchemy/orm/session.py", line 276, in _assert_active
    % self._rollback_exception
sqlalchemy.exc.InvalidRequestError: This Session's transaction has been rolled back due to a previous exception during flush. To begin a new transaction with this Session, first issue Session.rollback(). Original exception was: (sqlite3.IntegrityError) UNIQUE constraint failed: user.username [SQL: 'INSERT INTO user (username, password, name, email, gender, birth_date, phone_number, address, photodir, verified) VALUES (?, ?, ?, ?, ?, ?, ?, ?, ?, ?)'] [parameters: ('cethik', '$2b$12$60UQCzVKjIi5vsiYQvQ.AOq0itYi.lnRuvNFOPtKbsoM1uPnWRt/u', 'Erwan', 'cethik7@gmail.com', 'Male', '2018-01-01', '081224035608', 'Bandung', './static/img/photo_bucket/1logo.jpg', 0)]
127.0.0.1 - - [16/Apr/2018 07:13:48] "GET /category/Beverages/Stay%20Fruit/Smoothies%20buah%20naga%20&%20pisang%20(Beauty%20Blush) HTTP/1.0" 500 -
[2018-04-16 07:13:52,832] ERROR in app: Exception on /category/Beverages/Stay Fruit/Smoothies buah naga & pisang (Beauty Blush) [GET]
Traceback (most recent call last):
  File "/usr/local/lib/python3.5/dist-packages/flask/app.py", line 1982, in wsgi_app
    response = self.full_dispatch_request()
  File "/usr/local/lib/python3.5/dist-packages/flask/app.py", line 1614, in full_dispatch_request
    rv = self.handle_user_exception(e)
  File "/usr/local/lib/python3.5/dist-packages/flask/app.py", line 1517, in handle_user_exception
    reraise(exc_type, exc_value, tb)
  File "/usr/local/lib/python3.5/dist-packages/flask/_compat.py", line 33, in reraise
    raise value
  File "/usr/local/lib/python3.5/dist-packages/flask/app.py", line 1612, in full_dispatch_request
    rv = self.dispatch_request()
  File "/usr/local/lib/python3.5/dist-packages/flask/app.py", line 1598, in dispatch_request
    return self.view_functions[rule.endpoint](**req.view_args)
  File "./trial.py", line 514, in showitem
    item = session.query(Article,ArticlePhoto).filter_by(title=item).join(ArticlePhoto).all()
  File "/usr/local/lib/python3.5/dist-packages/sqlalchemy/orm/query.py", line 2703, in all
    return list(self)
  File "/usr/local/lib/python3.5/dist-packages/sqlalchemy/orm/query.py", line 2855, in __iter__
    return self._execute_and_instances(context)
  File "/usr/local/lib/python3.5/dist-packages/sqlalchemy/orm/query.py", line 2876, in _execute_and_instances
    close_with_result=True)
  File "/usr/local/lib/python3.5/dist-packages/sqlalchemy/orm/query.py", line 2885, in _get_bind_args
    **kw
  File "/usr/local/lib/python3.5/dist-packages/sqlalchemy/orm/query.py", line 2867, in _connection_from_session
    conn = self.session.connection(**kw)
  File "/usr/local/lib/python3.5/dist-packages/sqlalchemy/orm/session.py", line 1013, in connection
    execution_options=execution_options)
  File "/usr/local/lib/python3.5/dist-packages/sqlalchemy/orm/session.py", line 1018, in _connection_for_bind
    engine, execution_options)
  File "/usr/local/lib/python3.5/dist-packages/sqlalchemy/orm/session.py", line 382, in _connection_for_bind
    self._assert_active()
  File "/usr/local/lib/python3.5/dist-packages/sqlalchemy/orm/session.py", line 276, in _assert_active
    % self._rollback_exception
sqlalchemy.exc.InvalidRequestError: This Session's transaction has been rolled back due to a previous exception during flush. To begin a new transaction with this Session, first issue Session.rollback(). Original exception was: (sqlite3.IntegrityError) UNIQUE constraint failed: user.username [SQL: 'INSERT INTO user (username, password, name, email, gender, birth_date, phone_number, address, photodir, verified) VALUES (?, ?, ?, ?, ?, ?, ?, ?, ?, ?)'] [parameters: ('cethik', '$2b$12$60UQCzVKjIi5vsiYQvQ.AOq0itYi.lnRuvNFOPtKbsoM1uPnWRt/u', 'Erwan', 'cethik7@gmail.com', 'Male', '2018-01-01', '081224035608', 'Bandung', './static/img/photo_bucket/1logo.jpg', 0)]
127.0.0.1 - - [16/Apr/2018 07:13:52] "GET /category/Beverages/Stay%20Fruit/Smoothies%20buah%20naga%20&%20pisang%20(Beauty%20Blush) HTTP/1.0" 500 -
127.0.0.1 - - [16/Apr/2018 07:22:09] "GET / HTTP/1.0" 200 -
[2018-04-16 07:22:14,077] ERROR in app: Exception on /profile [GET]
Traceback (most recent call last):
  File "/usr/local/lib/python3.5/dist-packages/flask/app.py", line 1982, in wsgi_app
    response = self.full_dispatch_request()
  File "/usr/local/lib/python3.5/dist-packages/flask/app.py", line 1614, in full_dispatch_request
    rv = self.handle_user_exception(e)
  File "/usr/local/lib/python3.5/dist-packages/flask/app.py", line 1517, in handle_user_exception
    reraise(exc_type, exc_value, tb)
  File "/usr/local/lib/python3.5/dist-packages/flask/_compat.py", line 33, in reraise
    raise value
  File "/usr/local/lib/python3.5/dist-packages/flask/app.py", line 1612, in full_dispatch_request
    rv = self.dispatch_request()
  File "/usr/local/lib/python3.5/dist-packages/flask/app.py", line 1598, in dispatch_request
    return self.view_functions[rule.endpoint](**req.view_args)
  File "./trial.py", line 435, in profile
    shops = session.query(Shop,Article,ArticlePhoto,ShopTag).join(Article).join(ArticlePhoto).join(ShopTag).all()
  File "/usr/local/lib/python3.5/dist-packages/sqlalchemy/orm/query.py", line 2703, in all
    return list(self)
  File "/usr/local/lib/python3.5/dist-packages/sqlalchemy/orm/query.py", line 2855, in __iter__
    return self._execute_and_instances(context)
  File "/usr/local/lib/python3.5/dist-packages/sqlalchemy/orm/query.py", line 2876, in _execute_and_instances
    close_with_result=True)
  File "/usr/local/lib/python3.5/dist-packages/sqlalchemy/orm/query.py", line 2885, in _get_bind_args
    **kw
  File "/usr/local/lib/python3.5/dist-packages/sqlalchemy/orm/query.py", line 2867, in _connection_from_session
    conn = self.session.connection(**kw)
  File "/usr/local/lib/python3.5/dist-packages/sqlalchemy/orm/session.py", line 1013, in connection
    execution_options=execution_options)
  File "/usr/local/lib/python3.5/dist-packages/sqlalchemy/orm/session.py", line 1018, in _connection_for_bind
    engine, execution_options)
  File "/usr/local/lib/python3.5/dist-packages/sqlalchemy/orm/session.py", line 382, in _connection_for_bind
    self._assert_active()
  File "/usr/local/lib/python3.5/dist-packages/sqlalchemy/orm/session.py", line 276, in _assert_active
    % self._rollback_exception
sqlalchemy.exc.InvalidRequestError: This Session's transaction has been rolled back due to a previous exception during flush. To begin a new transaction with this Session, first issue Session.rollback(). Original exception was: (sqlite3.IntegrityError) UNIQUE constraint failed: user.username [SQL: 'INSERT INTO user (username, password, name, email, gender, birth_date, phone_number, address, photodir, verified) VALUES (?, ?, ?, ?, ?, ?, ?, ?, ?, ?)'] [parameters: ('cethik', '$2b$12$60UQCzVKjIi5vsiYQvQ.AOq0itYi.lnRuvNFOPtKbsoM1uPnWRt/u', 'Erwan', 'cethik7@gmail.com', 'Male', '2018-01-01', '081224035608', 'Bandung', './static/img/photo_bucket/1logo.jpg', 0)]
127.0.0.1 - - [16/Apr/2018 07:22:14] "GET /profile HTTP/1.0" 500 -
[2018-04-16 07:22:38,177] ERROR in app: Exception on /category/Food/nagilagi/Nagilagi [GET]
Traceback (most recent call last):
  File "/usr/local/lib/python3.5/dist-packages/flask/app.py", line 1982, in wsgi_app
    response = self.full_dispatch_request()
  File "/usr/local/lib/python3.5/dist-packages/flask/app.py", line 1614, in full_dispatch_request
    rv = self.handle_user_exception(e)
  File "/usr/local/lib/python3.5/dist-packages/flask/app.py", line 1517, in handle_user_exception
    reraise(exc_type, exc_value, tb)
  File "/usr/local/lib/python3.5/dist-packages/flask/_compat.py", line 33, in reraise
    raise value
  File "/usr/local/lib/python3.5/dist-packages/flask/app.py", line 1612, in full_dispatch_request
    rv = self.dispatch_request()
  File "/usr/local/lib/python3.5/dist-packages/flask/app.py", line 1598, in dispatch_request
    return self.view_functions[rule.endpoint](**req.view_args)
  File "./trial.py", line 514, in showitem
    item = session.query(Article,ArticlePhoto).filter_by(title=item).join(ArticlePhoto).all()
  File "/usr/local/lib/python3.5/dist-packages/sqlalchemy/orm/query.py", line 2703, in all
    return list(self)
  File "/usr/local/lib/python3.5/dist-packages/sqlalchemy/orm/query.py", line 2855, in __iter__
    return self._execute_and_instances(context)
  File "/usr/local/lib/python3.5/dist-packages/sqlalchemy/orm/query.py", line 2876, in _execute_and_instances
    close_with_result=True)
  File "/usr/local/lib/python3.5/dist-packages/sqlalchemy/orm/query.py", line 2885, in _get_bind_args
    **kw
  File "/usr/local/lib/python3.5/dist-packages/sqlalchemy/orm/query.py", line 2867, in _connection_from_session
    conn = self.session.connection(**kw)
  File "/usr/local/lib/python3.5/dist-packages/sqlalchemy/orm/session.py", line 1013, in connection
    execution_options=execution_options)
  File "/usr/local/lib/python3.5/dist-packages/sqlalchemy/orm/session.py", line 1018, in _connection_for_bind
    engine, execution_options)
  File "/usr/local/lib/python3.5/dist-packages/sqlalchemy/orm/session.py", line 382, in _connection_for_bind
    self._assert_active()
  File "/usr/local/lib/python3.5/dist-packages/sqlalchemy/orm/session.py", line 276, in _assert_active
    % self._rollback_exception
sqlalchemy.exc.InvalidRequestError: This Session's transaction has been rolled back due to a previous exception during flush. To begin a new transaction with this Session, first issue Session.rollback(). Original exception was: (sqlite3.IntegrityError) UNIQUE constraint failed: user.username [SQL: 'INSERT INTO user (username, password, name, email, gender, birth_date, phone_number, address, photodir, verified) VALUES (?, ?, ?, ?, ?, ?, ?, ?, ?, ?)'] [parameters: ('cethik', '$2b$12$60UQCzVKjIi5vsiYQvQ.AOq0itYi.lnRuvNFOPtKbsoM1uPnWRt/u', 'Erwan', 'cethik7@gmail.com', 'Male', '2018-01-01', '081224035608', 'Bandung', './static/img/photo_bucket/1logo.jpg', 0)]
127.0.0.1 - - [16/Apr/2018 07:22:38] "GET /category/Food/nagilagi/Nagilagi HTTP/1.0" 500 -
127.0.0.1 - - [16/Apr/2018 07:23:01] "GET / HTTP/1.0" 200 -
127.0.0.1 - - [16/Apr/2018 07:23:19] "GET /favicon.ico HTTP/1.0" 404 -
127.0.0.1 - - [16/Apr/2018 07:25:06] "GET / HTTP/1.0" 200 -
[2018-04-16 07:25:10,721] ERROR in app: Exception on /profile [GET]
Traceback (most recent call last):
  File "/usr/local/lib/python3.5/dist-packages/flask/app.py", line 1982, in wsgi_app
    response = self.full_dispatch_request()
  File "/usr/local/lib/python3.5/dist-packages/flask/app.py", line 1614, in full_dispatch_request
    rv = self.handle_user_exception(e)
  File "/usr/local/lib/python3.5/dist-packages/flask/app.py", line 1517, in handle_user_exception
    reraise(exc_type, exc_value, tb)
  File "/usr/local/lib/python3.5/dist-packages/flask/_compat.py", line 33, in reraise
    raise value
  File "/usr/local/lib/python3.5/dist-packages/flask/app.py", line 1612, in full_dispatch_request
    rv = self.dispatch_request()
  File "/usr/local/lib/python3.5/dist-packages/flask/app.py", line 1598, in dispatch_request
    return self.view_functions[rule.endpoint](**req.view_args)
  File "./trial.py", line 435, in profile
    shops = session.query(Shop,Article,ArticlePhoto,ShopTag).join(Article).join(ArticlePhoto).join(ShopTag).all()
  File "/usr/local/lib/python3.5/dist-packages/sqlalchemy/orm/query.py", line 2703, in all
    return list(self)
  File "/usr/local/lib/python3.5/dist-packages/sqlalchemy/orm/query.py", line 2855, in __iter__
    return self._execute_and_instances(context)
  File "/usr/local/lib/python3.5/dist-packages/sqlalchemy/orm/query.py", line 2876, in _execute_and_instances
    close_with_result=True)
  File "/usr/local/lib/python3.5/dist-packages/sqlalchemy/orm/query.py", line 2885, in _get_bind_args
    **kw
  File "/usr/local/lib/python3.5/dist-packages/sqlalchemy/orm/query.py", line 2867, in _connection_from_session
    conn = self.session.connection(**kw)
  File "/usr/local/lib/python3.5/dist-packages/sqlalchemy/orm/session.py", line 1013, in connection
    execution_options=execution_options)
  File "/usr/local/lib/python3.5/dist-packages/sqlalchemy/orm/session.py", line 1018, in _connection_for_bind
    engine, execution_options)
  File "/usr/local/lib/python3.5/dist-packages/sqlalchemy/orm/session.py", line 382, in _connection_for_bind
    self._assert_active()
  File "/usr/local/lib/python3.5/dist-packages/sqlalchemy/orm/session.py", line 276, in _assert_active
    % self._rollback_exception
sqlalchemy.exc.InvalidRequestError: This Session's transaction has been rolled back due to a previous exception during flush. To begin a new transaction with this Session, first issue Session.rollback(). Original exception was: (sqlite3.IntegrityError) UNIQUE constraint failed: user.username [SQL: 'INSERT INTO user (username, password, name, email, gender, birth_date, phone_number, address, photodir, verified) VALUES (?, ?, ?, ?, ?, ?, ?, ?, ?, ?)'] [parameters: ('cethik', '$2b$12$60UQCzVKjIi5vsiYQvQ.AOq0itYi.lnRuvNFOPtKbsoM1uPnWRt/u', 'Erwan', 'cethik7@gmail.com', 'Male', '2018-01-01', '081224035608', 'Bandung', './static/img/photo_bucket/1logo.jpg', 0)]
127.0.0.1 - - [16/Apr/2018 07:25:10] "GET /profile HTTP/1.0" 500 -
127.0.0.1 - - [16/Apr/2018 07:25:21] "GET /favicon.ico HTTP/1.0" 404 -
127.0.0.1 - - [16/Apr/2018 07:25:22] "GET /favicon.ico HTTP/1.0" 404 -
127.0.0.1 - - [16/Apr/2018 07:52:19] "GET /robots.txt HTTP/1.0" 404 -
127.0.0.1 - - [16/Apr/2018 07:52:20] "GET /static/img/logo-trimmed.png HTTP/1.0" 200 -
127.0.0.1 - - [16/Apr/2018 07:59:21] "GET /category HTTP/1.0" 200 -
127.0.0.1 - - [16/Apr/2018 07:59:22] "GET / HTTP/1.0" 200 -
127.0.0.1 - - [16/Apr/2018 07:59:22] "GET /apple-touch-icon-120x120-precomposed.png HTTP/1.0" 404 -
127.0.0.1 - - [16/Apr/2018 07:59:23] "GET /apple-touch-icon-120x120.png HTTP/1.0" 404 -
127.0.0.1 - - [16/Apr/2018 07:59:23] "GET /static/img/city-sunrise.png HTTP/1.0" 200 -
127.0.0.1 - - [16/Apr/2018 07:59:24] "GET /apple-touch-icon.png HTTP/1.0" 404 -
127.0.0.1 - - [16/Apr/2018 07:59:24] "GET /apple-touch-icon.png HTTP/1.0" 404 -
127.0.0.1 - - [16/Apr/2018 07:59:24] "GET /apple-touch-icon-precomposed.png HTTP/1.0" 404 -
127.0.0.1 - - [16/Apr/2018 07:59:25] "GET /favicon.ico HTTP/1.0" 404 -
127.0.0.1 - - [16/Apr/2018 07:59:33] "GET /category HTTP/1.0" 200 -
[2018-04-16 07:59:37,404] ERROR in app: Exception on /profile [GET]
Traceback (most recent call last):
  File "/usr/local/lib/python3.5/dist-packages/flask/app.py", line 1982, in wsgi_app
    response = self.full_dispatch_request()
  File "/usr/local/lib/python3.5/dist-packages/flask/app.py", line 1614, in full_dispatch_request
    rv = self.handle_user_exception(e)
  File "/usr/local/lib/python3.5/dist-packages/flask/app.py", line 1517, in handle_user_exception
    reraise(exc_type, exc_value, tb)
  File "/usr/local/lib/python3.5/dist-packages/flask/_compat.py", line 33, in reraise
    raise value
  File "/usr/local/lib/python3.5/dist-packages/flask/app.py", line 1612, in full_dispatch_request
    rv = self.dispatch_request()
  File "/usr/local/lib/python3.5/dist-packages/flask/app.py", line 1598, in dispatch_request
    return self.view_functions[rule.endpoint](**req.view_args)
  File "./trial.py", line 435, in profile
    shops = session.query(Shop,Article,ArticlePhoto,ShopTag).join(Article).join(ArticlePhoto).join(ShopTag).all()
  File "/usr/local/lib/python3.5/dist-packages/sqlalchemy/orm/query.py", line 2703, in all
    return list(self)
  File "/usr/local/lib/python3.5/dist-packages/sqlalchemy/orm/query.py", line 2855, in __iter__
    return self._execute_and_instances(context)
  File "/usr/local/lib/python3.5/dist-packages/sqlalchemy/orm/query.py", line 2876, in _execute_and_instances
    close_with_result=True)
  File "/usr/local/lib/python3.5/dist-packages/sqlalchemy/orm/query.py", line 2885, in _get_bind_args
    **kw
  File "/usr/local/lib/python3.5/dist-packages/sqlalchemy/orm/query.py", line 2867, in _connection_from_session
    conn = self.session.connection(**kw)
  File "/usr/local/lib/python3.5/dist-packages/sqlalchemy/orm/session.py", line 1013, in connection
    execution_options=execution_options)
  File "/usr/local/lib/python3.5/dist-packages/sqlalchemy/orm/session.py", line 1018, in _connection_for_bind
    engine, execution_options)
  File "/usr/local/lib/python3.5/dist-packages/sqlalchemy/orm/session.py", line 382, in _connection_for_bind
    self._assert_active()
  File "/usr/local/lib/python3.5/dist-packages/sqlalchemy/orm/session.py", line 276, in _assert_active
    % self._rollback_exception
sqlalchemy.exc.InvalidRequestError: This Session's transaction has been rolled back due to a previous exception during flush. To begin a new transaction with this Session, first issue Session.rollback(). Original exception was: (sqlite3.IntegrityError) UNIQUE constraint failed: user.username [SQL: 'INSERT INTO user (username, password, name, email, gender, birth_date, phone_number, address, photodir, verified) VALUES (?, ?, ?, ?, ?, ?, ?, ?, ?, ?)'] [parameters: ('cethik', '$2b$12$60UQCzVKjIi5vsiYQvQ.AOq0itYi.lnRuvNFOPtKbsoM1uPnWRt/u', 'Erwan', 'cethik7@gmail.com', 'Male', '2018-01-01', '081224035608', 'Bandung', './static/img/photo_bucket/1logo.jpg', 0)]
127.0.0.1 - - [16/Apr/2018 07:59:37] "GET /profile HTTP/1.0" 500 -
[2018-04-16 07:59:42,842] ERROR in app: Exception on /category/Fashion [GET]
Traceback (most recent call last):
  File "/usr/local/lib/python3.5/dist-packages/flask/app.py", line 1982, in wsgi_app
    response = self.full_dispatch_request()
  File "/usr/local/lib/python3.5/dist-packages/flask/app.py", line 1614, in full_dispatch_request
    rv = self.handle_user_exception(e)
  File "/usr/local/lib/python3.5/dist-packages/flask/app.py", line 1517, in handle_user_exception
    reraise(exc_type, exc_value, tb)
  File "/usr/local/lib/python3.5/dist-packages/flask/_compat.py", line 33, in reraise
    raise value
  File "/usr/local/lib/python3.5/dist-packages/flask/app.py", line 1612, in full_dispatch_request
    rv = self.dispatch_request()
  File "/usr/local/lib/python3.5/dist-packages/flask/app.py", line 1598, in dispatch_request
    return self.view_functions[rule.endpoint](**req.view_args)
  File "./trial.py", line 467, in shoplist
    shopname = session.query(Shop,ShopTag,ShopPhoto).join(ShopTag).filter_by(tag=category).join(ShopPhoto).all()
  File "/usr/local/lib/python3.5/dist-packages/sqlalchemy/orm/query.py", line 2703, in all
    return list(self)
  File "/usr/local/lib/python3.5/dist-packages/sqlalchemy/orm/query.py", line 2855, in __iter__
    return self._execute_and_instances(context)
  File "/usr/local/lib/python3.5/dist-packages/sqlalchemy/orm/query.py", line 2876, in _execute_and_instances
    close_with_result=True)
  File "/usr/local/lib/python3.5/dist-packages/sqlalchemy/orm/query.py", line 2885, in _get_bind_args
    **kw
  File "/usr/local/lib/python3.5/dist-packages/sqlalchemy/orm/query.py", line 2867, in _connection_from_session
    conn = self.session.connection(**kw)
  File "/usr/local/lib/python3.5/dist-packages/sqlalchemy/orm/session.py", line 1013, in connection
    execution_options=execution_options)
  File "/usr/local/lib/python3.5/dist-packages/sqlalchemy/orm/session.py", line 1018, in _connection_for_bind
    engine, execution_options)
  File "/usr/local/lib/python3.5/dist-packages/sqlalchemy/orm/session.py", line 382, in _connection_for_bind
    self._assert_active()
  File "/usr/local/lib/python3.5/dist-packages/sqlalchemy/orm/session.py", line 276, in _assert_active
    % self._rollback_exception
sqlalchemy.exc.InvalidRequestError: This Session's transaction has been rolled back due to a previous exception during flush. To begin a new transaction with this Session, first issue Session.rollback(). Original exception was: (sqlite3.IntegrityError) UNIQUE constraint failed: user.username [SQL: 'INSERT INTO user (username, password, name, email, gender, birth_date, phone_number, address, photodir, verified) VALUES (?, ?, ?, ?, ?, ?, ?, ?, ?, ?)'] [parameters: ('cethik', '$2b$12$60UQCzVKjIi5vsiYQvQ.AOq0itYi.lnRuvNFOPtKbsoM1uPnWRt/u', 'Erwan', 'cethik7@gmail.com', 'Male', '2018-01-01', '081224035608', 'Bandung', './static/img/photo_bucket/1logo.jpg', 0)]
127.0.0.1 - - [16/Apr/2018 07:59:42] "GET /category/Fashion HTTP/1.0" 500 -
[2018-04-16 08:21:27,247] ERROR in app: Exception on /category/Food [GET]
Traceback (most recent call last):
  File "/usr/local/lib/python3.5/dist-packages/flask/app.py", line 1982, in wsgi_app
    response = self.full_dispatch_request()
  File "/usr/local/lib/python3.5/dist-packages/flask/app.py", line 1614, in full_dispatch_request
    rv = self.handle_user_exception(e)
  File "/usr/local/lib/python3.5/dist-packages/flask/app.py", line 1517, in handle_user_exception
    reraise(exc_type, exc_value, tb)
  File "/usr/local/lib/python3.5/dist-packages/flask/_compat.py", line 33, in reraise
    raise value
  File "/usr/local/lib/python3.5/dist-packages/flask/app.py", line 1612, in full_dispatch_request
    rv = self.dispatch_request()
  File "/usr/local/lib/python3.5/dist-packages/flask/app.py", line 1598, in dispatch_request
    return self.view_functions[rule.endpoint](**req.view_args)
  File "./trial.py", line 467, in shoplist
    shopname = session.query(Shop,ShopTag,ShopPhoto).join(ShopTag).filter_by(tag=category).join(ShopPhoto).all()
  File "/usr/local/lib/python3.5/dist-packages/sqlalchemy/orm/query.py", line 2703, in all
    return list(self)
  File "/usr/local/lib/python3.5/dist-packages/sqlalchemy/orm/query.py", line 2855, in __iter__
    return self._execute_and_instances(context)
  File "/usr/local/lib/python3.5/dist-packages/sqlalchemy/orm/query.py", line 2876, in _execute_and_instances
    close_with_result=True)
  File "/usr/local/lib/python3.5/dist-packages/sqlalchemy/orm/query.py", line 2885, in _get_bind_args
    **kw
  File "/usr/local/lib/python3.5/dist-packages/sqlalchemy/orm/query.py", line 2867, in _connection_from_session
    conn = self.session.connection(**kw)
  File "/usr/local/lib/python3.5/dist-packages/sqlalchemy/orm/session.py", line 1013, in connection
    execution_options=execution_options)
  File "/usr/local/lib/python3.5/dist-packages/sqlalchemy/orm/session.py", line 1018, in _connection_for_bind
    engine, execution_options)
  File "/usr/local/lib/python3.5/dist-packages/sqlalchemy/orm/session.py", line 382, in _connection_for_bind
    self._assert_active()
  File "/usr/local/lib/python3.5/dist-packages/sqlalchemy/orm/session.py", line 276, in _assert_active
    % self._rollback_exception
sqlalchemy.exc.InvalidRequestError: This Session's transaction has been rolled back due to a previous exception during flush. To begin a new transaction with this Session, first issue Session.rollback(). Original exception was: (sqlite3.IntegrityError) UNIQUE constraint failed: user.username [SQL: 'INSERT INTO user (username, password, name, email, gender, birth_date, phone_number, address, photodir, verified) VALUES (?, ?, ?, ?, ?, ?, ?, ?, ?, ?)'] [parameters: ('cethik', '$2b$12$60UQCzVKjIi5vsiYQvQ.AOq0itYi.lnRuvNFOPtKbsoM1uPnWRt/u', 'Erwan', 'cethik7@gmail.com', 'Male', '2018-01-01', '081224035608', 'Bandung', './static/img/photo_bucket/1logo.jpg', 0)]
127.0.0.1 - - [16/Apr/2018 08:21:27] "GET /category/Food HTTP/1.0" 500 -
89.248.167.131 - - [16/Apr/2018 09:46:18] code 400, message Bad request syntax ('HELLOKETTLE')
89.248.167.131 - - [16/Apr/2018 09:46:18] "HELLOKETTLE" HTTPStatus.BAD_REQUEST -
194.190.169.90 - - [16/Apr/2018 11:11:36] code 400, message Bad HTTP/0.9 request type ('\x03\x00\x00+&à\x00\x00\x00\x00\x00Cookie:')
194.190.169.90 - - [16/Apr/2018 11:11:36] "  +&à     Cookie: mstshash=hello" HTTPStatus.BAD_REQUEST -
127.0.0.1 - - [16/Apr/2018 12:19:05] "GET / HTTP/1.0" 200 -
127.0.0.1 - - [16/Apr/2018 12:19:13] "GET /category HTTP/1.0" 200 -
[2018-04-16 12:19:19,018] ERROR in app: Exception on /category/Fashion [GET]
Traceback (most recent call last):
  File "/usr/local/lib/python3.5/dist-packages/flask/app.py", line 1982, in wsgi_app
    response = self.full_dispatch_request()
  File "/usr/local/lib/python3.5/dist-packages/flask/app.py", line 1614, in full_dispatch_request
    rv = self.handle_user_exception(e)
  File "/usr/local/lib/python3.5/dist-packages/flask/app.py", line 1517, in handle_user_exception
    reraise(exc_type, exc_value, tb)
  File "/usr/local/lib/python3.5/dist-packages/flask/_compat.py", line 33, in reraise
    raise value
  File "/usr/local/lib/python3.5/dist-packages/flask/app.py", line 1612, in full_dispatch_request
    rv = self.dispatch_request()
  File "/usr/local/lib/python3.5/dist-packages/flask/app.py", line 1598, in dispatch_request
    return self.view_functions[rule.endpoint](**req.view_args)
  File "./trial.py", line 467, in shoplist
    shopname = session.query(Shop,ShopTag,ShopPhoto).join(ShopTag).filter_by(tag=category).join(ShopPhoto).all()
  File "/usr/local/lib/python3.5/dist-packages/sqlalchemy/orm/query.py", line 2703, in all
    return list(self)
  File "/usr/local/lib/python3.5/dist-packages/sqlalchemy/orm/query.py", line 2855, in __iter__
    return self._execute_and_instances(context)
  File "/usr/local/lib/python3.5/dist-packages/sqlalchemy/orm/query.py", line 2876, in _execute_and_instances
    close_with_result=True)
  File "/usr/local/lib/python3.5/dist-packages/sqlalchemy/orm/query.py", line 2885, in _get_bind_args
    **kw
  File "/usr/local/lib/python3.5/dist-packages/sqlalchemy/orm/query.py", line 2867, in _connection_from_session
    conn = self.session.connection(**kw)
  File "/usr/local/lib/python3.5/dist-packages/sqlalchemy/orm/session.py", line 1013, in connection
    execution_options=execution_options)
  File "/usr/local/lib/python3.5/dist-packages/sqlalchemy/orm/session.py", line 1018, in _connection_for_bind
    engine, execution_options)
  File "/usr/local/lib/python3.5/dist-packages/sqlalchemy/orm/session.py", line 382, in _connection_for_bind
    self._assert_active()
  File "/usr/local/lib/python3.5/dist-packages/sqlalchemy/orm/session.py", line 276, in _assert_active
    % self._rollback_exception
sqlalchemy.exc.InvalidRequestError: This Session's transaction has been rolled back due to a previous exception during flush. To begin a new transaction with this Session, first issue Session.rollback(). Original exception was: (sqlite3.IntegrityError) UNIQUE constraint failed: user.username [SQL: 'INSERT INTO user (username, password, name, email, gender, birth_date, phone_number, address, photodir, verified) VALUES (?, ?, ?, ?, ?, ?, ?, ?, ?, ?)'] [parameters: ('cethik', '$2b$12$60UQCzVKjIi5vsiYQvQ.AOq0itYi.lnRuvNFOPtKbsoM1uPnWRt/u', 'Erwan', 'cethik7@gmail.com', 'Male', '2018-01-01', '081224035608', 'Bandung', './static/img/photo_bucket/1logo.jpg', 0)]
127.0.0.1 - - [16/Apr/2018 12:19:19] "GET /category/Fashion HTTP/1.0" 500 -
127.0.0.1 - - [16/Apr/2018 13:05:01] "GET / HTTP/1.0" 200 -
127.0.0.1 - - [16/Apr/2018 13:05:01] "GET / HTTP/1.0" 200 -
127.0.0.1 - - [16/Apr/2018 13:05:02] "GET /static/img/logo-trimmed.png HTTP/1.0" 200 -
127.0.0.1 - - [16/Apr/2018 13:51:09] "GET / HTTP/1.0" 200 -
127.0.0.1 - - [16/Apr/2018 13:51:14] "GET /apple-touch-icon-120x120-precomposed.png HTTP/1.0" 404 -
127.0.0.1 - - [16/Apr/2018 13:51:15] "GET /apple-touch-icon-120x120.png HTTP/1.0" 404 -
127.0.0.1 - - [16/Apr/2018 13:51:15] "GET /apple-touch-icon.png HTTP/1.0" 404 -
127.0.0.1 - - [16/Apr/2018 13:51:15] "GET /apple-touch-icon.png HTTP/1.0" 404 -
127.0.0.1 - - [16/Apr/2018 13:51:15] "GET /apple-touch-icon-precomposed.png HTTP/1.0" 404 -
127.0.0.1 - - [16/Apr/2018 13:51:16] "GET /favicon.ico HTTP/1.0" 404 -
107.170.231.244 - - [16/Apr/2018 14:03:49] "GET / HTTP/1.1" 200 -
127.0.0.1 - - [16/Apr/2018 22:59:25] "GET /category HTTP/1.0" 200 -
127.0.0.1 - - [16/Apr/2018 22:59:26] "GET /static/css/bootstrap.min.css HTTP/1.0" 304 -
127.0.0.1 - - [16/Apr/2018 22:59:26] "GET /static/js/jquery.js HTTP/1.0" 304 -
127.0.0.1 - - [16/Apr/2018 22:59:26] "GET /static/js/custom.js HTTP/1.0" 304 -
127.0.0.1 - - [16/Apr/2018 22:59:26] "GET /static/img/logo-trimmed.png HTTP/1.0" 304 -
127.0.0.1 - - [16/Apr/2018 22:59:26] "GET /static/js/bootstrap.min.js HTTP/1.0" 304 -
127.0.0.1 - - [16/Apr/2018 22:59:26] "GET /static/css/custom.css HTTP/1.0" 304 -
[2018-04-16 22:59:30,933] ERROR in app: Exception on /category/Fashion [GET]
Traceback (most recent call last):
  File "/usr/local/lib/python3.5/dist-packages/flask/app.py", line 1982, in wsgi_app
    response = self.full_dispatch_request()
  File "/usr/local/lib/python3.5/dist-packages/flask/app.py", line 1614, in full_dispatch_request
    rv = self.handle_user_exception(e)
  File "/usr/local/lib/python3.5/dist-packages/flask/app.py", line 1517, in handle_user_exception
    reraise(exc_type, exc_value, tb)
  File "/usr/local/lib/python3.5/dist-packages/flask/_compat.py", line 33, in reraise
    raise value
  File "/usr/local/lib/python3.5/dist-packages/flask/app.py", line 1612, in full_dispatch_request
    rv = self.dispatch_request()
  File "/usr/local/lib/python3.5/dist-packages/flask/app.py", line 1598, in dispatch_request
    return self.view_functions[rule.endpoint](**req.view_args)
  File "./trial.py", line 467, in shoplist
    shopname = session.query(Shop,ShopTag,ShopPhoto).join(ShopTag).filter_by(tag=category).join(ShopPhoto).all()
  File "/usr/local/lib/python3.5/dist-packages/sqlalchemy/orm/query.py", line 2703, in all
    return list(self)
  File "/usr/local/lib/python3.5/dist-packages/sqlalchemy/orm/query.py", line 2855, in __iter__
    return self._execute_and_instances(context)
  File "/usr/local/lib/python3.5/dist-packages/sqlalchemy/orm/query.py", line 2876, in _execute_and_instances
    close_with_result=True)
  File "/usr/local/lib/python3.5/dist-packages/sqlalchemy/orm/query.py", line 2885, in _get_bind_args
    **kw
  File "/usr/local/lib/python3.5/dist-packages/sqlalchemy/orm/query.py", line 2867, in _connection_from_session
    conn = self.session.connection(**kw)
  File "/usr/local/lib/python3.5/dist-packages/sqlalchemy/orm/session.py", line 1013, in connection
    execution_options=execution_options)
  File "/usr/local/lib/python3.5/dist-packages/sqlalchemy/orm/session.py", line 1018, in _connection_for_bind
    engine, execution_options)
  File "/usr/local/lib/python3.5/dist-packages/sqlalchemy/orm/session.py", line 382, in _connection_for_bind
    self._assert_active()
  File "/usr/local/lib/python3.5/dist-packages/sqlalchemy/orm/session.py", line 276, in _assert_active
    % self._rollback_exception
sqlalchemy.exc.InvalidRequestError: This Session's transaction has been rolled back due to a previous exception during flush. To begin a new transaction with this Session, first issue Session.rollback(). Original exception was: (sqlite3.IntegrityError) UNIQUE constraint failed: user.username [SQL: 'INSERT INTO user (username, password, name, email, gender, birth_date, phone_number, address, photodir, verified) VALUES (?, ?, ?, ?, ?, ?, ?, ?, ?, ?)'] [parameters: ('cethik', '$2b$12$60UQCzVKjIi5vsiYQvQ.AOq0itYi.lnRuvNFOPtKbsoM1uPnWRt/u', 'Erwan', 'cethik7@gmail.com', 'Male', '2018-01-01', '081224035608', 'Bandung', './static/img/photo_bucket/1logo.jpg', 0)]
127.0.0.1 - - [16/Apr/2018 22:59:30] "GET /category/Fashion HTTP/1.0" 500 -
[2018-04-16 22:59:34,102] ERROR in app: Exception on /category/Fashion [GET]
Traceback (most recent call last):
  File "/usr/local/lib/python3.5/dist-packages/flask/app.py", line 1982, in wsgi_app
    response = self.full_dispatch_request()
  File "/usr/local/lib/python3.5/dist-packages/flask/app.py", line 1614, in full_dispatch_request
    rv = self.handle_user_exception(e)
  File "/usr/local/lib/python3.5/dist-packages/flask/app.py", line 1517, in handle_user_exception
    reraise(exc_type, exc_value, tb)
  File "/usr/local/lib/python3.5/dist-packages/flask/_compat.py", line 33, in reraise
    raise value
  File "/usr/local/lib/python3.5/dist-packages/flask/app.py", line 1612, in full_dispatch_request
    rv = self.dispatch_request()
  File "/usr/local/lib/python3.5/dist-packages/flask/app.py", line 1598, in dispatch_request
    return self.view_functions[rule.endpoint](**req.view_args)
  File "./trial.py", line 467, in shoplist
    shopname = session.query(Shop,ShopTag,ShopPhoto).join(ShopTag).filter_by(tag=category).join(ShopPhoto).all()
  File "/usr/local/lib/python3.5/dist-packages/sqlalchemy/orm/query.py", line 2703, in all
    return list(self)
  File "/usr/local/lib/python3.5/dist-packages/sqlalchemy/orm/query.py", line 2855, in __iter__
    return self._execute_and_instances(context)
  File "/usr/local/lib/python3.5/dist-packages/sqlalchemy/orm/query.py", line 2876, in _execute_and_instances
    close_with_result=True)
  File "/usr/local/lib/python3.5/dist-packages/sqlalchemy/orm/query.py", line 2885, in _get_bind_args
    **kw
  File "/usr/local/lib/python3.5/dist-packages/sqlalchemy/orm/query.py", line 2867, in _connection_from_session
    conn = self.session.connection(**kw)
  File "/usr/local/lib/python3.5/dist-packages/sqlalchemy/orm/session.py", line 1013, in connection
    execution_options=execution_options)
  File "/usr/local/lib/python3.5/dist-packages/sqlalchemy/orm/session.py", line 1018, in _connection_for_bind
    engine, execution_options)
  File "/usr/local/lib/python3.5/dist-packages/sqlalchemy/orm/session.py", line 382, in _connection_for_bind
    self._assert_active()
  File "/usr/local/lib/python3.5/dist-packages/sqlalchemy/orm/session.py", line 276, in _assert_active
    % self._rollback_exception
sqlalchemy.exc.InvalidRequestError: This Session's transaction has been rolled back due to a previous exception during flush. To begin a new transaction with this Session, first issue Session.rollback(). Original exception was: (sqlite3.IntegrityError) UNIQUE constraint failed: user.username [SQL: 'INSERT INTO user (username, password, name, email, gender, birth_date, phone_number, address, photodir, verified) VALUES (?, ?, ?, ?, ?, ?, ?, ?, ?, ?)'] [parameters: ('cethik', '$2b$12$60UQCzVKjIi5vsiYQvQ.AOq0itYi.lnRuvNFOPtKbsoM1uPnWRt/u', 'Erwan', 'cethik7@gmail.com', 'Male', '2018-01-01', '081224035608', 'Bandung', './static/img/photo_bucket/1logo.jpg', 0)]
127.0.0.1 - - [16/Apr/2018 22:59:34] "GET /category/Fashion HTTP/1.0" 500 -
[2018-04-16 22:59:37,966] ERROR in app: Exception on /profile [GET]
Traceback (most recent call last):
  File "/usr/local/lib/python3.5/dist-packages/flask/app.py", line 1982, in wsgi_app
    response = self.full_dispatch_request()
  File "/usr/local/lib/python3.5/dist-packages/flask/app.py", line 1614, in full_dispatch_request
    rv = self.handle_user_exception(e)
  File "/usr/local/lib/python3.5/dist-packages/flask/app.py", line 1517, in handle_user_exception
    reraise(exc_type, exc_value, tb)
  File "/usr/local/lib/python3.5/dist-packages/flask/_compat.py", line 33, in reraise
    raise value
  File "/usr/local/lib/python3.5/dist-packages/flask/app.py", line 1612, in full_dispatch_request
    rv = self.dispatch_request()
  File "/usr/local/lib/python3.5/dist-packages/flask/app.py", line 1598, in dispatch_request
    return self.view_functions[rule.endpoint](**req.view_args)
  File "./trial.py", line 435, in profile
    shops = session.query(Shop,Article,ArticlePhoto,ShopTag).join(Article).join(ArticlePhoto).join(ShopTag).all()
  File "/usr/local/lib/python3.5/dist-packages/sqlalchemy/orm/query.py", line 2703, in all
    return list(self)
  File "/usr/local/lib/python3.5/dist-packages/sqlalchemy/orm/query.py", line 2855, in __iter__
    return self._execute_and_instances(context)
  File "/usr/local/lib/python3.5/dist-packages/sqlalchemy/orm/query.py", line 2876, in _execute_and_instances
    close_with_result=True)
  File "/usr/local/lib/python3.5/dist-packages/sqlalchemy/orm/query.py", line 2885, in _get_bind_args
    **kw
  File "/usr/local/lib/python3.5/dist-packages/sqlalchemy/orm/query.py", line 2867, in _connection_from_session
    conn = self.session.connection(**kw)
  File "/usr/local/lib/python3.5/dist-packages/sqlalchemy/orm/session.py", line 1013, in connection
    execution_options=execution_options)
  File "/usr/local/lib/python3.5/dist-packages/sqlalchemy/orm/session.py", line 1018, in _connection_for_bind
    engine, execution_options)
  File "/usr/local/lib/python3.5/dist-packages/sqlalchemy/orm/session.py", line 382, in _connection_for_bind
    self._assert_active()
  File "/usr/local/lib/python3.5/dist-packages/sqlalchemy/orm/session.py", line 276, in _assert_active
    % self._rollback_exception
sqlalchemy.exc.InvalidRequestError: This Session's transaction has been rolled back due to a previous exception during flush. To begin a new transaction with this Session, first issue Session.rollback(). Original exception was: (sqlite3.IntegrityError) UNIQUE constraint failed: user.username [SQL: 'INSERT INTO user (username, password, name, email, gender, birth_date, phone_number, address, photodir, verified) VALUES (?, ?, ?, ?, ?, ?, ?, ?, ?, ?)'] [parameters: ('cethik', '$2b$12$60UQCzVKjIi5vsiYQvQ.AOq0itYi.lnRuvNFOPtKbsoM1uPnWRt/u', 'Erwan', 'cethik7@gmail.com', 'Male', '2018-01-01', '081224035608', 'Bandung', './static/img/photo_bucket/1logo.jpg', 0)]
127.0.0.1 - - [16/Apr/2018 22:59:37] "GET /profile HTTP/1.0" 500 -
127.0.0.1 - - [16/Apr/2018 22:59:42] "GET /about HTTP/1.0" 200 -
127.0.0.1 - - [16/Apr/2018 22:59:43] "GET /static/img/background-white.jpg HTTP/1.0" 304 -
127.0.0.1 - - [16/Apr/2018 22:59:46] "GET /login HTTP/1.0" 200 -
127.0.0.1 - - [16/Apr/2018 22:59:47] "GET /static/img/city-sunrise.png HTTP/1.0" 304 -
127.0.0.1 - - [17/Apr/2018 00:17:27] "GET /robots.txt HTTP/1.0" 404 -
127.0.0.1 - - [17/Apr/2018 00:17:27] "GET / HTTP/1.0" 200 -
127.0.0.1 - - [17/Apr/2018 01:39:28] "GET /static/css/bootstrap.min.css HTTP/1.0" 200 -
127.0.0.1 - - [17/Apr/2018 01:39:29] "GET /static/css/custom.css HTTP/1.0" 200 -
127.0.0.1 - - [17/Apr/2018 02:13:16] "GET / HTTP/1.0" 200 -
127.0.0.1 - - [17/Apr/2018 02:13:16] "GET /static/css/bootstrap.min.css HTTP/1.0" 200 -
127.0.0.1 - - [17/Apr/2018 02:13:16] "GET /static/css/custom.css HTTP/1.0" 200 -
127.0.0.1 - - [17/Apr/2018 02:13:16] "GET /static/js/bootstrap.min.js HTTP/1.0" 200 -
127.0.0.1 - - [17/Apr/2018 02:13:16] "GET /static/js/jquery.js HTTP/1.0" 200 -
127.0.0.1 - - [17/Apr/2018 02:13:16] "GET /static/js/custom.js HTTP/1.0" 200 -
127.0.0.1 - - [17/Apr/2018 02:13:17] "GET /static/img/logo-trimmed.png HTTP/1.0" 200 -
127.0.0.1 - - [17/Apr/2018 02:13:17] "GET /static/img/city-sunrise.png HTTP/1.0" 200 -
127.0.0.1 - - [17/Apr/2018 02:13:17] "GET /static/img/background-white.jpg HTTP/1.0" 200 -
127.0.0.1 - - [17/Apr/2018 02:13:23] "GET /category HTTP/1.0" 200 -
127.0.0.1 - - [17/Apr/2018 02:13:25] "GET /favicon.ico HTTP/1.0" 404 -
[2018-04-17 02:13:36,074] ERROR in app: Exception on /profile [GET]
Traceback (most recent call last):
  File "/usr/local/lib/python3.5/dist-packages/flask/app.py", line 1982, in wsgi_app
    response = self.full_dispatch_request()
  File "/usr/local/lib/python3.5/dist-packages/flask/app.py", line 1614, in full_dispatch_request
    rv = self.handle_user_exception(e)
  File "/usr/local/lib/python3.5/dist-packages/flask/app.py", line 1517, in handle_user_exception
    reraise(exc_type, exc_value, tb)
  File "/usr/local/lib/python3.5/dist-packages/flask/_compat.py", line 33, in reraise
    raise value
  File "/usr/local/lib/python3.5/dist-packages/flask/app.py", line 1612, in full_dispatch_request
    rv = self.dispatch_request()
  File "/usr/local/lib/python3.5/dist-packages/flask/app.py", line 1598, in dispatch_request
    return self.view_functions[rule.endpoint](**req.view_args)
  File "./trial.py", line 435, in profile
    shops = session.query(Shop,Article,ArticlePhoto,ShopTag).join(Article).join(ArticlePhoto).join(ShopTag).all()
  File "/usr/local/lib/python3.5/dist-packages/sqlalchemy/orm/query.py", line 2703, in all
    return list(self)
  File "/usr/local/lib/python3.5/dist-packages/sqlalchemy/orm/query.py", line 2855, in __iter__
    return self._execute_and_instances(context)
  File "/usr/local/lib/python3.5/dist-packages/sqlalchemy/orm/query.py", line 2876, in _execute_and_instances
    close_with_result=True)
  File "/usr/local/lib/python3.5/dist-packages/sqlalchemy/orm/query.py", line 2885, in _get_bind_args
    **kw
  File "/usr/local/lib/python3.5/dist-packages/sqlalchemy/orm/query.py", line 2867, in _connection_from_session
    conn = self.session.connection(**kw)
  File "/usr/local/lib/python3.5/dist-packages/sqlalchemy/orm/session.py", line 1013, in connection
    execution_options=execution_options)
  File "/usr/local/lib/python3.5/dist-packages/sqlalchemy/orm/session.py", line 1018, in _connection_for_bind
    engine, execution_options)
  File "/usr/local/lib/python3.5/dist-packages/sqlalchemy/orm/session.py", line 382, in _connection_for_bind
    self._assert_active()
  File "/usr/local/lib/python3.5/dist-packages/sqlalchemy/orm/session.py", line 276, in _assert_active
    % self._rollback_exception
sqlalchemy.exc.InvalidRequestError: This Session's transaction has been rolled back due to a previous exception during flush. To begin a new transaction with this Session, first issue Session.rollback(). Original exception was: (sqlite3.IntegrityError) UNIQUE constraint failed: user.username [SQL: 'INSERT INTO user (username, password, name, email, gender, birth_date, phone_number, address, photodir, verified) VALUES (?, ?, ?, ?, ?, ?, ?, ?, ?, ?)'] [parameters: ('cethik', '$2b$12$60UQCzVKjIi5vsiYQvQ.AOq0itYi.lnRuvNFOPtKbsoM1uPnWRt/u', 'Erwan', 'cethik7@gmail.com', 'Male', '2018-01-01', '081224035608', 'Bandung', './static/img/photo_bucket/1logo.jpg', 0)]
127.0.0.1 - - [17/Apr/2018 02:13:36] "GET /profile HTTP/1.0" 500 -
127.0.0.1 - - [17/Apr/2018 02:13:39] "GET /sign_up HTTP/1.0" 200 -
127.0.0.1 - - [17/Apr/2018 02:13:42] "GET /login HTTP/1.0" 200 -
127.0.0.1 - - [17/Apr/2018 02:13:43] "GET /static/img/city-sunrise.png HTTP/1.0" 200 -
127.0.0.1 - - [17/Apr/2018 02:13:43] "GET /static/img/city-sunrise.png HTTP/1.0" 200 -
[2018-04-17 02:14:00,746] ERROR in app: Exception on /login [POST]
Traceback (most recent call last):
  File "/usr/local/lib/python3.5/dist-packages/flask/app.py", line 1982, in wsgi_app
    response = self.full_dispatch_request()
  File "/usr/local/lib/python3.5/dist-packages/flask/app.py", line 1614, in full_dispatch_request
    rv = self.handle_user_exception(e)
  File "/usr/local/lib/python3.5/dist-packages/flask/app.py", line 1517, in handle_user_exception
    reraise(exc_type, exc_value, tb)
  File "/usr/local/lib/python3.5/dist-packages/flask/_compat.py", line 33, in reraise
    raise value
  File "/usr/local/lib/python3.5/dist-packages/flask/app.py", line 1612, in full_dispatch_request
    rv = self.dispatch_request()
  File "/usr/local/lib/python3.5/dist-packages/flask/app.py", line 1598, in dispatch_request
    return self.view_functions[rule.endpoint](**req.view_args)
  File "./trial.py", line 238, in login
    U = user_loader(username)
  File "./trial.py", line 205, in user_loader
    U = session.query(User).filter_by(username=username).first()
  File "/usr/local/lib/python3.5/dist-packages/sqlalchemy/orm/query.py", line 2755, in first
    ret = list(self[0:1])
  File "/usr/local/lib/python3.5/dist-packages/sqlalchemy/orm/query.py", line 2547, in __getitem__
    return list(res)
  File "/usr/local/lib/python3.5/dist-packages/sqlalchemy/orm/query.py", line 2855, in __iter__
    return self._execute_and_instances(context)
  File "/usr/local/lib/python3.5/dist-packages/sqlalchemy/orm/query.py", line 2876, in _execute_and_instances
    close_with_result=True)
  File "/usr/local/lib/python3.5/dist-packages/sqlalchemy/orm/query.py", line 2885, in _get_bind_args
    **kw
  File "/usr/local/lib/python3.5/dist-packages/sqlalchemy/orm/query.py", line 2867, in _connection_from_session
    conn = self.session.connection(**kw)
  File "/usr/local/lib/python3.5/dist-packages/sqlalchemy/orm/session.py", line 1013, in connection
    execution_options=execution_options)
  File "/usr/local/lib/python3.5/dist-packages/sqlalchemy/orm/session.py", line 1018, in _connection_for_bind
    engine, execution_options)
  File "/usr/local/lib/python3.5/dist-packages/sqlalchemy/orm/session.py", line 382, in _connection_for_bind
    self._assert_active()
  File "/usr/local/lib/python3.5/dist-packages/sqlalchemy/orm/session.py", line 276, in _assert_active
    % self._rollback_exception
sqlalchemy.exc.InvalidRequestError: This Session's transaction has been rolled back due to a previous exception during flush. To begin a new transaction with this Session, first issue Session.rollback(). Original exception was: (sqlite3.IntegrityError) UNIQUE constraint failed: user.username [SQL: 'INSERT INTO user (username, password, name, email, gender, birth_date, phone_number, address, photodir, verified) VALUES (?, ?, ?, ?, ?, ?, ?, ?, ?, ?)'] [parameters: ('cethik', '$2b$12$60UQCzVKjIi5vsiYQvQ.AOq0itYi.lnRuvNFOPtKbsoM1uPnWRt/u', 'Erwan', 'cethik7@gmail.com', 'Male', '2018-01-01', '081224035608', 'Bandung', './static/img/photo_bucket/1logo.jpg', 0)]
127.0.0.1 - - [17/Apr/2018 02:14:00] "POST /login HTTP/1.0" 500 -
127.0.0.1 - - [17/Apr/2018 02:14:54] "GET / HTTP/1.0" 200 -
127.0.0.1 - - [17/Apr/2018 02:14:54] "GET /static/css/custom.css HTTP/1.0" 304 -
127.0.0.1 - - [17/Apr/2018 02:14:55] "GET /static/js/jquery.js HTTP/1.0" 304 -
127.0.0.1 - - [17/Apr/2018 02:14:55] "GET /static/css/bootstrap.min.css HTTP/1.0" 304 -
127.0.0.1 - - [17/Apr/2018 02:14:55] "GET /static/js/bootstrap.min.js HTTP/1.0" 304 -
127.0.0.1 - - [17/Apr/2018 02:14:56] "GET /static/img/logo-trimmed.png HTTP/1.0" 304 -
127.0.0.1 - - [17/Apr/2018 02:14:56] "GET /static/js/custom.js HTTP/1.0" 304 -
127.0.0.1 - - [17/Apr/2018 02:14:56] "GET /static/img/background-white.jpg HTTP/1.0" 304 -
127.0.0.1 - - [17/Apr/2018 02:15:01] "GET /login HTTP/1.0" 200 -
127.0.0.1 - - [17/Apr/2018 02:15:01] "GET /static/css/bootstrap.min.css HTTP/1.0" 304 -
127.0.0.1 - - [17/Apr/2018 02:15:02] "GET /static/js/custom.js HTTP/1.0" 304 -
127.0.0.1 - - [17/Apr/2018 02:15:02] "GET /static/js/bootstrap.min.js HTTP/1.0" 304 -
127.0.0.1 - - [17/Apr/2018 02:15:02] "GET /static/css/custom.css HTTP/1.0" 304 -
127.0.0.1 - - [17/Apr/2018 02:15:02] "GET /static/js/jquery.js HTTP/1.0" 304 -
127.0.0.1 - - [17/Apr/2018 02:15:02] "GET /static/img/logo-trimmed.png HTTP/1.0" 304 -
[2018-04-17 02:15:19,686] ERROR in app: Exception on /login [POST]
Traceback (most recent call last):
  File "/usr/local/lib/python3.5/dist-packages/flask/app.py", line 1982, in wsgi_app
    response = self.full_dispatch_request()
  File "/usr/local/lib/python3.5/dist-packages/flask/app.py", line 1614, in full_dispatch_request
    rv = self.handle_user_exception(e)
  File "/usr/local/lib/python3.5/dist-packages/flask/app.py", line 1517, in handle_user_exception
    reraise(exc_type, exc_value, tb)
  File "/usr/local/lib/python3.5/dist-packages/flask/_compat.py", line 33, in reraise
    raise value
  File "/usr/local/lib/python3.5/dist-packages/flask/app.py", line 1612, in full_dispatch_request
    rv = self.dispatch_request()
  File "/usr/local/lib/python3.5/dist-packages/flask/app.py", line 1598, in dispatch_request
    return self.view_functions[rule.endpoint](**req.view_args)
  File "./trial.py", line 238, in login
    U = user_loader(username)
  File "./trial.py", line 205, in user_loader
    U = session.query(User).filter_by(username=username).first()
  File "/usr/local/lib/python3.5/dist-packages/sqlalchemy/orm/query.py", line 2755, in first
    ret = list(self[0:1])
  File "/usr/local/lib/python3.5/dist-packages/sqlalchemy/orm/query.py", line 2547, in __getitem__
    return list(res)
  File "/usr/local/lib/python3.5/dist-packages/sqlalchemy/orm/query.py", line 2855, in __iter__
    return self._execute_and_instances(context)
  File "/usr/local/lib/python3.5/dist-packages/sqlalchemy/orm/query.py", line 2876, in _execute_and_instances
    close_with_result=True)
  File "/usr/local/lib/python3.5/dist-packages/sqlalchemy/orm/query.py", line 2885, in _get_bind_args
    **kw
  File "/usr/local/lib/python3.5/dist-packages/sqlalchemy/orm/query.py", line 2867, in _connection_from_session
    conn = self.session.connection(**kw)
  File "/usr/local/lib/python3.5/dist-packages/sqlalchemy/orm/session.py", line 1013, in connection
    execution_options=execution_options)
  File "/usr/local/lib/python3.5/dist-packages/sqlalchemy/orm/session.py", line 1018, in _connection_for_bind
    engine, execution_options)
  File "/usr/local/lib/python3.5/dist-packages/sqlalchemy/orm/session.py", line 382, in _connection_for_bind
    self._assert_active()
  File "/usr/local/lib/python3.5/dist-packages/sqlalchemy/orm/session.py", line 276, in _assert_active
    % self._rollback_exception
sqlalchemy.exc.InvalidRequestError: This Session's transaction has been rolled back due to a previous exception during flush. To begin a new transaction with this Session, first issue Session.rollback(). Original exception was: (sqlite3.IntegrityError) UNIQUE constraint failed: user.username [SQL: 'INSERT INTO user (username, password, name, email, gender, birth_date, phone_number, address, photodir, verified) VALUES (?, ?, ?, ?, ?, ?, ?, ?, ?, ?)'] [parameters: ('cethik', '$2b$12$60UQCzVKjIi5vsiYQvQ.AOq0itYi.lnRuvNFOPtKbsoM1uPnWRt/u', 'Erwan', 'cethik7@gmail.com', 'Male', '2018-01-01', '081224035608', 'Bandung', './static/img/photo_bucket/1logo.jpg', 0)]
127.0.0.1 - - [17/Apr/2018 02:15:19] "POST /login HTTP/1.0" 500 -
127.0.0.1 - - [17/Apr/2018 04:50:51] "GET / HTTP/1.0" 200 -
127.0.0.1 - - [17/Apr/2018 04:50:51] "GET /static/js/jquery.js HTTP/1.0" 200 -
127.0.0.1 - - [17/Apr/2018 04:50:51] "GET /static/css/bootstrap.min.css HTTP/1.0" 200 -
127.0.0.1 - - [17/Apr/2018 04:50:51] "GET /static/js/bootstrap.min.js HTTP/1.0" 200 -
127.0.0.1 - - [17/Apr/2018 04:50:51] "GET /static/css/custom.css HTTP/1.0" 304 -
127.0.0.1 - - [17/Apr/2018 04:50:52] "GET /static/js/custom.js HTTP/1.0" 304 -
127.0.0.1 - - [17/Apr/2018 04:50:52] "GET /static/img/logo-trimmed.png HTTP/1.0" 304 -
127.0.0.1 - - [17/Apr/2018 04:50:53] "GET /static/img/city-sunrise.png HTTP/1.0" 200 -
127.0.0.1 - - [17/Apr/2018 04:50:53] "GET /static/img/background-white.jpg HTTP/1.0" 200 -
127.0.0.1 - - [17/Apr/2018 04:50:54] "GET /login HTTP/1.0" 200 -
127.0.0.1 - - [17/Apr/2018 04:50:55] "GET /static/img/city-sunrise.png HTTP/1.0" 206 -
127.0.0.1 - - [17/Apr/2018 04:50:55] "GET /static/img/city-sunrise.png HTTP/1.0" 206 -
[2018-04-17 04:50:58,854] ERROR in app: Exception on /login [POST]
Traceback (most recent call last):
  File "/usr/local/lib/python3.5/dist-packages/flask/app.py", line 1982, in wsgi_app
    response = self.full_dispatch_request()
  File "/usr/local/lib/python3.5/dist-packages/flask/app.py", line 1614, in full_dispatch_request
    rv = self.handle_user_exception(e)
  File "/usr/local/lib/python3.5/dist-packages/flask/app.py", line 1517, in handle_user_exception
    reraise(exc_type, exc_value, tb)
  File "/usr/local/lib/python3.5/dist-packages/flask/_compat.py", line 33, in reraise
    raise value
  File "/usr/local/lib/python3.5/dist-packages/flask/app.py", line 1612, in full_dispatch_request
    rv = self.dispatch_request()
  File "/usr/local/lib/python3.5/dist-packages/flask/app.py", line 1598, in dispatch_request
    return self.view_functions[rule.endpoint](**req.view_args)
  File "./trial.py", line 238, in login
    U = user_loader(username)
  File "./trial.py", line 205, in user_loader
    U = session.query(User).filter_by(username=username).first()
  File "/usr/local/lib/python3.5/dist-packages/sqlalchemy/orm/query.py", line 2755, in first
    ret = list(self[0:1])
  File "/usr/local/lib/python3.5/dist-packages/sqlalchemy/orm/query.py", line 2547, in __getitem__
    return list(res)
  File "/usr/local/lib/python3.5/dist-packages/sqlalchemy/orm/query.py", line 2855, in __iter__
    return self._execute_and_instances(context)
  File "/usr/local/lib/python3.5/dist-packages/sqlalchemy/orm/query.py", line 2876, in _execute_and_instances
    close_with_result=True)
  File "/usr/local/lib/python3.5/dist-packages/sqlalchemy/orm/query.py", line 2885, in _get_bind_args
    **kw
  File "/usr/local/lib/python3.5/dist-packages/sqlalchemy/orm/query.py", line 2867, in _connection_from_session
    conn = self.session.connection(**kw)
  File "/usr/local/lib/python3.5/dist-packages/sqlalchemy/orm/session.py", line 1013, in connection
    execution_options=execution_options)
  File "/usr/local/lib/python3.5/dist-packages/sqlalchemy/orm/session.py", line 1018, in _connection_for_bind
    engine, execution_options)
  File "/usr/local/lib/python3.5/dist-packages/sqlalchemy/orm/session.py", line 382, in _connection_for_bind
    self._assert_active()
  File "/usr/local/lib/python3.5/dist-packages/sqlalchemy/orm/session.py", line 276, in _assert_active
    % self._rollback_exception
sqlalchemy.exc.InvalidRequestError: This Session's transaction has been rolled back due to a previous exception during flush. To begin a new transaction with this Session, first issue Session.rollback(). Original exception was: (sqlite3.IntegrityError) UNIQUE constraint failed: user.username [SQL: 'INSERT INTO user (username, password, name, email, gender, birth_date, phone_number, address, photodir, verified) VALUES (?, ?, ?, ?, ?, ?, ?, ?, ?, ?)'] [parameters: ('cethik', '$2b$12$60UQCzVKjIi5vsiYQvQ.AOq0itYi.lnRuvNFOPtKbsoM1uPnWRt/u', 'Erwan', 'cethik7@gmail.com', 'Male', '2018-01-01', '081224035608', 'Bandung', './static/img/photo_bucket/1logo.jpg', 0)]
127.0.0.1 - - [17/Apr/2018 04:50:58] "POST /login HTTP/1.0" 500 -
127.0.0.1 - - [17/Apr/2018 04:50:59] "GET /favicon.ico HTTP/1.0" 404 -
127.0.0.1 - - [17/Apr/2018 04:55:50] "GET / HTTP/1.0" 200 -
127.0.0.1 - - [17/Apr/2018 04:55:50] "GET /static/img/city-sunrise.png HTTP/1.0" 206 -
127.0.0.1 - - [17/Apr/2018 04:55:51] "GET /static/img/city-sunrise.png HTTP/1.0" 206 -
[2018-04-17 04:55:52,100] ERROR in app: Exception on /profile [GET]
Traceback (most recent call last):
  File "/usr/local/lib/python3.5/dist-packages/flask/app.py", line 1982, in wsgi_app
    response = self.full_dispatch_request()
  File "/usr/local/lib/python3.5/dist-packages/flask/app.py", line 1614, in full_dispatch_request
    rv = self.handle_user_exception(e)
  File "/usr/local/lib/python3.5/dist-packages/flask/app.py", line 1517, in handle_user_exception
    reraise(exc_type, exc_value, tb)
  File "/usr/local/lib/python3.5/dist-packages/flask/_compat.py", line 33, in reraise
    raise value
  File "/usr/local/lib/python3.5/dist-packages/flask/app.py", line 1612, in full_dispatch_request
    rv = self.dispatch_request()
  File "/usr/local/lib/python3.5/dist-packages/flask/app.py", line 1598, in dispatch_request
    return self.view_functions[rule.endpoint](**req.view_args)
  File "./trial.py", line 435, in profile
    shops = session.query(Shop,Article,ArticlePhoto,ShopTag).join(Article).join(ArticlePhoto).join(ShopTag).all()
  File "/usr/local/lib/python3.5/dist-packages/sqlalchemy/orm/query.py", line 2703, in all
    return list(self)
  File "/usr/local/lib/python3.5/dist-packages/sqlalchemy/orm/query.py", line 2855, in __iter__
    return self._execute_and_instances(context)
  File "/usr/local/lib/python3.5/dist-packages/sqlalchemy/orm/query.py", line 2876, in _execute_and_instances
    close_with_result=True)
  File "/usr/local/lib/python3.5/dist-packages/sqlalchemy/orm/query.py", line 2885, in _get_bind_args
    **kw
  File "/usr/local/lib/python3.5/dist-packages/sqlalchemy/orm/query.py", line 2867, in _connection_from_session
    conn = self.session.connection(**kw)
  File "/usr/local/lib/python3.5/dist-packages/sqlalchemy/orm/session.py", line 1013, in connection
    execution_options=execution_options)
  File "/usr/local/lib/python3.5/dist-packages/sqlalchemy/orm/session.py", line 1018, in _connection_for_bind
    engine, execution_options)
  File "/usr/local/lib/python3.5/dist-packages/sqlalchemy/orm/session.py", line 382, in _connection_for_bind
    self._assert_active()
  File "/usr/local/lib/python3.5/dist-packages/sqlalchemy/orm/session.py", line 276, in _assert_active
    % self._rollback_exception
sqlalchemy.exc.InvalidRequestError: This Session's transaction has been rolled back due to a previous exception during flush. To begin a new transaction with this Session, first issue Session.rollback(). Original exception was: (sqlite3.IntegrityError) UNIQUE constraint failed: user.username [SQL: 'INSERT INTO user (username, password, name, email, gender, birth_date, phone_number, address, photodir, verified) VALUES (?, ?, ?, ?, ?, ?, ?, ?, ?, ?)'] [parameters: ('cethik', '$2b$12$60UQCzVKjIi5vsiYQvQ.AOq0itYi.lnRuvNFOPtKbsoM1uPnWRt/u', 'Erwan', 'cethik7@gmail.com', 'Male', '2018-01-01', '081224035608', 'Bandung', './static/img/photo_bucket/1logo.jpg', 0)]
127.0.0.1 - - [17/Apr/2018 04:55:52] "GET /profile HTTP/1.0" 500 -
127.0.0.1 - - [17/Apr/2018 04:55:54] "GET /static/img/city-sunrise.png HTTP/1.0" 206 -
127.0.0.1 - - [17/Apr/2018 04:55:54] "GET /static/img/city-sunrise.png HTTP/1.0" 206 -
127.0.0.1 - - [17/Apr/2018 04:55:56] "GET /category HTTP/1.0" 200 -
[2018-04-17 04:55:58,425] ERROR in app: Exception on /category/Fashion [GET]
Traceback (most recent call last):
  File "/usr/local/lib/python3.5/dist-packages/flask/app.py", line 1982, in wsgi_app
    response = self.full_dispatch_request()
  File "/usr/local/lib/python3.5/dist-packages/flask/app.py", line 1614, in full_dispatch_request
    rv = self.handle_user_exception(e)
  File "/usr/local/lib/python3.5/dist-packages/flask/app.py", line 1517, in handle_user_exception
    reraise(exc_type, exc_value, tb)
  File "/usr/local/lib/python3.5/dist-packages/flask/_compat.py", line 33, in reraise
    raise value
  File "/usr/local/lib/python3.5/dist-packages/flask/app.py", line 1612, in full_dispatch_request
    rv = self.dispatch_request()
  File "/usr/local/lib/python3.5/dist-packages/flask/app.py", line 1598, in dispatch_request
    return self.view_functions[rule.endpoint](**req.view_args)
  File "./trial.py", line 467, in shoplist
    shopname = session.query(Shop,ShopTag,ShopPhoto).join(ShopTag).filter_by(tag=category).join(ShopPhoto).all()
  File "/usr/local/lib/python3.5/dist-packages/sqlalchemy/orm/query.py", line 2703, in all
    return list(self)
  File "/usr/local/lib/python3.5/dist-packages/sqlalchemy/orm/query.py", line 2855, in __iter__
    return self._execute_and_instances(context)
  File "/usr/local/lib/python3.5/dist-packages/sqlalchemy/orm/query.py", line 2876, in _execute_and_instances
    close_with_result=True)
  File "/usr/local/lib/python3.5/dist-packages/sqlalchemy/orm/query.py", line 2885, in _get_bind_args
    **kw
  File "/usr/local/lib/python3.5/dist-packages/sqlalchemy/orm/query.py", line 2867, in _connection_from_session
    conn = self.session.connection(**kw)
  File "/usr/local/lib/python3.5/dist-packages/sqlalchemy/orm/session.py", line 1013, in connection
    execution_options=execution_options)
  File "/usr/local/lib/python3.5/dist-packages/sqlalchemy/orm/session.py", line 1018, in _connection_for_bind
    engine, execution_options)
  File "/usr/local/lib/python3.5/dist-packages/sqlalchemy/orm/session.py", line 382, in _connection_for_bind
    self._assert_active()
  File "/usr/local/lib/python3.5/dist-packages/sqlalchemy/orm/session.py", line 276, in _assert_active
    % self._rollback_exception
sqlalchemy.exc.InvalidRequestError: This Session's transaction has been rolled back due to a previous exception during flush. To begin a new transaction with this Session, first issue Session.rollback(). Original exception was: (sqlite3.IntegrityError) UNIQUE constraint failed: user.username [SQL: 'INSERT INTO user (username, password, name, email, gender, birth_date, phone_number, address, photodir, verified) VALUES (?, ?, ?, ?, ?, ?, ?, ?, ?, ?)'] [parameters: ('cethik', '$2b$12$60UQCzVKjIi5vsiYQvQ.AOq0itYi.lnRuvNFOPtKbsoM1uPnWRt/u', 'Erwan', 'cethik7@gmail.com', 'Male', '2018-01-01', '081224035608', 'Bandung', './static/img/photo_bucket/1logo.jpg', 0)]
127.0.0.1 - - [17/Apr/2018 04:55:58] "GET /category/Fashion HTTP/1.0" 500 -
127.0.0.1 - - [17/Apr/2018 04:56:33] "GET / HTTP/1.0" 200 -
127.0.0.1 - - [17/Apr/2018 04:56:34] "GET /static/img/background-white.jpg HTTP/1.0" 304 -
127.0.0.1 - - [17/Apr/2018 04:56:37] "GET /category HTTP/1.0" 200 -
[2018-04-17 04:56:47,514] ERROR in app: Exception on /profile [GET]
Traceback (most recent call last):
  File "/usr/local/lib/python3.5/dist-packages/flask/app.py", line 1982, in wsgi_app
    response = self.full_dispatch_request()
  File "/usr/local/lib/python3.5/dist-packages/flask/app.py", line 1614, in full_dispatch_request
    rv = self.handle_user_exception(e)
  File "/usr/local/lib/python3.5/dist-packages/flask/app.py", line 1517, in handle_user_exception
    reraise(exc_type, exc_value, tb)
  File "/usr/local/lib/python3.5/dist-packages/flask/_compat.py", line 33, in reraise
    raise value
  File "/usr/local/lib/python3.5/dist-packages/flask/app.py", line 1612, in full_dispatch_request
    rv = self.dispatch_request()
  File "/usr/local/lib/python3.5/dist-packages/flask/app.py", line 1598, in dispatch_request
    return self.view_functions[rule.endpoint](**req.view_args)
  File "./trial.py", line 435, in profile
    shops = session.query(Shop,Article,ArticlePhoto,ShopTag).join(Article).join(ArticlePhoto).join(ShopTag).all()
  File "/usr/local/lib/python3.5/dist-packages/sqlalchemy/orm/query.py", line 2703, in all
    return list(self)
  File "/usr/local/lib/python3.5/dist-packages/sqlalchemy/orm/query.py", line 2855, in __iter__
    return self._execute_and_instances(context)
  File "/usr/local/lib/python3.5/dist-packages/sqlalchemy/orm/query.py", line 2876, in _execute_and_instances
    close_with_result=True)
  File "/usr/local/lib/python3.5/dist-packages/sqlalchemy/orm/query.py", line 2885, in _get_bind_args
    **kw
  File "/usr/local/lib/python3.5/dist-packages/sqlalchemy/orm/query.py", line 2867, in _connection_from_session
    conn = self.session.connection(**kw)
  File "/usr/local/lib/python3.5/dist-packages/sqlalchemy/orm/session.py", line 1013, in connection
    execution_options=execution_options)
  File "/usr/local/lib/python3.5/dist-packages/sqlalchemy/orm/session.py", line 1018, in _connection_for_bind
    engine, execution_options)
  File "/usr/local/lib/python3.5/dist-packages/sqlalchemy/orm/session.py", line 382, in _connection_for_bind
    self._assert_active()
  File "/usr/local/lib/python3.5/dist-packages/sqlalchemy/orm/session.py", line 276, in _assert_active
    % self._rollback_exception
sqlalchemy.exc.InvalidRequestError: This Session's transaction has been rolled back due to a previous exception during flush. To begin a new transaction with this Session, first issue Session.rollback(). Original exception was: (sqlite3.IntegrityError) UNIQUE constraint failed: user.username [SQL: 'INSERT INTO user (username, password, name, email, gender, birth_date, phone_number, address, photodir, verified) VALUES (?, ?, ?, ?, ?, ?, ?, ?, ?, ?)'] [parameters: ('cethik', '$2b$12$60UQCzVKjIi5vsiYQvQ.AOq0itYi.lnRuvNFOPtKbsoM1uPnWRt/u', 'Erwan', 'cethik7@gmail.com', 'Male', '2018-01-01', '081224035608', 'Bandung', './static/img/photo_bucket/1logo.jpg', 0)]
127.0.0.1 - - [17/Apr/2018 04:56:47] "GET /profile HTTP/1.0" 500 -
